Workbook

Sheet 홈
B1: 안동 이어드림 · 데이터 대시보드
B3: 원도심에서 도는 돈과 월영교에 모이는 사람을 밤까지 잇는 3단계 릴레이: 데이터로 진단하고, 효과를 예측하고, 검증을 설계했다
B5: 홈 | C5: 문제 | D5: 혜택 배치 | E5: 운영 시간 | F5: 버스(BIS) | G5: 월영교 야간 | H5: 기대효과 | I5: 효과 평가 | J5: 전국 진단 | K5: 서식4 | L5: 방문객 설문 | M5: 데이터 출처
B7: 이야기 흐름 (칸을 누르면 해당 화면으로 이동)
B9: ① 문제 | G9: ② 혜택이 어긋남 | L9: ③ 운영 시간 창 | Q9: ④ 밤에 끊기는 길
B10: 방문은 +5.6%인데 방문당 체험·문화 소비 −16.8% (전국 중앙 −2.0%) | G10: 방문 1위 중구동 주민증 혜택업체 0곳 (도산면 2.4%에 6곳) | L10: 안동역 막차 21~22시 → 릴레이 18:30~21:00 | Q10: 원도심→월영교 19시 이후 버스 0회 (112번 막차 18:45)
B15: ⑤ 월영교의 빈자리 | G15: ⑥ 기대효과 | L15: ⑦ 효과 평가 | Q15: ⑧ 전국 확산
B16: 21시까지 식사 3곳/16곳 주점 0곳 소비 배율 0.40 | G16: 확대안 체험 결제 13,684건 체험·문화 격차의 22% | L16: 추첨 순서로 열어 비교 83곳이면 5개월 안에 +50% 효과부터 판정 | Q16: 144개 시·군 자가 진단 안동과 같은 유형 7곳
B22: 쓰는 법
B23: ● 노란 칸 = 직접 바꿔 보는 값. 목록(▼)을 고르거나 숫자를 넣으면 그 화면의 숫자 카드와 차트가 바로 다시 계산됩니다.
B24: ● 위쪽 파란 메뉴를 누르면 다른 화면으로 이동합니다. 원자료와 계산 시트는 숨겨 두었습니다(시트 탭 오른쪽 클릭 → 숨기기 취소로 볼 수 있음).
B25: ● 기대효과 화면은 1만 번이 아니라 3,000번 모의실험을 엑셀 안에서 다시 돌립니다(F9 = 다시 뽑기). 보고서 숫자는 파이썬 1만 회 결과입니다.
B26: ● 모든 예상 효과는 시행 전 조건부 값입니다. 실제 효과는 「효과 평가」 화면의 방법으로 시행 후에 판정합니다.
B28: 결과물 7개와 화면
B29: 결과물 | I29: 화면 | L29: 상태
B30: ① 식음→체험 연결(혜택 배치 진단) | I30: 혜택 배치 | L30: 완료 · 체험 연결 경로표는 시행 후
B31: ② 운영 시간 창 | I31: 운영 시간 | L31: 완료
B32: ③ 교통 공백 확인 | I32: 버스(BIS) | L32: 버스 완료 · 택시 실측은 못 함(시행 전 필요)
B33: ④ 야간 팝업(영업 종료·업종 공백) | I33: 월영교 야간 | L33: 완료 · 월영교 현장 확인 조사일 기록 보완
B34: ⑤ 행동검증·예상 효과 | I34: 기대효과 | L34: 완료 · 시행 첫 달 기록으로 갱신(현장조사 못 함)
B35: ⑥ 시행 후 효과 평가 계획 | I35: 효과 평가 | L35: 완료
B36: ⑦ 전국 진단표 | I36: 전국 진단 | L36: 완료
B37: (보조) 팀 온라인 설문 103명(방문 경험 72명) | I37: 방문객 설문 | L37: 완료 · 9/23~24 구글폼, 의향은 참여율 아님

Sheet 1_문제
B1: 문제 · 방문은 늘었는데 체험·문화 소비는 줄었다
B3: 관광객 감소도, 당일치기 증가도 아니다. 방문당 체험·문화 소비만 전국보다 크게 줄었다(2024→2026년 1~8월, 외지인)
B5: 홈 | C5: 문제 | D5: 혜택 배치 | E5: 운영 시간 | F5: 버스(BIS) | G5: 월영교 야간 | H5: 기대효과 | I5: 효과 평가 | J5: 전국 진단 | K5: 서식4 | L5: 방문객 설문 | M5: 데이터 출처
B6: 비교할 시·군 ▼
B7: 경주시 | F7: ← 목록에서 시·군을 고르면 파란 카드와 차트의 파란 막대가 그 지역으로 바뀝니다(빨강 = 안동)
B9: 안동 · 외지인 방문 변화율 | F9: 안동 · 방문당 관광소비 변화율 | J9: 안동 · 방문당 체험·문화 소비 변화율 | N9: 안동 · 체험·문화 감소폭 순위
B10: =INDEX('d_시군'!$H$2:$H$147,MATCH("안동시",'d_시군'!$A$2:$A$147,0)) | F10: =INDEX('d_시군'!$I$2:$I$147,MATCH("안동시",'d_시군'!$A$2:$A$147,0)) | J10: =INDEX('d_시군'!$J$2:$J$147,MATCH("안동시",'d_시군'!$A$2:$A$147,0)) | N10: =MATCH("안동시",'d_시군'!$A$2:$A$147,0)
B12: ="전국 중앙 "&TEXT(MEDIAN('d_시군'!$H$2:$H$147),"+0.0%;-0.0%") | F12: ="전국 중앙 "&TEXT(MEDIAN('d_시군'!$I$2:$I$147),"+0.0%;-0.0%") | J12: ="전국 중앙 "&TEXT(MEDIAN('d_시군'!$J$2:$J$147),"+0.0%;-0.0%") | N12: 146개 시·군 중(1위 = 가장 많이 줄어듦)
B14: ="선택 · "&'1_문제'!$B$7&" · 외지인 방문 변화율" | F14: ="선택 · "&'1_문제'!$B$7&" · 방문당 관광소비 변화율" | J14: ="선택 · "&'1_문제'!$B$7&" · 방문당 체험·문화 소비 변화율" | N14: ="선택 · "&'1_문제'!$B$7&" · 감소폭 순위"
B15: =INDEX('d_시군'!$H$2:$H$147,MATCH('1_문제'!$B$7,'d_시군'!$A$2:$A$147,0)) | F15: =INDEX('d_시군'!$I$2:$I$147,MATCH('1_문제'!$B$7,'d_시군'!$A$2:$A$147,0)) | J15: =INDEX('d_시군'!$J$2:$J$147,MATCH('1_문제'!$B$7,'d_시군'!$A$2:$A$147,0)) | N15: =MATCH('1_문제'!$B$7,'d_시군'!$A$2:$A$147,0)
B17: ="안동과 차이 "&TEXT((INDEX('d_시군'!$H$2:$H$147,MATCH('1_문제'!$B$7,'d_시군'!$A$2:$A$147,0))-INDEX('d_시군'!$H$2:$H$147,MATCH("안동시",'d_시군'!$A$2:$A$147,0)))*100,"+0.0;-0.0")&"%p" | F17: ="안동과 차이 "&TEXT((INDEX('d_시군'!$I$2:$I$147,MATCH('1_문제'!$B$7,'d_시군'!$A$2:$A$147,0))-INDEX('d_시군'!$I$2:$I$147,MATCH("안동시",'d_시군'!$A$2:$A$147,0)))*100,"+0.0;-0.0")&"%p" | J17: ="안동과 차이 "&TEXT((INDEX('d_시군'!$J$2:$J$147,MATCH('1_문제'!$B$7,'d_시군'!$A$2:$A$147,0))-INDEX('d_시군'!$J$2:$J$147,MATCH("안동시",'d_시군'!$A$2:$A$147,0)))*100,"+0.0;-0.0")&"%p" | N17: 146개 시·군 중
B57: 읽는 법: 관광객 감소(방문 +5.6%)도, 당일치기 증가(무박 86.3→86.4%, 2019→2025)도 아니다. 방문당 체험·문화 소비는 −16.8%로 전국 146곳 중 감소폭 22번째다. 다만 체험·문화는 관광소비의 약 1%이고, 하락의 3분의 2는 문화서비스가 2025년 중반 한 번에 꺾인 것이라 원인을 한 가지로 단정하지 않는다. 외식·숙박은 전국보다 잘 되고 있다. 오른쪽 차트의 "전국 중앙 추세 대비 차이" = 2026년 값 − 2024년 값 × (1 + 그 업종의 146곳 중앙 변화율).
B58: 출처: 한국관광 데이터랩 외지인 신용카드 소비(BDT_02_01_003, 업종 중분류) ÷ 외지인 방문 연인원(BDT_01_01_006), 2024·2026년 1~8월. 체험·문화 = 문화서비스 + 관광유원시설 + 기타레저.

Sheet 2_혜택배치
B1: 혜택 배치 · 사람이 모이는 곳에 혜택이 없다
B3: 외지인 방문 1위 중구동(원도심)에 주민증 혜택업체 0곳, 12위 도산면에 6곳. 혜택을 옮기면 어긋남이 얼마나 줄어드는지 바꿔 보세요
B5: 홈 | C5: 문제 | D5: 혜택 배치 | E5: 운영 시간 | F5: 버스(BIS) | G5: 월영교 야간 | H5: 기대효과 | I5: 효과 평가 | J5: 전국 진단 | K5: 서식4 | L5: 방문객 설문 | M5: 데이터 출처
B6: 혜택을 추가할 동 ▼ | G6: 추가할 업체 수
B7: 중구동 | G7: 0 | J7: ← 동을 고르고 업체 수를 넣으면 카드와 차트(빨강)에 반영됩니다
B9: 중구동 혜택업체(추가 반영) | F9: 방문 상위 5개 동의 혜택 비중 | J9: 방문과 혜택의 어긋남 지수 | N9: 주민증 이용 중 관람지 비중
B10: =INDEX('d_혜택'!$E$2:$E$25,MATCH("중구동",'d_혜택'!$A$2:$A$25,0)) | F10: =SUM('d_혜택'!$E$2:$E$6)/SUM('d_혜택'!$E$2:$E$25) | J10: =0.5*SUMPRODUCT(ABS('d_혜택'!$G$2:$G$25-'d_혜택'!$F$2:$F$25)) | N10: 0.95438785
B12: 추가 전 0곳 (방문 점유율 12.5%, 1위) | F12: ="추가 전 "&TEXT(SUM('d_혜택'!$C$2:$C$6)/SUM('d_혜택'!$C$2:$C$25),"0%")&" · 방문 비중은 "&TEXT(SUM('d_혜택'!$G$2:$G$6),"0%") | J12: ="추가 전 "&TEXT(0.5*SUMPRODUCT(ABS('d_혜택'!$G$2:$G$25-'d_혜택'!$C$2:$C$25/SUM('d_혜택'!$C$2:$C$25))),"0%")&" · 0% = 방문 비중대로 배치" | N12: 체험 0.9% (월 약 7건) · 이용 표시 합계 20,477건
B33: 주민증 가맹 업체별 이용 표시(누적, 2024.6~2026.9)
B34: 업체 | D34: 분류 | E34: 행정동 | F34: 이용 표시(건) | G34: 방문 1만 회당 월 이용
B35: 하회마을 | D35: 관람 | E35: 풍천면 | F35: 11045 | G35: 21.8931
B36: 도산서원 | D36: 관람 | E36: 도산면 | F36: 5039 | G36: 34.4895
B37: 안동문화관광단지 유교랜드 | D37: 관람 | E37: 용상동 | F37: 2505 | G37: 5.0551
B38: 이육사문학관 | D38: 관람 | E38: 도산면 | F38: 483 | G38: 3.3059
B39: 한국문화테마파크 | D39: 관람 | E39: 도산면 | F39: 356 | G39: 2.4366
B40: 황소곳간식당 | D40: 식음료 | E40: 풍산읍 | F40: 223 | G40: 0.3965
B41: 카페구름마루 | D41: 식음료 | E41: 용상동 | F41: 137 | G41: 0.2765
B42: 세계유교문화박물관 | D42: 관람 | E42: 도산면 | F42: 115 | G42: 0.7871
B43: 계명산자연휴양림 | D43: 숙박 | E43: 길안면 | F43: 97 | G43: 0.7447
B44: 우렁각시장어총각 | D44: 식음료 | E44: 용상동 | F44: 94 | G44: 0.1897
B45: 카페 브레드79 | D45: 식음료 | E45: 옥동 | F45: 48 | G45: 0.0782
B46: 현도예 | D46: 체험 | E46: 태화동 | F46: 42 | G46: 0.1589
... B60: 산숲 | D60: 식음료 | E60: 길안면 | F60: 4 | G60: 0.0307
B62: 읽는 법: 혜택은 유교문화 관람지에 몰려 있고, 사람이 가장 많은 원도심에는 없다. 업체 이용도 관람지(하회마을·도산서원·유교랜드)에 95%가 몰린다. 주민증 가맹 26곳의 이용 건수를 회귀분석했다(업체마다 차이가 너무 커서 포아송 대신 음이항, 과산포 검정 p = 0.001). 이용을 가른 건 업종이고(관람지는 식당의 약 47배), 업체가 있는 동에 방문이 많아도 이용은 거의 늘지 않았다(유의하지 않음) → 혜택을 옮기는 것만으로는 부족하고 체험으로 잇는 장치가 필요하다.
B63: 출처: 데이터랩 읍면동별 외지인 방문자 수(BDT_01_01_005_1) · 안동시 정보공개청구 회신(혜택업체 27곳, 2026-09-18) · 한국관광공사 주민증 누리집 가맹점 이용 표시(2026-09-21 조회) · 소상공인 상가정보(행정동 대조)
B64: 방문객 설문(96명 응답): 유료 체험을 망설이는 이유는 정보 부족 35% · 줄·예약 불편 32% · 이동 시간 부족 16% · 가격 14% → 혜택은 할인만이 아니라 체험 정보·예약을 잇는 쪽으로. 자세히는 「방문객 설문」 화면.

Sheet 3_운영시간
B1: 운영 시간 창 · 안동역 막차가 릴레이의 끝을 정한다
B3: 주말 저녁 승차는 18~19시에 가장 많고, 막차는 21~22시다. 릴레이 시작·종료 시각을 바꿔 창 안에 들어오는 승차를 확인해 보세요
B5: 홈 | C5: 문제 | D5: 혜택 배치 | E5: 운영 시간 | F5: 버스(BIS) | G5: 월영교 야간 | H5: 기대효과 | I5: 효과 평가 | J5: 전국 진단 | K5: 서식4 | L5: 방문객 설문 | M5: 데이터 출처
B6: 연도 ▼ | E6: 요일 구분 ▼ | H6: 열차 ▼ | K6: 릴레이 시작(시) | N6: 릴레이 종료(시)
B7: 2026 | E7: 주말 | H7: 전체 | K7: 18.5 | N7: 21
B9: 저녁(17~22시) 최대 승차 시간대 | F9: 마지막 승차 시간대(막차) | J9: 릴레이 창 안 승차 비중 | N9: 종료 후 막차까지 여유
B10: =INDEX('d_역계산'!$A$14:$A$18,MATCH(MAX('d_역계산'!$C$14:$C$18),'d_역계산'!$C$14:$C$18,0)) | F10: =LOOKUP(2,1/('d_역계산'!$C$2:$C$20>0),'d_역계산'!$A$2:$A$20) | J10: =SUMIFS('d_역계산'!$C$2:$C$20,'d_역계산'!$B$2:$B$20,">="&INT('3_운영시간'!$K$7),'d_역계산'!$B$2:$B$20,"<"&'3_운영시간'!$N$7)/SUM('d_역계산'!$C$2:$C$20) | N10: =MAX(0,LOOKUP(2,1/('d_역계산'!$C$2:$C$20>0),'d_역계산'!$B$2:$B$20)+1-'3_운영시간'!$N$7)
B12: ="승차 "&TEXT(MAX('d_역계산'!$C$14:$C$18),"#,##0")&"명 (1~8월 합계)" | F12: ="22시 이후 승차 "&TEXT(SUM('d_역계산'!$C$19:$C$20),"#,##0")&"명" | J12: ="창 "&TEXT('3_운영시간'!$K$7/24,"hh:mm")&"~"&TEXT('3_운영시간'!$N$7/24,"hh:mm") | N12: =IF('3_운영시간'!$N$7>LOOKUP(2,1/('d_역계산'!$C$2:$C$20>0),'d_역계산'!$B$2:$B$20)+1,"막차 이후 → 귀가 수단 없음",IF('3_운영시간'!$N$7>LOOKUP(2,1/('d_역계산'!$C$2:$C$20>0),'d_역계산'!$B$2:$B$20),"막차 시간대와 겹침 → 여유 없음","막차 전에 끝남"))
B48: 읽는 법: 시간 분포는 수요가 아니라 열차 시각표를 반영한다(22시 이후 0 = 열차가 없음). 그래서 막차가 설계의 제약 조건이 되고, 릴레이는 18:30에 시작해 21:00에 끝나야 막차 전에 닿는다. 승차 인원에는 주민이 섞여 있어 "관광객"이라 부르지 않는다. 값은 그 달 해당 요일 전체의 합이다.
B49: 출처: 코레일 안동역 월별·요일별·시간대별 승하차(KTX-이음·새마을·무궁화, 2024.1~2026.8, 팀원 취합), 연도 간 비교를 위해 1~8월만 합산
B50: 방문객 설문: 당일 귀가한 방문자 40명 중 23명(58%)이 20~22시 막차 시간대에 귀가했다고 답했다 → 릴레이가 21시 전에 끝나야 하는 이유와 같은 방향. 자세히는 「방문객 설문」 화면.

Sheet 4_버스
B1: 버스(BIS) · 원도심에서 월영교로 가는 밤길이 끊긴다
B3: 안동역↔원도심은 밤 10시까지 다니지만 원도심→월영교는 112번 한 노선, 하루 6회, 19시 이후 0회다. 노선을 고르고 저녁 운행을 추가해 보세요
B5: 홈 | C5: 문제 | D5: 혜택 배치 | E5: 운영 시간 | F5: 버스(BIS) | G5: 월영교 야간 | H5: 기대효과 | I5: 효과 평가 | J5: 전국 진단 | K5: 서식4 | L5: 방문객 설문 | M5: 데이터 출처
B6: 노선 ▼ | E6: 시간표 ▼ | H6: 19~21시 원도심→월영교 추가 운행
B7: 112 | E7: 평일 | H7: 0 | L7: ← 추가 운행 횟수를 넣으면 카드와 빨간 선에 반영됩니다
B9: 선택 노선 운행 횟수 | F9: 원도심→월영교 19시 이후 운행(추가 반영) | J9: 안동역→원도심 19시 이후 운행 | N9: 버스정보 안내기 설치 정류장
B10: =SUM('d_버스계산'!$B$2:$B$20) | F10: =SUM('d_버스계산'!$I$16:$I$20) | J10: =SUM('d_버스계산'!$C$16:$C$20) | N10: 316
B12: =IF(SUM('d_버스계산'!$B$2:$B$20)=0,"이 시간표에는 운행 없음","첫차 "&TEXT(MIN('d_버스출발'!$D$2:$D$1398),"hh:mm")&" · 막차 "&TEXT(MAX('d_버스출발'!$D$2:$D$1398),"hh:mm")) | F12: 추가 전 0회 · 112번 원도심 출발 막차 18:45(기점) | J12: 막차 22:10 · 원도심→안동역 막차 22:40 | N12: 전체 3,309곳 중 · 월영교 500m 4곳 중 1곳
B59: 읽는 법: 버스 시각은 기점 출발 시각이라 구간 통과는 더 늦다. 공휴일 시간표가 없는 노선이 많아 토요일 운행은 단정하지 않는다. 추가 운행 칸은 "관광택시 저녁 재배치나 셔틀로 몇 회를 채우면" 그래프가 어떻게 바뀌는지 보는 가정이다.
B60: 출처: 안동시 버스정보시스템 누리집 공개 시간표·노선·정류장(2026-09-22 조회, 46개 노선·3,309개 정류장, 안내기 = bitYn), 국토교통부 전국 버스정류장 위치정보(대조)
B61: 방문객 설문: 시내버스로 다닌 방문자 30명 중 22명(73%)이 '불편했다'. 이동이 불편해 포기한 곳 1위는 월영교 같은 야간 명소(46%, 33/71).

Sheet 5_월영교
B1: 월영교 야간 · 사람은 모이는데 쓸 곳이 없다
B3: 외곽 방문자의 54%가 월영교에 들르지만 소비 배율은 0.40, 21시까지 식사 가능한 곳은 16곳 중 3곳, 주점 0곳. 팝업을 넣어 빈자리를 채워 보세요
B5: 홈 | C5: 문제 | D5: 혜택 배치 | E5: 운영 시간 | F5: 버스(BIS) | G5: 월영교 야간 | H5: 기대효과 | I5: 효과 평가 | J5: 전국 진단 | K5: 서식4 | L5: 방문객 설문 | M5: 데이터 출처
B6: 팝업 식사·주점 부스 | E6: 팝업 종료 시각(시) | H6: 관광지 ▼
B7: 8 | E7: 22 | H7: 월영교
B9: 21시까지 식사 가능한 곳(팝업 반영) | F9: 주점(팝업 반영) | J9: 선택 관광지 소비 전환 배율 | N9: 외곽 방문자 중 월영교도 방문
B10: =COUNTIFS('d_월영교'!$D$2:$D$17,1,'d_월영교'!$C$2:$C$17,">=21")+IF('5_월영교'!$E$7>=21,'5_월영교'!$B$7,0) | F10: =IF('5_월영교'!$E$7>=21,'5_월영교'!$B$7,0) | J10: =INDEX('d_철도'!$D$2:$D$20,MATCH('5_월영교'!$H$7,'d_철도'!$A$2:$A$20,0)) | N10: 0.548
B12: ="팝업 전 3곳 · 식사 가능 비중 "&TEXT((COUNTIFS('d_월영교'!$D$2:$D$17,1,'d_월영교'!$C$2:$C$17,">=21")+IF('5_월영교'!$E$7>=21,'5_월영교'!$B$7,0))/(16+'5_월영교'!$B$7),"0%") | F12: 팝업 전 0곳 (원도심 1km는 764곳 중 86곳) | J12: ="방문 "&TEXT(INDEX('d_철도'!$B$2:$B$20,MATCH('5_월영교'!$H$7,'d_철도'!$A$2:$A$20,0)),"0.0")&"% vs 소비건수 "&TEXT(INDEX('d_철도'!$C$2:$C$20,MATCH('5_월영교'!$H$7,'d_철도'!$A$2:$A$20,0)),"0.0")&"% (2022.4~6)" | N12: 만휴정 54.8% · 도산서원 54.2% (철도공사 연관규칙)
B58: 읽는 법: 월영교는 외곽을 돈 방문객이 돌아오며 모이는 곳인데, 반경 1km 식당 대부분이 20:30 전에 닫고 22시 이후엔 카페만 남으며 주점은 없다. 18시 이후 운영하는 체험도 문보트·황포돛배뿐이다. 팝업은 21시 이후 식사·주류를 채우는 자리이며, 부스 수는 처리량·부지 조건 확인 후 정한다(예시 8개 = 2026 월영장터 장터 규모). 참고로 연 10일인 월영야행 기간에도 권역 월 소비가 통계적으로 늘지 않았다 → 상시 운영·원도심 연결이 필요한 이유.
B59: 출처: 소상공인 상가(상권)정보(2026-06-30) · 팀 현장 확인(영업 종료, 2026-09 확인, 조사일·방법 보완 예정) · 한국철도공사 8대 도시(안동) 관광 형태 분석(2022.4~6, 소비는 건수)
B60: 방문객 설문: 20시 이후 월영교 주변 식당·편의시설이 '부족·매우 부족' 53%(38/72), '충분' 3%(2명). 21~23시 팝업 포차는 방문자 82%가 긍정(의향이지 이용률이 아님).

Sheet 6_기대효과
B1: 기대효과 · 3단계를 이으면 무엇이 얼마나 바뀌나
B3: 시나리오와 핵심 값 몇 개를 바꾸면 3,000번 모의실험이 다시 돌아갑니다. 숫자는 시행 전 조건부 예상이며, 가장 큰 가정은 시행 첫 달에 실측해 바꿉니다
B5: 홈 | C5: 문제 | D5: 혜택 배치 | E5: 운영 시간 | F5: 버스(BIS) | G5: 월영교 야간 | H5: 기대효과 | I5: 효과 평가 | J5: 전국 진단 | K5: 서식4 | L5: 방문객 설문 | M5: 데이터 출처
B6: 시나리오 ▼ | E6: 참여 식당 수(직접 입력 시) | H6: 운영 개월 | K6: 팝업 부스 수 | N6: 참여율(직접 입력 시)
B7: 확대안 | E7: 40 | H7: 8 | K7: 8 | N7: 0.02
B8: 시나리오: 기본안 = 식당 20곳, 참여율 실측 기반(0.1~0.9%, 안동 주민증·반값여행·하회마을) / 확대안 = 83곳, 계산대 직접 권유(0.46~5%, 가정) / 직접 입력 = 입력한 식당 수, 참여율을 중앙값으로 ±50%. 나머지 가정(체험 결제율, 완주율, 반사실 등)은 데이터로 추정한 분포로 고정.
B9: ="지금 적용된 값: 참여 식당 "&'d_시나리오'!$I$7&"곳 · 참여율 "&TEXT('d_시나리오'!$H$2,"0.00%")&" ~ "&TEXT('d_시나리오'!$J$2,"0.00%")&"(최빈 "&TEXT('d_시나리오'!$I$2,"0.00%")&") · 운영 "&'6_기대효과'!$H$7&"개월 · 팝업 부스 "&'6_기대효과'!$K$7&"개"
B10: 체험 결제(낮 + 저녁 문보트) | F10: 방문당 체험·문화 소비 증가(안동 전체) | J10: 안동 내 추가 소비(원래 썼을 돈 제외) | N10: 단계를 이어야만 생기는 몫
B11: =MEDIAN('d_모의실험'!$T$2:$T$3001) | F11: =MEDIAN('d_모의실험'!$Y$2:$Y$3001) | J11: =MEDIAN('d_모의실험'!$X$2:$X$3001)/100000000 | N11: =MEDIAN('d_모의실험'!$W$2:$W$3001)/MEDIAN('d_모의실험'!$X$2:$X$3001)
B13: ="90% 범위 "&TEXT(PERCENTILE('d_모의실험'!$T$2:$T$3001,0.05),"#,##0")&" ~ "&TEXT(PERCENTILE('d_모의실험'!$T$2:$T$3001,0.95),"#,##0") | F13: ="회복 목표 +17.7% 중 "&TEXT(MEDIAN('d_모의실험'!$Z$2:$Z$3001),"0%")&" 메움" | J13: ="90% 범위 "&TEXT(PERCENTILE('d_모의실험'!$X$2:$X$3001,0.05)/1E8,"0.00")&" ~ "&TEXT(PERCENTILE('d_모의실험'!$X$2:$X$3001,0.95)/1E8,"0.00")&"억" | N13: ="저녁 문보트 결제 "&TEXT(MEDIAN('d_모의실험'!$S$2:$S$3001),"#,##0")&"건 (단계를 따로 하면 0)"
B15: 릴레이 인증(월) | F15: 저녁 원도심→월영교 이동(주말 하루) | J15: 월영교 21시 식사 가능 / 주점 | N15: 회복 목표(179.7원) 도달 확률
B16: =MEDIAN('d_모의실험'!$P$2:$P$3001)/'6_기대효과'!$H$7 | F16: =MEDIAN('d_모의실험'!$R$2:$R$3001)/(70*'6_기대효과'!$H$7/8) | J16: ="3→"&(3+'6_기대효과'!$K$7)&"곳 / 0→"&'6_기대효과'!$K$7&"곳" | N16: =COUNTIF('d_모의실험'!$Y$2:$Y$3001,">="&('d_고정'!$B$7/'d_고정'!$B$6-1))/3000
B18: ="현재 주민증 월 이용 888건의 "&TEXT(MEDIAN('d_모의실험'!$P$2:$P$3001)/'6_기대효과'!$H$7/888,"0.0")&"배" | F18: ="4인 택시 하루 "&ROUNDUP(MEDIAN('d_모의실험'!$R$2:$R$3001)/(70*'6_기대효과'!$H$7/8)/4,0)&"회 필요 (재배치 한도 12회)" | J18: 팝업 부스를 21시 이후 운영할 때 | N18: 3,000번 중 목표 이상이 나온 비율
B38: 계산 방법: 인증 = 중구동 외지인 방문 × (참여 식당 ÷ 83곳) × 참여율 → 낮 체험 결제·저녁 월영교 도착(자연 완주율 15~17%, 철도공사 역산) → 문보트·팝업 결제. 원래 썼을 돈(반사실, 평균 50%)을 뺀 것이 추가 소비다. 참여율 하한은 주민증 26곳 이용 회귀, 최빈은 반값여행 1차 신청, 상한은 하회마을 이용률. 체험 가격(27개)·축제 객단가(56개)는 실측 분포.
B39: 주의: 시행 전 조건부 예상이다(90% 범위 = 가정한 분포에서 나온 모의실험 구간, 신뢰구간 아님). 효과가 원도심에서 생기므로 안동 전체 %로는 작게 보인다. 사업 규모 지표(체험 결제·인증·운행)와 함께 읽는다.
B40: 필요 조건(파이썬 1만 회, 중앙값): 참여율 0.1% → 격차의 1% / 0.5% → 격차의 5% / 1% → 격차의 9% / 2% → 격차의 19% / 5% → 격차의 47% / 10% → 격차의 94% (확대안 83곳). 격차의 절반을 메우려면 참여율 5.3%가 필요하고, 지금까지 확인된 이용률은 1% 이하다. 참여율 칸에 시행 첫 달 인증률을 넣으면 바로 다시 계산된다.

Sheet 7_효과평가
B1: 효과 평가(시행 후) · 효과는 원인이 생기는 곳에서 재고, 증상으로 환산한다
B3: 도시 전체 지표로는 효과가 +24% 이상이어야 판정된다. 그래서 참여 식당을 추첨 순서로 열어 같은 달끼리 비교한다. 예상 효과를 넣어 판정 가능성을 확인해 보세요
B5: 홈 | C5: 문제 | D5: 혜택 배치 | E5: 운영 시간 | F5: 버스(BIS) | G5: 월영교 야간 | H5: 기대효과 | I5: 효과 평가 | J5: 전국 진단 | K5: 서식4 | L5: 방문객 설문 | M5: 데이터 출처
B6: 안동 전체 예상 효과 | E6: 순차 확대 설계 ▼ | J6: 참여 식당 손님 체험 결제 증가
B7: 0.04 | E7: 확대안 83곳·5개월 | J7: 1
B9: 도시 합성통제로 판정 가능? | F9: 순차 확대 검정력 | J9: 안동 사전 적합 순위 | N9: 효과 없는 기간의 거짓 양성
B10: =IF('7_효과평가'!$B$7>=0.24,"가능","어려움") | F10: =IFERROR(INDEX('d_검증'!$J$2:$L$8,MATCH(MIN(MAX('7_효과평가'!$J$7,0),1.0),'d_검증'!$I$2:$I$8,1),MATCH('7_효과평가'!$E$7,'d_검증'!$J$1:$L$1,0))+(MIN(MAX('7_효과평가'!$J$7,0),1.0)-INDEX('d_검증'!$I$2:$I$8,MATCH(MIN(MAX('7_효과평가'!$J$7,0),1.0),'d_검증'!$I$2:$I$8,1)))*(INDEX('d_검증'!$J$2:$L$8,MIN(MATCH(MIN(MAX('7_효과평가'!$J$7,0),1.0),'d_검증'!$I$2:$I$8,1)+1,7),MATCH('7_효과평가'!$E$7,'d_검증'!$J$1:$L$1,0))-INDEX('d_검증'!$J$2:$L$8,MATCH(MIN(MAX('7_효과평가'!$J$7,0),1.0),'d_검증'!$I$2:$I$8,1),MATCH('7_효과평가'!$E$7,'d_검증'!$J$1:$L$1,0)))/(INDEX('d_검증'!$I$2:$I$8,MIN(MATCH(MIN(MAX('7_효과평가'!$J$7,0),1.0),'d_검증'!$I$2:$I$8,1)+1,7))-INDEX('d_검증'!$I$2:$I$8,MATCH(MIN(MAX('7_효과평가'!$J$7,0),1.0),'d_검증'!$I$2:$I$8,1))),INDEX('d_검증'!$J$2:$L$8,MATCH(MIN(MAX('7_효과평가'!$J$7,0),1.0),'d_검증'!$I$2:$I$8,1),MATCH('7_효과평가'!$E$7,'d_검증'!$J$1:$L$1,0))) | J10: 1 | N10: 0.87755102
B12: 최소 검출 효과 +24% (한 방향, p ≤ 0.10) | F12: 입력한 효과를 판정할 확률(80% 이상이면 충분) | J12: 후보 49곳 중(비교 조합이 과거를 가장 잘 따라감) | N12: 가짜 시행 한 방향 p (높을수록 정상)
B50: 읽는 법: 도시 지표(안동 전체)는 효과가 1,172만 방문에 희석되고 분기마다 크게 출렁여 +24% 이상만 판정된다. 참여 식당 손님 단위에서는 같은 효과가 약 2배(+100%, 반사실 50%)로 보여, 추첨 순서로 연 묶음과 아직 안 연 묶음을 같은 달에 비교하면 판정할 수 있다. 확인된 효과는 다시 "체험·문화 격차 중 몇 %를 메웠나"로 환산해 보고한다. 과거에 비교 조합이 안동을 잘 따라온 것은 방법이 쓸 만하다는 뜻이지 정책 효과의 증명이 아니다.
B51: 출처: 데이터랩 239개 시·군 월별 외지인 카드·방문 패널(2022.1~2026.6, 2024.9~12 카드 결측), 합성통제(사전 추세 상관 상위 10곳, 한 방향 순위 검정), 순차 확대 검정력은 포아송 고정효과 모의실험

Sheet 8_전국진단
B1: 전국 진단 · 안동과 같은 문제를 가진 시·군 찾기
B3: 시·군을 고르면 네 지표에서의 위치와 문제 유형이 나온다. 가중치를 바꿔 순위가 얼마나 흔들리는지도 확인해 보세요(점수보다 유형으로 읽는다)
B5: 홈 | C5: 문제 | D5: 혜택 배치 | E5: 운영 시간 | F5: 버스(BIS) | G5: 월영교 야간 | H5: 기대효과 | I5: 효과 평가 | J5: 전국 진단 | K5: 서식4 | L5: 방문객 설문 | M5: 데이터 출처
B6: 시·군 ▼ | E6: 가중치: 체험 | H6: 숙박 | K6: 저녁 | N6: 야간
B7: 안동시 | E7: 1 | H7: 1 | K7: 1 | N7: 1
B9: 진단 점수(0=좋음, 100=나쁨) | F9: 문제 유형(하위 25% 지표) | J9: 체험·문화 소비 변화율 | N9: 평균 숙박일수
B10: =INDEX('d_진단'!$J$2:$J$145,MATCH('8_전국진단'!$B$7,'d_진단'!$A$2:$A$145,0)) | F10: =IF(INDEX('d_진단'!$L$2:$L$145,MATCH('8_전국진단'!$B$7,'d_진단'!$A$2:$A$145,0))="","해당 없음",INDEX('d_진단'!$L$2:$L$145,MATCH('8_전국진단'!$B$7,'d_진단'!$A$2:$A$145,0))) | J10: =INDEX('d_진단'!$B$2:$B$145,MATCH('8_전국진단'!$B$7,'d_진단'!$A$2:$A$145,0)) | N10: =INDEX('d_진단'!$C$2:$C$145,MATCH('8_전국진단'!$B$7,'d_진단'!$A$2:$A$145,0))
B12: ="144곳 중 "&INDEX('d_진단'!$K$2:$K$145,MATCH('8_전국진단'!$B$7,'d_진단'!$A$2:$A$145,0))&"위" | F12: ="같은 유형 "&COUNTIF('d_진단'!$L$2:$L$145,INDEX('d_진단'!$L$2:$L$145,MATCH('8_전국진단'!$B$7,'d_진단'!$A$2:$A$145,0)))&"곳" | J12: ="문제 백분위 "&TEXT(INDEX('d_진단'!$F$2:$F$145,MATCH('8_전국진단'!$B$7,'d_진단'!$A$2:$A$145,0)),"0")&" · 중앙 "&TEXT(MEDIAN('d_진단'!$B$2:$B$145),"+0.0%;-0.0%") | N12: ="문제 백분위 "&TEXT(INDEX('d_진단'!$G$2:$G$145,MATCH('8_전국진단'!$B$7,'d_진단'!$A$2:$A$145,0)),"0")&" · 중앙 "&TEXT(MEDIAN('d_진단'!$C$2:$C$145),"0.00")&"일"
B33: 진단 점수 상위 10곳(가중치 반영, 실시간)
B34: 순위 | D34: 시·군 | F34: 점수 | H34: 유형
B35: 1 | D35: =INDEX('d_진단'!$A$2:$A$145,MATCH(LARGE('d_진단'!$J$2:$J$145,1),'d_진단'!$J$2:$J$145,0)) | F35: =LARGE('d_진단'!$J$2:$J$145,1) | H35: =INDEX('d_진단'!$L$2:$L$145,MATCH(LARGE('d_진단'!$J$2:$J$145,1),'d_진단'!$J$2:$J$145,0))
B36: 2 | D36: =INDEX('d_진단'!$A$2:$A$145,MATCH(LARGE('d_진단'!$J$2:$J$145,2),'d_진단'!$J$2:$J$145,0)) | F36: =LARGE('d_진단'!$J$2:$J$145,2) | H36: =INDEX('d_진단'!$L$2:$L$145,MATCH(LARGE('d_진단'!$J$2:$J$145,2),'d_진단'!$J$2:$J$145,0))
B37: 3 | D37: =INDEX('d_진단'!$A$2:$A$145,MATCH(LARGE('d_진단'!$J$2:$J$145,3),'d_진단'!$J$2:$J$145,0)) | F37: =LARGE('d_진단'!$J$2:$J$145,3) | H37: =INDEX('d_진단'!$L$2:$L$145,MATCH(LARGE('d_진단'!$J$2:$J$145,3),'d_진단'!$J$2:$J$145,0))
B38: 4 | D38: =INDEX('d_진단'!$A$2:$A$145,MATCH(LARGE('d_진단'!$J$2:$J$145,4),'d_진단'!$J$2:$J$145,0)) | F38: =LARGE('d_진단'!$J$2:$J$145,4) | H38: =INDEX('d_진단'!$L$2:$L$145,MATCH(LARGE('d_진단'!$J$2:$J$145,4),'d_진단'!$J$2:$J$145,0))
B39: 5 | D39: =INDEX('d_진단'!$A$2:$A$145,MATCH(LARGE('d_진단'!$J$2:$J$145,5),'d_진단'!$J$2:$J$145,0)) | F39: =LARGE('d_진단'!$J$2:$J$145,5) | H39: =INDEX('d_진단'!$L$2:$L$145,MATCH(LARGE('d_진단'!$J$2:$J$145,5),'d_진단'!$J$2:$J$145,0))
B40: 6 | D40: =INDEX('d_진단'!$A$2:$A$145,MATCH(LARGE('d_진단'!$J$2:$J$145,6),'d_진단'!$J$2:$J$145,0)) | F40: =LARGE('d_진단'!$J$2:$J$145,6) | H40: =INDEX('d_진단'!$L$2:$L$145,MATCH(LARGE('d_진단'!$J$2:$J$145,6),'d_진단'!$J$2:$J$145,0))
B41: 7 | D41: =INDEX('d_진단'!$A$2:$A$145,MATCH(LARGE('d_진단'!$J$2:$J$145,7),'d_진단'!$J$2:$J$145,0)) | F41: =LARGE('d_진단'!$J$2:$J$145,7) | H41: =INDEX('d_진단'!$L$2:$L$145,MATCH(LARGE('d_진단'!$J$2:$J$145,7),'d_진단'!$J$2:$J$145,0))
B42: 8 | D42: =INDEX('d_진단'!$A$2:$A$145,MATCH(LARGE('d_진단'!$J$2:$J$145,8),'d_진단'!$J$2:$J$145,0)) | F42: =LARGE('d_진단'!$J$2:$J$145,8) | H42: =INDEX('d_진단'!$L$2:$L$145,MATCH(LARGE('d_진단'!$J$2:$J$145,8),'d_진단'!$J$2:$J$145,0))
B43: 9 | D43: =INDEX('d_진단'!$A$2:$A$145,MATCH(LARGE('d_진단'!$J$2:$J$145,9),'d_진단'!$J$2:$J$145,0)) | F43: =LARGE('d_진단'!$J$2:$J$145,9) | H43: =INDEX('d_진단'!$L$2:$L$145,MATCH(LARGE('d_진단'!$J$2:$J$145,9),'d_진단'!$J$2:$J$145,0))
B44: 10 | D44: =INDEX('d_진단'!$A$2:$A$145,MATCH(LARGE('d_진단'!$J$2:$J$145,10),'d_진단'!$J$2:$J$145,0)) | F44: =LARGE('d_진단'!$J$2:$J$145,10) | H44: =INDEX('d_진단'!$L$2:$L$145,MATCH(LARGE('d_진단'!$J$2:$J$145,10),'d_진단'!$J$2:$J$145,0))
B46: 안동과 같은 유형(체험·문화 소비 하락 + 짧은 숙박) 6곳: 영덕군, 양양군, 남해군, 울진군, 광명시, 강릉시 → 이어드림 방식의 확산 후보. 같은 가중치로 안동은 57위지만 가중치를 무작위로 바꾸면 18~100위로 흔들린다 → 점수 하나로 순위를 매기지 않고 유형으로 읽는다.
B47: 지표(낮을수록 문제): ① 방문당 체험·문화 소비 변화율 2024→2026 1~8월 ② 평균 숙박일수 2025(LN_02_01_013) ③ 저녁 전환율 18~21시÷14~18시 ④ 야간(21~24시) 방문 비중, 2026 1~8월(BDT_01_01_006). 시·군 144곳(방문 100만 이상, 광역시 자치구 제외). 탐색 지표이며 정책 효과 점수가 아니다.

Sheet 9_서식4
B1: 서식4 활용사례 작성본(초안)
B3: 공모요강 서식4 양식 · 개조식 2~3장 · 함초롬바탕 11pt · 줄간격 160. 전체 파일은 보고서/서식4_20260923/
B5: 홈 | C5: 문제 | D5: 혜택 배치 | E5: 운영 시간 | F5: 버스(BIS) | G5: 월영교 야간 | H5: 기대효과 | I5: 효과 평가 | J5: 전국 진단 | K5: 서식4 | L5: 방문객 설문 | M5: 데이터 출처
B7: [서식 4]
B8: 『2026 한국관광 데이터랩 활용 경진대회』 작성양식
B9: 신청자(대표)인적사항 | 소속기관명: [팀 작성] 부서명: [팀 작성]성명: [팀 작성] 직명/직위: [팀 작성] 담당업무: [팀 작성] |
B10: 응모작 제목 | 사람이 모이는 곳엔 혜택이 없고, 막차 앞에서 밤이 끊긴다: 데이터로 다시 잇는 안동 이어드림 [팀 결정] |
B11: 한국관광 데이터랩(필수) | 지역별 관광 현황(외지인 방문자·요일·시간대, 읍면동 방문자), 신용카드 관광소비(업종별), 숙박 현황(평균 숙박일수), 중심-연관 관광지, 내비게이션 목적지 검색, 야간관광 현황, 축제 현황(방문자·관광소비) |
B12: 타분야 데이터(선택) | 코레일 안동역 시간대별 승하차(2024.1~2026.8), 한국철도공사 8대 도시(안동) 가명결합 분석(2022.4~6), 소상공인 상가(상권)정보(2026.6), 안동시 디지털관광주민증 혜택업체·이용 건수(정보공개청구), 주민증 가맹점별 이용 실적, 관광지식정보시스템 주요관광지점 입장객, 안동시 버스정보시스템 시간표, 팀 온라인 설문(103명, 2026.9.23~24), 팀 현장 확인(월영교 1km 음식점 영업 종료) |
B13: 성과분야(1개 선택) | 관광지 안전문제 해결 □ 마케팅 및 홍보 활성화 □ 매출·수익 등 경제적 성과 □전략수립 및 기획 ■ 상품 및 서비스 개발·개선 □ 앱·웹 등 서비스 개발 □ |
B14: 핵심성과(1-2줄 요약) | 데이터랩 방문·소비·시간대 데이터와 철도·상가·주민증 데이터를 결합해 "방문 1위 원도심에 혜택 0곳", "19시 이후 대중교통 0회·주점 0곳"의 공백을 찾고, 원도심과 월영교를 잇는 3단계 야간 릴레이의 운영안·효과 추정·시행 후 효과 평가 계획을 설계 |
B15: 계량성과 | 온라인 설문 103명(안동 방문 경험 72명) 수행 |
B16: 1) 문제점 또는 현안사항
B17: ○ 흔한 두 설명은 데이터로 기각: 관광객은 줄지 않았고(외지인 방문 +5.6%, 2024→2026년 1~8월), 당일치기도 늘지 않음(무박 비중 86.3% → 86.4%, 2019→2025년)
B18: ○ [체험·문화 소비 감소] 외지인 방문당 체험·문화 소비 183.5원 → 152.7원(−16.8%, 2024→2026년 1~8월), 전국 146개 시·군 중앙 −2.0%, 감소폭 22번째. 과거 추세가 비슷한 시·군 10곳의 조합과 비교해도 2025년 이후 안동만 낮아짐(합성통제)
... B55: * 관련 자료(참고자료 zip): 분석보고서(PDF)·데이터 대시보드(엑셀), 전국 진단표(엑셀), 분석 스크립트

Sheet 10_설문
B1: 방문객 설문 · 방문객이 직접 말한 불편과 의향
B3: 팀 온라인 설문 103명(최근 3년 안에 안동 방문 72명, 2026.9.23~24). 응답자 범위와 이동수단을 바꿔 보세요. 불편·부족은 근거로, 의향은 참여율이 아니라 수요의 방향으로만 읽습니다
B5: 홈 | C5: 문제 | D5: 혜택 배치 | E5: 운영 시간 | F5: 버스(BIS) | G5: 월영교 야간 | H5: 기대효과 | I5: 효과 평가 | J5: 전국 진단 | K5: 서식4 | L5: 방문객 설문 | M5: 데이터 출처
B6: 응답자 범위 ▼ | E6: 이동수단 ▼
B7: 방문자만 | E7: 전체 | I7: ="선택한 응답자 "&'d_설문계산'!$B$3&"명"
B9: 시내버스 이용자 중 "불편했다" | F9: 이동이 불편해 월영교 등 야간 명소 포기 | J9: 20시 이후 월영교 식당·편의시설 부족 | N9: 당일 귀가자 중 20~22시(막차) 귀가
B10: =IFERROR(COUNTIFS('d_설문'!$A$2:$A$104,'d_설문계산'!$B$1,'d_설문'!$B$2:$B$104,'d_설문계산'!$B$2,'d_설문'!$C$2:$C$104,1,'d_설문'!$D$2:$D$104,"불편했다")/COUNTIFS('d_설문'!$A$2:$A$104,'d_설문계산'!$B$1,'d_설문'!$B$2:$B$104,'d_설문계산'!$B$2,'d_설문'!$C$2:$C$104,1),"해당 없음") | F10: =IFERROR(COUNTIFS('d_설문'!$A$2:$A$104,'d_설문계산'!$B$1,'d_설문'!$B$2:$B$104,'d_설문계산'!$B$2,'d_설문'!$I$2:$I$104,1,'d_설문'!$F$2:$F$104,1)/COUNTIFS('d_설문'!$A$2:$A$104,'d_설문계산'!$B$1,'d_설문'!$B$2:$B$104,'d_설문계산'!$B$2,'d_설문'!$I$2:$I$104,1),"해당 없음") | J10: =IFERROR(COUNTIFS('d_설문'!$A$2:$A$104,'d_설문계산'!$B$1,'d_설문'!$B$2:$B$104,'d_설문계산'!$B$2,'d_설문'!$J$2:$J$104,"부족")/COUNTIFS('d_설문'!$A$2:$A$104,'d_설문계산'!$B$1,'d_설문'!$B$2:$B$104,'d_설문계산'!$B$2,'d_설문'!$J$2:$J$104,"<>미응답"),"해당 없음") | N10: =IFERROR(COUNTIFS('d_설문'!$A$2:$A$104,'d_설문계산'!$B$1,'d_설문'!$B$2:$B$104,'d_설문계산'!$B$2,'d_설문'!$L$2:$L$104,"20-22시(막차)")/COUNTIFS('d_설문'!$A$2:$A$104,'d_설문계산'!$B$1,'d_설문'!$B$2:$B$104,'d_설문계산'!$B$2,'d_설문'!$L$2:$L$104,"<>미응답",'d_설문'!$L$2:$L$104,"<>숙박"),"해당 없음")
B12: ="주 이동수단이 시내버스인 사람 중 "&COUNTIFS('d_설문'!$A$2:$A$104,'d_설문계산'!$B$1,'d_설문'!$B$2:$B$104,'d_설문계산'!$B$2,'d_설문'!$C$2:$C$104,1,'d_설문'!$D$2:$D$104,"불편했다")&"명 / "&COUNTIFS('d_설문'!$A$2:$A$104,'d_설문계산'!$B$1,'d_설문'!$B$2:$B$104,'d_설문계산'!$B$2,'d_설문'!$C$2:$C$104,1)&"명" | F12: ="포기한 곳 문항 응답자 중 "&COUNTIFS('d_설문'!$A$2:$A$104,'d_설문계산'!$B$1,'d_설문'!$B$2:$B$104,'d_설문계산'!$B$2,'d_설문'!$I$2:$I$104,1,'d_설문'!$F$2:$F$104,1)&"명 / "&COUNTIFS('d_설문'!$A$2:$A$104,'d_설문계산'!$B$1,'d_설문'!$B$2:$B$104,'d_설문계산'!$B$2,'d_설문'!$I$2:$I$104,1)&"명" | J12: ="부족·매우 부족 "&COUNTIFS('d_설문'!$A$2:$A$104,'d_설문계산'!$B$1,'d_설문'!$B$2:$B$104,'d_설문계산'!$B$2,'d_설문'!$J$2:$J$104,"부족")&"명 / "&COUNTIFS('d_설문'!$A$2:$A$104,'d_설문계산'!$B$1,'d_설문'!$B$2:$B$104,'d_설문계산'!$B$2,'d_설문'!$J$2:$J$104,"<>미응답")&"명" | N12: ="숙박자 제외 "&COUNTIFS('d_설문'!$A$2:$A$104,'d_설문계산'!$B$1,'d_설문'!$B$2:$B$104,'d_설문계산'!$B$2,'d_설문'!$L$2:$L$104,"20-22시(막차)")&"명 / "&COUNTIFS('d_설문'!$A$2:$A$104,'d_설문계산'!$B$1,'d_설문'!$B$2:$B$104,'d_설문계산'!$B$2,'d_설문'!$L$2:$L$104,"<>미응답",'d_설문'!$L$2:$L$104,"<>숙박")&"명"
B49: 이동수단 보정: 응답한 방문자 중 차 없는 사람이 46%로 실제(철도공사 추정 철도+버스 10.5%)보다 많다. 10.5 : 89.5로 다시 가중하면 긍정(있다+매우 있다) 비율은 체험 쿠폰 76% · 셔틀 70%(차 없음 94%, 자가용 67%) · 팝업 76% · 축제 혜택 78%.
B50: 읽는 법: "불편했다·부족했다·막차에 귀가"는 방문 경험이라 기존 데이터(112번 막차 18:45, 월영교 1km 주점 0곳, 안동역 막차 21~22시)를 뒷받침하는 근거로 쓴다. "이용하겠다"는 의향이라 실제 참여율로 쓰지 않는다. 기대효과 모의실험의 체험 결제율 r(평균 25%)은 그대로 두고, "매우 있다" 비율을 상한 참고로만 본다. 가격 때문에 망설인다는 응답은 14%뿐이라 1단계 혜택은 할인 폭보다 체험 정보·예약·동선을 잇는 데 무게를 둔다.
B51: 출처: 팀 온라인 설문(구글폼, 2026-09-23~24, 응답 103명, 편의 표본, 인구통계·개인정보 문항 없음). 안 가 본 응답자도 뒤 문항에 답해 경험 문항은 '방문자만'으로 보는 것이 기본. 정제 scripts/설문_정제.py · 집계 scripts/설문_분석.py

Sheet 11_출처
B1: 데이터 출처 · 무엇을 어디에 썼나
B3: 한국관광 데이터랩 8종 + 타분야 7종 + 팀 현장 확인(월영교 영업 종료) + 팀 온라인 설문. 모든 수치는 분석 스크립트로 다시 계산할 수 있다
B5: 홈 | C5: 문제 | D5: 혜택 배치 | E5: 운영 시간 | F5: 버스(BIS) | G5: 월영교 야간 | H5: 기대효과 | I5: 효과 평가 | J5: 전국 진단 | K5: 서식4 | L5: 방문객 설문 | M5: 데이터 출처
B7: 구분 | C7: 데이터 | D7: 제공처·코드 | E7: 기간 | F7: 쓴 화면
B8: 데이터랩 | C8: 외지인 신용카드 관광소비(업종 중분류) | D8: BDT_02_01_003 | E8: 2019~2026 | F8: 문제, 효과 평가, 전국 진단
B9: 데이터랩 | C9: 방문자 수 성별·연령·요일·시간대 교차표(외지인) | D9: BDT_01_01_006 | E9: 2019~2026 | F9: 문제, 기대효과, 전국 진단
B10: 데이터랩 | C10: 읍면동별 외지인 방문자 수 | D10: BDT_01_01_005_1 | E10: 2018~2026 | F10: 혜택 배치, 기대효과
B11: 데이터랩 | C11: 평균 숙박일수 | D11: LN_02_01_013 | E11: 2025 | F11: 전국 진단
B12: 데이터랩 | C12: 관심관광지·목적지 검색(내비) | D12: LN_03_01_037 · BDT_03_01_003_1 | E12: 2018~2026 | F12: 문제(하회마을 검색 비중)
B13: 데이터랩 | C13: 야간관광 현황(야간 검색·방문) | D13: BY_TH_NIGHT_TOUR | E13: 2024~2026 | F13: 월영교, 기대효과(완주율)
B14: 데이터랩 | C14: 축제 방문자·관광소비 | D14: FE_01_01_005 · 007 | E14: 2025 | F14: 기대효과(팝업 객단가)
B15: 데이터랩 | C15: 지역별 관광지출액(강남동 외지인) | D15: 화면 전사 | E15: 2023~2026 | F15: 기대효과, 월영야행 사건연구
B16: 타분야 | C16: 안동역 시간대별 승하차(이음·새마을·무궁화) | D16: 코레일(팀원 취합) | E16: 2024.1~2026.8 | F16: 운영 시간
B17: 타분야 | C17: 8대 도시(안동) 관광 형태 분석(가명결합) | D17: 한국철도공사 | E17: 2022.4~6 | F17: 월영교, 기대효과(완주율)
B18: 타분야 | C18: 상가(상권)정보 음식점 3,254곳 | D18: 소상공인시장진흥공단 | E18: 2026.6 | F18: 혜택 배치, 월영교
... B25: 전화 | C25: 관광택시 운행 관행 · 월영야행 부지 | D25: 안동시관광협의회 · 한국정신문화재단 | E25: 2026-09-22 | F25: 기대효과, 월영교
B27: 분석 스크립트(저장소 scripts/): 교수브리핑_수치.py · 이어드림_파라미터추정.py · 이어드림_시뮬레이션.py · 이어드림_사후검증_패널.py · 이어드림_사후검증_합성통제.py · 이어드림_순차도입_검정력.py · 전국진단표.py · 설문_정제.py · 설문_분석.py · 교수님_통합대시보드.py

Sheet d_시군
A1: 시군 | B1: 방문_2024 | C1: 방문_2026 | D1: 관광소비_방문당_2024 | E1: 관광소비_방문당_2026 | F1: 체험문화_2024 | G1: 체험문화_2026 | H1: 방문_변화율 | I1: 관광소비_변화율 | J1: 체험문화_변화율 | L1: 전체 | M1: 안동 | N1: 선택
A2: 울진군 | B2: 5373040 | C2: 5814482 | D2: 12158.792 | E2: 14386.692 | F2: 267.89713 | G2: 123.45227 | H2: 0.082158703 | I2: 0.18323362 | J2: -0.53918032 | L2: =J2 | M2: =IF(A2="안동시",J2,"") | N2: =IF(A2='1_문제'!$B$7,J2,"")
A3: 남해군 | B3: 5683426 | C3: 6132203 | D3: 11352.58 | E3: 13021.564 | F3: 242.12297 | G3: 116.03171 | H3: 0.078962408 | I3: 0.14701364 | J3: -0.52077364 | L3: =J3 | M3: =IF(A3="안동시",J3,"") | N3: =IF(A3='1_문제'!$B$7,J3,"")
A4: 진안군 | B4: 3191290 | C4: 3319211 | D4: 9001.5517 | E4: 10039.135 | F4: 37.726123 | G4: 22.088984 | H4: 0.040084417 | I4: 0.11526715 | J4: -0.41449101 | L4: =J4 | M4: =IF(A4="안동시",J4,"") | N4: =IF(A4='1_문제'!$B$7,J4,"")
A5: 성주군 | B5: 4996993 | C5: 5165392 | D5: 26324.341 | E5: 25992.893 | F5: 86.683131 | G5: 51.228058 | H5: 0.033700067 | I5: -0.012590946 | J5: -0.4090193 | L5: =J5 | M5: =IF(A5="안동시",J5,"") | N5: =IF(A5='1_문제'!$B$7,J5,"")
A6: 인제군 | B6: 5809011 | C6: 8035452 | D6: 12794.385 | E6: 10020.423 | F6: 161.7518 | G6: 100.13314 | H6: 0.38327368 | I6: -0.21681087 | J6: -0.38094579 | L6: =J6 | M6: =IF(A6="안동시",J6,"") | N6: =IF(A6='1_문제'!$B$7,J6,"")
A7: 완주군 | B7: 15365622 | C7: 15381299 | D7: 12488.011 | E7: 13391.832 | F7: 205.99765 | G7: 134.12996 | H7: 0.0010202646 | I7: 0.072375044 | J7: -0.34887626 | L7: =J7 | M7: =IF(A7="안동시",J7,"") | N7: =IF(A7='1_문제'!$B$7,J7,"")
A8: 영주시 | B8: 5916900 | C8: 6115623 | D8: 12632.257 | E8: 12738.33 | F8: 128.06301 | G8: 90.944782 | H8: 0.033585661 | I8: 0.0083969362 | J8: -0.28984345 | L8: =J8 | M8: =IF(A8="안동시",J8,"") | N8: =IF(A8='1_문제'!$B$7,J8,"")
A9: 음성군 | B9: 11779580 | C9: 12805374 | D9: 27202.713 | E9: 24809.027 | F9: 249.52188 | G9: 179.68019 | H9: 0.087082392 | I9: -0.087994377 | J9: -0.27990209 | L9: =J9 | M9: =IF(A9="안동시",J9,"") | N9: =IF(A9='1_문제'!$B$7,J9,"")
A10: 예산군 | B10: 9821603 | C10: 10981851 | D10: 16793.371 | E10: 17610.413 | F10: 155.6304 | G10: 112.18901 | H10: 0.11813224 | I10: 0.048652647 | J10: -0.27913177 | L10: =J10 | M10: =IF(A10="안동시",J10,"") | N10: =IF(A10='1_문제'!$B$7,J10,"")
A11: 의성군 | B11: 4555385 | C11: 4444033 | D11: 13737.098 | E11: 15960.386 | F11: 32.782301 | G11: 23.82318 | H11: -0.024444037 | I11: 0.16184551 | J11: -0.27329138 | L11: =J11 | M11: =IF(A11="안동시",J11,"") | N11: =IF(A11='1_문제'!$B$7,J11,"")
A12: 양양군 | B12: 10450534 | C12: 10726738 | D12: 13732.143 | E12: 17049.989 | F12: 265.7381 | G12: 200.38282 | H12: 0.026429654 | I12: 0.24161168 | J12: -0.24593868 | L12: =J12 | M12: =IF(A12="안동시",J12,"") | N12: =IF(A12='1_문제'!$B$7,J12,"")
A13: 평택시 | B13: 31582863 | C13: 37993040 | D13: 23818.271 | E13: 22194.784 | F13: 405.68374 | G13: 306.84291 | H13: 0.20296377 | I13: -0.068161411 | J13: -0.24364011 | L13: =J13 | M13: =IF(A13="안동시",J13,"") | N13: =IF(A13='1_문제'!$B$7,J13,"")
... A147: 과천시 | B147: 13850191 | C147: 14754138 | D147: 8583.7569 | E147: 10534.67 | F147: 68.903599 | G147: 994.1878 | H147: 0.065266031 | I147: 0.22727963 | J147: 13.428677 | L147: =J147 | M147: =IF(A147="안동시",J147,"") | N147: =IF(A147='1_문제'!$B$7,J147,"")

Sheet d_업종전체
A1: 키 | B1: 2024 | C1: 2026
A2: 가평군|일반외식업 | B2: 5050.2109 | C2: 5952.0094
A3: 가평군|육상운송 | B3: 2709.2463 | C3: 2584.08
A4: 가평군|기타관광쇼핑 | B4: 4062.5739 | C4: 3912.1572
A5: 가평군|대형쇼핑몰 | B5: 132.84836 | C5: 115.48192
A6: 가평군|제과음료업 | B6: 2147.2242 | C6: 1345.5423
A7: 가평군|골프장 | B7: 2193.6975 | C7: 2031.7693
A8: 가평군|기타숙박 | B8: 379.03557 | C8: 379.03505
A9: 가평군|뷰티 | B9: 47.172023 | C9: 63.838234
A10: 가평군|레저용품쇼핑 | B10: 32.923929 | C10: 31.41084
A11: 가평군|기타레저 | B11: 272.12962 | C11: 354.29515
A12: 가평군|문화서비스 | B12: 8.8777959 | C12: 12.354734
A13: 가평군|여행업 | B13: 6.1296264 | C13: 0
... A2191: 횡성군|렌터카 | B2191: 2.8591325 | C2191: 1.1134472

Sheet d_업종
A1: 업종 | B1: 안동_2024 | C1: 안동_2026 | D1: 전국중앙_변화율 | E1: 선택_2024 | F1: 선택_2026 | G1: 안동 중앙대비(원) | H1: 선택 중앙대비(원) | J1: 선택 이름
A2: 일반외식업 | B2: 4253.6943 | C2: 4527.9358 | D2: 0.026656257 | E2: =SUMIFS('d_업종전체'!$B$2:$B$2191,'d_업종전체'!$A$2:$A$2191,'1_문제'!$B$7&"|"&A2) | F2: =SUMIFS('d_업종전체'!$C$2:$C$2191,'d_업종전체'!$A$2:$A$2191,'1_문제'!$B$7&"|"&A2) | G2: =C2-B2*(1+D2) | H2: =F2-E2*(1+D2) | J2: ='1_문제'!$B$7
A3: 육상운송 | B3: 4127.2808 | C3: 3998.0447 | D3: 0.1393934 | E3: =SUMIFS('d_업종전체'!$B$2:$B$2191,'d_업종전체'!$A$2:$A$2191,'1_문제'!$B$7&"|"&A3) | F3: =SUMIFS('d_업종전체'!$C$2:$C$2191,'d_업종전체'!$A$2:$A$2191,'1_문제'!$B$7&"|"&A3) | G3: =C3-B3*(1+D3) | H3: =F3-E3*(1+D3)
A4: 기타관광쇼핑 | B4: 3497.8211 | C4: 3442.2112 | D4: 0.0022993268 | E4: =SUMIFS('d_업종전체'!$B$2:$B$2191,'d_업종전체'!$A$2:$A$2191,'1_문제'!$B$7&"|"&A4) | F4: =SUMIFS('d_업종전체'!$C$2:$C$2191,'d_업종전체'!$A$2:$A$2191,'1_문제'!$B$7&"|"&A4) | G4: =C4-B4*(1+D4) | H4: =F4-E4*(1+D4)
A5: 대형쇼핑몰 | B5: 1427.1795 | C5: 968.84025 | D5: -0.11554091 | E5: =SUMIFS('d_업종전체'!$B$2:$B$2191,'d_업종전체'!$A$2:$A$2191,'1_문제'!$B$7&"|"&A5) | F5: =SUMIFS('d_업종전체'!$C$2:$C$2191,'d_업종전체'!$A$2:$A$2191,'1_문제'!$B$7&"|"&A5) | G5: =C5-B5*(1+D5) | H5: =F5-E5*(1+D5)
A6: 제과음료업 | B6: 808.2286 | C6: 850.95186 | D6: 0.095818985 | E6: =SUMIFS('d_업종전체'!$B$2:$B$2191,'d_업종전체'!$A$2:$A$2191,'1_문제'!$B$7&"|"&A6) | F6: =SUMIFS('d_업종전체'!$C$2:$C$2191,'d_업종전체'!$A$2:$A$2191,'1_문제'!$B$7&"|"&A6) | G6: =C6-B6*(1+D6) | H6: =F6-E6*(1+D6)
A7: 골프장 | B7: 563.08996 | C7: 380.31471 | D7: -0.090776161 | E7: =SUMIFS('d_업종전체'!$B$2:$B$2191,'d_업종전체'!$A$2:$A$2191,'1_문제'!$B$7&"|"&A7) | F7: =SUMIFS('d_업종전체'!$C$2:$C$2191,'d_업종전체'!$A$2:$A$2191,'1_문제'!$B$7&"|"&A7) | G7: =C7-B7*(1+D7) | H7: =F7-E7*(1+D7)
A8: 기타숙박 | B8: 229.95633 | C8: 360.79758 | D8: -0.083508481 | E8: =SUMIFS('d_업종전체'!$B$2:$B$2191,'d_업종전체'!$A$2:$A$2191,'1_문제'!$B$7&"|"&A8) | F8: =SUMIFS('d_업종전체'!$C$2:$C$2191,'d_업종전체'!$A$2:$A$2191,'1_문제'!$B$7&"|"&A8) | G8: =C8-B8*(1+D8) | H8: =F8-E8*(1+D8)
A9: 뷰티 | B9: 257.75962 | C9: 257.35841 | D9: 0.072424798 | E9: =SUMIFS('d_업종전체'!$B$2:$B$2191,'d_업종전체'!$A$2:$A$2191,'1_문제'!$B$7&"|"&A9) | F9: =SUMIFS('d_업종전체'!$C$2:$C$2191,'d_업종전체'!$A$2:$A$2191,'1_문제'!$B$7&"|"&A9) | G9: =C9-B9*(1+D9) | H9: =F9-E9*(1+D9)
A10: 레저용품쇼핑 | B10: 199.7871 | C10: 160.73263 | D10: -0.082298297 | E10: =SUMIFS('d_업종전체'!$B$2:$B$2191,'d_업종전체'!$A$2:$A$2191,'1_문제'!$B$7&"|"&A10) | F10: =SUMIFS('d_업종전체'!$C$2:$C$2191,'d_업종전체'!$A$2:$A$2191,'1_문제'!$B$7&"|"&A10) | G10: =C10-B10*(1+D10) | H10: =F10-E10*(1+D10)
A11: 기타레저 | B11: 136.70714 | C11: 126.30911 | D11: 0.0070757045 | E11: =SUMIFS('d_업종전체'!$B$2:$B$2191,'d_업종전체'!$A$2:$A$2191,'1_문제'!$B$7&"|"&A11) | F11: =SUMIFS('d_업종전체'!$C$2:$C$2191,'d_업종전체'!$A$2:$A$2191,'1_문제'!$B$7&"|"&A11) | G11: =C11-B11*(1+D11) | H11: =F11-E11*(1+D11)
A12: 문화서비스 | B12: 46.097481 | C12: 26.251647 | D12: -0.065814364 | E12: =SUMIFS('d_업종전체'!$B$2:$B$2191,'d_업종전체'!$A$2:$A$2191,'1_문제'!$B$7&"|"&A12) | F12: =SUMIFS('d_업종전체'!$C$2:$C$2191,'d_업종전체'!$A$2:$A$2191,'1_문제'!$B$7&"|"&A12) | G12: =C12-B12*(1+D12) | H12: =F12-E12*(1+D12)
A13: 여행업 | B13: 3.6406925 | C13: 15.418914 | D13: -0.49525742 | E13: =SUMIFS('d_업종전체'!$B$2:$B$2191,'d_업종전체'!$A$2:$A$2191,'1_문제'!$B$7&"|"&A13) | F13: =SUMIFS('d_업종전체'!$C$2:$C$2191,'d_업종전체'!$A$2:$A$2191,'1_문제'!$B$7&"|"&A13) | G13: =C13-B13*(1+D13) | H13: =F13-E13*(1+D13)

Sheet d_혜택
A1: 행정동 | B1: 방문점유율 | C1: 혜택업체 | D1: 추가 | E1: 혜택 합계 | F1: 혜택 점유율 | G1: 방문 점유율(비율)
A2: 중구동 | B2: 12.458637 | C2: 0 | D2: =IF(A2='2_혜택배치'!$B$7,'2_혜택배치'!$G$7,0) | E2: =C2+D2 | F2: =E2/SUM($E$2:$E$25) | G2: =B2/100
A3: 옥동 | B3: 9.9587315 | C3: 2 | D3: =IF(A3='2_혜택배치'!$B$7,'2_혜택배치'!$G$7,0) | E3: =C3+D3 | F3: =E3/SUM($E$2:$E$25) | G3: =B3/100
A4: 서구동 | B4: 9.6668848 | C4: 2 | D4: =IF(A4='2_혜택배치'!$B$7,'2_혜택배치'!$G$7,0) | E4: =C4+D4 | F4: =E4/SUM($E$2:$E$25) | G4: =B4/100
A5: 풍산읍 | B5: 9.3563732 | C5: 2 | D5: =IF(A5='2_혜택배치'!$B$7,'2_혜택배치'!$G$7,0) | E5: =C5+D5 | F5: =E5/SUM($E$2:$E$25) | G5: =B5/100
A6: 풍천면 | B6: 9.1307218 | C6: 3 | D6: =IF(A6='2_혜택배치'!$B$7,'2_혜택배치'!$G$7,0) | E6: =C6+D6 | F6: =E6/SUM($E$2:$E$25) | G6: =B6/100
A7: 용상동 | B7: 8.2128839 | C7: 3 | D7: =IF(A7='2_혜택배치'!$B$7,'2_혜택배치'!$G$7,0) | E7: =C7+D7 | F7: =E7/SUM($E$2:$E$25) | G7: =B7/100
A8: 강남동 | B8: 7.0800265 | C8: 0 | D8: =IF(A8='2_혜택배치'!$B$7,'2_혜택배치'!$G$7,0) | E8: =C8+D8 | F8: =E8/SUM($E$2:$E$25) | G8: =B8/100
A9: 명륜동 | B9: 4.7055485 | C9: 0 | D9: =IF(A9='2_혜택배치'!$B$7,'2_혜택배치'!$G$7,0) | E9: =C9+D9 | F9: =E9/SUM($E$2:$E$25) | G9: =B9/100
A10: 송하동 | B10: 4.689017 | C10: 1 | D10: =IF(A10='2_혜택배치'!$B$7,'2_혜택배치'!$G$7,0) | E10: =C10+D10 | F10: =E10/SUM($E$2:$E$25) | G10: =B10/100
A11: 태화동 | B11: 4.5532397 | C11: 1 | D11: =IF(A11='2_혜택배치'!$B$7,'2_혜택배치'!$G$7,0) | E11: =C11+D11 | F11: =E11/SUM($E$2:$E$25) | G11: =B11/100
A12: 서후면 | B12: 3.3295076 | C12: 0 | D12: =IF(A12='2_혜택배치'!$B$7,'2_혜택배치'!$G$7,0) | E12: =C12+D12 | F12: =E12/SUM($E$2:$E$25) | G12: =B12/100
A13: 도산면 | B13: 2.4243832 | C13: 6 | D13: =IF(A13='2_혜택배치'!$B$7,'2_혜택배치'!$G$7,0) | E13: =C13+D13 | F13: =E13/SUM($E$2:$E$25) | G13: =B13/100
... A25: 예안면 | B25: 0.41292095 | C25: 0 | D25: =IF(A25='2_혜택배치'!$B$7,'2_혜택배치'!$G$7,0) | E25: =C25+D25 | F25: =E25/SUM($E$2:$E$25) | G25: =B25/100

Sheet d_역
A1: 키 | B1: 인원
A2: 2024|공휴일|KTX-이음|승차|00-01 | B2: 0
A3: 2024|공휴일|KTX-이음|승차|01-02 | B3: 0
A4: 2024|공휴일|KTX-이음|승차|02-03 | B4: 0
A5: 2024|공휴일|KTX-이음|승차|03-04 | B5: 0
A6: 2024|공휴일|KTX-이음|승차|04-05 | B6: 0
A7: 2024|공휴일|KTX-이음|승차|05-06 | B7: 529
A8: 2024|공휴일|KTX-이음|승차|06-07 | B8: 0
A9: 2024|공휴일|KTX-이음|승차|07-08 | B9: 0
A10: 2024|공휴일|KTX-이음|승차|08-09 | B10: 884
A11: 2024|공휴일|KTX-이음|승차|09-10 | B11: 0
A12: 2024|공휴일|KTX-이음|승차|10-11 | B12: 1045
A13: 2024|공휴일|KTX-이음|승차|11-12 | B13: 1026
... A2305: 2026|평일|전체|하차|23-24 | B2305: 14060

Sheet d_버스
A1: 키 | B1: 회
A2: 110|평일|6 | B2: 7
A3: 110|평일|7 | B3: 10
A4: 110|평일|8 | B4: 10
A5: 110|평일|9 | B5: 10
A6: 110|평일|10 | B6: 9
A7: 110|평일|11 | B7: 9
A8: 110|평일|12 | B8: 10
A9: 110|평일|13 | B9: 8
A10: 110|평일|14 | B10: 9
A11: 110|평일|15 | B11: 8
A12: 110|평일|16 | B12: 9
A13: 110|평일|17 | B13: 9
... A529: 풍천3-1|평일|17 | B529: 1

Sheet d_버스출발
A1: 노선번호 | B1: 시간표 구분 | C1: 시각값 | D1: 선택 노선 시각
A2: 110 | B2: 평일 | C2: 0.27777778 | D2: =IF(AND(A2&""='4_버스'!$B$7&"",B2='4_버스'!$E$7),C2,"")
A3: 110 | B3: 평일 | C3: 0.29166667 | D3: =IF(AND(A3&""='4_버스'!$B$7&"",B3='4_버스'!$E$7),C3,"")
A4: 110 | B4: 평일 | C4: 0.30416667 | D4: =IF(AND(A4&""='4_버스'!$B$7&"",B4='4_버스'!$E$7),C4,"")
A5: 110 | B5: 평일 | C5: 0.3125 | D5: =IF(AND(A5&""='4_버스'!$B$7&"",B5='4_버스'!$E$7),C5,"")
A6: 110 | B6: 평일 | C6: 0.31944444 | D6: =IF(AND(A6&""='4_버스'!$B$7&"",B6='4_버스'!$E$7),C6,"")
A7: 110 | B7: 평일 | C7: 0.325 | D7: =IF(AND(A7&""='4_버스'!$B$7&"",B7='4_버스'!$E$7),C7,"")
A8: 110 | B8: 평일 | C8: 0.33333333 | D8: =IF(AND(A8&""='4_버스'!$B$7&"",B8='4_버스'!$E$7),C8,"")
A9: 110 | B9: 평일 | C9: 0.34027778 | D9: =IF(AND(A9&""='4_버스'!$B$7&"",B9='4_버스'!$E$7),C9,"")
A10: 110 | B10: 평일 | C10: 0.35069444 | D10: =IF(AND(A10&""='4_버스'!$B$7&"",B10='4_버스'!$E$7),C10,"")
A11: 110 | B11: 평일 | C11: 0.36111111 | D11: =IF(AND(A11&""='4_버스'!$B$7&"",B11='4_버스'!$E$7),C11,"")
A12: 110 | B12: 평일 | C12: 0.36805556 | D12: =IF(AND(A12&""='4_버스'!$B$7&"",B12='4_버스'!$E$7),C12,"")
A13: 110 | B13: 평일 | C13: 0.37708333 | D13: =IF(AND(A13&""='4_버스'!$B$7&"",B13='4_버스'!$E$7),C13,"")
... A1398: 풍천3-1 | B1398: 평일 | C1398: 0.70833333 | D1398: =IF(AND(A1398&""='4_버스'!$B$7&"",B1398='4_버스'!$E$7),C1398,"")

Sheet d_노선목록
A1: 노선
A2: 110
A3: 111
A4: 112
A5: 113
A6: 114
A7: 210
A8: 211
A9: 212
A10: 213
A11: 310
A12: 311
... A47: 풍천3-1

Sheet d_정류장
A1: 경도_전체 | B1: 위도_전체 | C1: 경도_안내기 | D1: 위도_안내기 | F1: 경도_112 | G1: 위도_112 | H1: 경도_안동역 | I1: 위도_안동역 | J1: 경도_원도심 | K1: 위도_원도심 | L1: 경도_월영교 | M1: 위도_월영교
A2: 128.5864 | B2: 36.633899 | F2: 128.76539 | G2: 36.551019 | H2: 128.67597 | I2: 36.57419 | J2: 128.7277 | K2: 36.566105 | L2: 128.75865 | M2: 36.577697
A3: 128.58635 | B3: 36.633991 | F3: 128.76248 | G3: 36.552204 | H3: 128.67597 | I3: 36.57419 | J3: 128.72672 | K3: 36.565713 | L3: 128.75881 | M3: 36.578155
A4: 128.74781 | B4: 36.561408 | C4: 128.74781 | D4: 36.561408 | F4: 128.76018 | G4: 36.5537 | H4: 128.67552 | I4: 36.573483 | J4: 128.72617 | K4: 36.566704 | L4: 128.76169 | M4: 36.580393
A5: 128.74877 | B5: 36.560797 | C5: 128.74877 | D5: 36.560797 | F5: 128.75754 | G5: 36.555419 | H5: 128.67566 | I5: 36.57349 | J5: 128.72764 | K5: 36.563376 | L5: 128.76183 | M5: 36.580607
A6: 128.70096 | B6: 36.564399 | C6: 128.70096 | D6: 36.564399 | F6: 128.75486 | G6: 36.557173 | H6: 128.67687 | I6: 36.575506 | J6: 128.72712 | K6: 36.563374
A7: 128.20098 | B7: 36.594511 | F7: 128.75264 | G7: 36.558602 | J7: 128.72564 | K7: 36.566804
A8: 128.20053 | B8: 36.594469 | F8: 128.75066 | G8: 36.559922 | J8: 128.72712 | K8: 36.563138
A9: 128.70995 | B9: 36.571661 | C9: 128.70995 | D9: 36.571661 | F9: 128.74781 | G9: 36.561408 | J9: 128.7298 | K9: 36.5675
A10: 128.50106 | B10: 36.571655 | F10: 128.73725 | G10: 36.564038 | J10: 128.73012 | K10: 36.567516
A11: 128.54422 | B11: 36.600394 | C11: 128.54422 | D11: 36.600394 | F11: 128.7343 | G11: 36.563491 | J11: 128.73079 | K11: 36.563294
A12: 128.54398 | B12: 36.600427 | C12: 128.54398 | D12: 36.600427 | F12: 128.73079 | G12: 36.563294 | J12: 128.73212 | K12: 36.565983
A13: 128.70034 | B13: 36.572195 | F13: 128.72764 | G13: 36.563376 | J13: 128.7309 | K13: 36.563049
A14: 128.45953 | B14: 36.657996 | F14: 128.7238 | G14: 36.563465 | J14: 128.73107 | K14: 36.563112
A15: 128.39494 | B15: 36.633912 | F15: 128.71878 | G15: 36.563648 | J15: 128.72386 | K15: 36.566732
A16: 128.39524 | B16: 36.634087 | F16: 128.71661 | G16: 36.562456 | J16: 128.73128 | K16: 36.563039
A17: 128.37625 | B17: 36.640337 | F17: 128.71581 | G17: 36.559499 | J17: 128.73084 | K17: 36.56842
A18: 128.37638 | B18: 36.64034 | F18: 128.69916 | G18: 36.55351 | J18: 128.73277 | K18: 36.565946
A19: 128.356 | B19: 36.609642 | F19: 128.69257 | G19: 36.548398 | J19: 128.73115 | K19: 36.568499
A20: 128.356 | B20: 36.609489 | F20: 128.68741 | G20: 36.54605 | J20: 128.7238 | K20: 36.563465
A21: 128.35226 | B21: 36.611325 | F21: 128.68258 | G21: 36.552048 | J21: 128.72377 | K21: 36.563227
A22: 128.35233 | B22: 36.611229 | F22: 128.68487 | G22: 36.557149
A23: 128.51953 | B23: 36.571617 | F23: 128.67687 | G23: 36.575506
A24: 128.51972 | B24: 36.571715 | F24: 128.67566 | G24: 36.57349
A25: 128.77662 | B25: 36.616301 | F25: 128.67552 | G25: 36.573483
A26: 128.77759 | B26: 36.616044 | F26: 128.68462 | G26: 36.557141
A27: 128.78159 | B27: 36.616552 | F27: 128.68246 | G27: 36.552428
A28: 128.78161 | B28: 36.616662 | F28: 128.68717 | G28: 36.545892
A29: 128.77615 | B29: 36.604022 | F29: 128.69264 | G29: 36.548258
A30: 128.77599 | B30: 36.603841 | F30: 128.69928 | G30: 36.553198
A31: 128.97902 | B31: 36.464722 | F31: 128.71631 | G31: 36.559764
A32: 128.84241 | B32: 36.61826 | F32: 128.71687 | G32: 36.562141
A33: 128.84235 | B33: 36.618259 | F33: 128.71896 | G33: 36.563434
... A136: 128.78265 | B136: 36.589644 | F136: 128.71896 | G136: 36.563434
A137: 128.73296 | B137: 36.550607 | C137: 128.73296 | D137: 36.550607 | F137: 128.72377 | G137: 36.563227
A138: 128.72586 | B138: 36.548187 | F138: 128.72712 | G138: 36.563138
A139: 128.72574 | B139: 36.547942 | F139: 128.7309 | G139: 36.563049
A140: 128.72127 | B140: 36.550813 | C140: 128.72127 | D140: 36.550813 | F140: 128.7341 | G140: 36.563196
A141: 128.70396 | B141: 36.546565 | F141: 128.73868 | G141: 36.564071
A142: 128.7193 | B142: 36.552139 | F142: 128.74134 | G142: 36.56413
...

Sheet d_철도
A1: 관광지명 | B1: 방문점유율_pct | C1: 방문객소비건수점유율_pct | D1: 소비방문배율
A2: 월영교 | B2: 15.24 | C2: 6.05 | D2: 0.4
A3: 안동문화관광단지 | B3: 11.02 | C3: 2.28 | D3: 0.21
A4: 안동하회마을 | B4: 6.29 | C4: 0.4 | D4: 0.06
A5: 낙강물길공원 | B5: 2.37 | C5: 0 | D5: 0
A6: 만휴정 | B6: 2.23 | C6: 0 | D6: 0
A7: 봉정사 | B7: 1.71 | C7: 0.02 | D7: 0.01
A8: 도산서원 | B8: 2.27 | C8: 0.65 | D8: 0.29
A9: 병산서원 | B9: 1.13 | C9: 0.06 | D9: 0.05
A10: 권정생동화나라 | B10: 0.43 | C10: 0.01 | D10: 0.03
A11: 안동민속촌 | B11: 1.1 | C11: 0.75 | D11: 0.68
A12: 유교문화박물관 | B12: 0.36 | C12: 0.13 | D12: 0.37
A13: 안동포마을 | B13: 0.07 | C13: 0 | D13: 0
... A20: 안동문화의거리 | B20: 18.85 | C20: 32.66 | D20: 1.73

Sheet d_분류
A1: 분류 | B1: 이용
A2: 관람 | B2: 19543
A3: 식음료 | B3: 560
A4: 숙박 | B4: 193
A5: 체험 | B5: 181

Sheet d_역계산
A1: 시간대 | B1: 시 | C1: 승차 | D1: 하차 | E1: 창 안 승차
A2: 05시 | B2: 5 | C2: =SUMIFS('d_역'!$B$2:$B$2305,'d_역'!$A$2:$A$2305,'3_운영시간'!$B$7&"|"&'3_운영시간'!$E$7&"|"&'3_운영시간'!$H$7&"|승차|05-06") | D2: =SUMIFS('d_역'!$B$2:$B$2305,'d_역'!$A$2:$A$2305,'3_운영시간'!$B$7&"|"&'3_운영시간'!$E$7&"|"&'3_운영시간'!$H$7&"|하차|05-06") | E2: =IF(AND(B2+1>'3_운영시간'!$K$7,B2<'3_운영시간'!$N$7),C2,"")
A3: 06시 | B3: 6 | C3: =SUMIFS('d_역'!$B$2:$B$2305,'d_역'!$A$2:$A$2305,'3_운영시간'!$B$7&"|"&'3_운영시간'!$E$7&"|"&'3_운영시간'!$H$7&"|승차|06-07") | D3: =SUMIFS('d_역'!$B$2:$B$2305,'d_역'!$A$2:$A$2305,'3_운영시간'!$B$7&"|"&'3_운영시간'!$E$7&"|"&'3_운영시간'!$H$7&"|하차|06-07") | E3: =IF(AND(B3+1>'3_운영시간'!$K$7,B3<'3_운영시간'!$N$7),C3,"")
A4: 07시 | B4: 7 | C4: =SUMIFS('d_역'!$B$2:$B$2305,'d_역'!$A$2:$A$2305,'3_운영시간'!$B$7&"|"&'3_운영시간'!$E$7&"|"&'3_운영시간'!$H$7&"|승차|07-08") | D4: =SUMIFS('d_역'!$B$2:$B$2305,'d_역'!$A$2:$A$2305,'3_운영시간'!$B$7&"|"&'3_운영시간'!$E$7&"|"&'3_운영시간'!$H$7&"|하차|07-08") | E4: =IF(AND(B4+1>'3_운영시간'!$K$7,B4<'3_운영시간'!$N$7),C4,"")
A5: 08시 | B5: 8 | C5: =SUMIFS('d_역'!$B$2:$B$2305,'d_역'!$A$2:$A$2305,'3_운영시간'!$B$7&"|"&'3_운영시간'!$E$7&"|"&'3_운영시간'!$H$7&"|승차|08-09") | D5: =SUMIFS('d_역'!$B$2:$B$2305,'d_역'!$A$2:$A$2305,'3_운영시간'!$B$7&"|"&'3_운영시간'!$E$7&"|"&'3_운영시간'!$H$7&"|하차|08-09") | E5: =IF(AND(B5+1>'3_운영시간'!$K$7,B5<'3_운영시간'!$N$7),C5,"")
A6: 09시 | B6: 9 | C6: =SUMIFS('d_역'!$B$2:$B$2305,'d_역'!$A$2:$A$2305,'3_운영시간'!$B$7&"|"&'3_운영시간'!$E$7&"|"&'3_운영시간'!$H$7&"|승차|09-10") | D6: =SUMIFS('d_역'!$B$2:$B$2305,'d_역'!$A$2:$A$2305,'3_운영시간'!$B$7&"|"&'3_운영시간'!$E$7&"|"&'3_운영시간'!$H$7&"|하차|09-10") | E6: =IF(AND(B6+1>'3_운영시간'!$K$7,B6<'3_운영시간'!$N$7),C6,"")
A7: 10시 | B7: 10 | C7: =SUMIFS('d_역'!$B$2:$B$2305,'d_역'!$A$2:$A$2305,'3_운영시간'!$B$7&"|"&'3_운영시간'!$E$7&"|"&'3_운영시간'!$H$7&"|승차|10-11") | D7: =SUMIFS('d_역'!$B$2:$B$2305,'d_역'!$A$2:$A$2305,'3_운영시간'!$B$7&"|"&'3_운영시간'!$E$7&"|"&'3_운영시간'!$H$7&"|하차|10-11") | E7: =IF(AND(B7+1>'3_운영시간'!$K$7,B7<'3_운영시간'!$N$7),C7,"")
A8: 11시 | B8: 11 | C8: =SUMIFS('d_역'!$B$2:$B$2305,'d_역'!$A$2:$A$2305,'3_운영시간'!$B$7&"|"&'3_운영시간'!$E$7&"|"&'3_운영시간'!$H$7&"|승차|11-12") | D8: =SUMIFS('d_역'!$B$2:$B$2305,'d_역'!$A$2:$A$2305,'3_운영시간'!$B$7&"|"&'3_운영시간'!$E$7&"|"&'3_운영시간'!$H$7&"|하차|11-12") | E8: =IF(AND(B8+1>'3_운영시간'!$K$7,B8<'3_운영시간'!$N$7),C8,"")
A9: 12시 | B9: 12 | C9: =SUMIFS('d_역'!$B$2:$B$2305,'d_역'!$A$2:$A$2305,'3_운영시간'!$B$7&"|"&'3_운영시간'!$E$7&"|"&'3_운영시간'!$H$7&"|승차|12-13") | D9: =SUMIFS('d_역'!$B$2:$B$2305,'d_역'!$A$2:$A$2305,'3_운영시간'!$B$7&"|"&'3_운영시간'!$E$7&"|"&'3_운영시간'!$H$7&"|하차|12-13") | E9: =IF(AND(B9+1>'3_운영시간'!$K$7,B9<'3_운영시간'!$N$7),C9,"")
A10: 13시 | B10: 13 | C10: =SUMIFS('d_역'!$B$2:$B$2305,'d_역'!$A$2:$A$2305,'3_운영시간'!$B$7&"|"&'3_운영시간'!$E$7&"|"&'3_운영시간'!$H$7&"|승차|13-14") | D10: =SUMIFS('d_역'!$B$2:$B$2305,'d_역'!$A$2:$A$2305,'3_운영시간'!$B$7&"|"&'3_운영시간'!$E$7&"|"&'3_운영시간'!$H$7&"|하차|13-14") | E10: =IF(AND(B10+1>'3_운영시간'!$K$7,B10<'3_운영시간'!$N$7),C10,"")
A11: 14시 | B11: 14 | C11: =SUMIFS('d_역'!$B$2:$B$2305,'d_역'!$A$2:$A$2305,'3_운영시간'!$B$7&"|"&'3_운영시간'!$E$7&"|"&'3_운영시간'!$H$7&"|승차|14-15") | D11: =SUMIFS('d_역'!$B$2:$B$2305,'d_역'!$A$2:$A$2305,'3_운영시간'!$B$7&"|"&'3_운영시간'!$E$7&"|"&'3_운영시간'!$H$7&"|하차|14-15") | E11: =IF(AND(B11+1>'3_운영시간'!$K$7,B11<'3_운영시간'!$N$7),C11,"")
A12: 15시 | B12: 15 | C12: =SUMIFS('d_역'!$B$2:$B$2305,'d_역'!$A$2:$A$2305,'3_운영시간'!$B$7&"|"&'3_운영시간'!$E$7&"|"&'3_운영시간'!$H$7&"|승차|15-16") | D12: =SUMIFS('d_역'!$B$2:$B$2305,'d_역'!$A$2:$A$2305,'3_운영시간'!$B$7&"|"&'3_운영시간'!$E$7&"|"&'3_운영시간'!$H$7&"|하차|15-16") | E12: =IF(AND(B12+1>'3_운영시간'!$K$7,B12<'3_운영시간'!$N$7),C12,"")
A13: 16시 | B13: 16 | C13: =SUMIFS('d_역'!$B$2:$B$2305,'d_역'!$A$2:$A$2305,'3_운영시간'!$B$7&"|"&'3_운영시간'!$E$7&"|"&'3_운영시간'!$H$7&"|승차|16-17") | D13: =SUMIFS('d_역'!$B$2:$B$2305,'d_역'!$A$2:$A$2305,'3_운영시간'!$B$7&"|"&'3_운영시간'!$E$7&"|"&'3_운영시간'!$H$7&"|하차|16-17") | E13: =IF(AND(B13+1>'3_운영시간'!$K$7,B13<'3_운영시간'!$N$7),C13,"")
A14: 17시 | B14: 17 | C14: =SUMIFS('d_역'!$B$2:$B$2305,'d_역'!$A$2:$A$2305,'3_운영시간'!$B$7&"|"&'3_운영시간'!$E$7&"|"&'3_운영시간'!$H$7&"|승차|17-18") | D14: =SUMIFS('d_역'!$B$2:$B$2305,'d_역'!$A$2:$A$2305,'3_운영시간'!$B$7&"|"&'3_운영시간'!$E$7&"|"&'3_운영시간'!$H$7&"|하차|17-18") | E14: =IF(AND(B14+1>'3_운영시간'!$K$7,B14<'3_운영시간'!$N$7),C14,"")
A15: 18시 | B15: 18 | C15: =SUMIFS('d_역'!$B$2:$B$2305,'d_역'!$A$2:$A$2305,'3_운영시간'!$B$7&"|"&'3_운영시간'!$E$7&"|"&'3_운영시간'!$H$7&"|승차|18-19") | D15: =SUMIFS('d_역'!$B$2:$B$2305,'d_역'!$A$2:$A$2305,'3_운영시간'!$B$7&"|"&'3_운영시간'!$E$7&"|"&'3_운영시간'!$H$7&"|하차|18-19") | E15: =IF(AND(B15+1>'3_운영시간'!$K$7,B15<'3_운영시간'!$N$7),C15,"")
A16: 19시 | B16: 19 | C16: =SUMIFS('d_역'!$B$2:$B$2305,'d_역'!$A$2:$A$2305,'3_운영시간'!$B$7&"|"&'3_운영시간'!$E$7&"|"&'3_운영시간'!$H$7&"|승차|19-20") | D16: =SUMIFS('d_역'!$B$2:$B$2305,'d_역'!$A$2:$A$2305,'3_운영시간'!$B$7&"|"&'3_운영시간'!$E$7&"|"&'3_운영시간'!$H$7&"|하차|19-20") | E16: =IF(AND(B16+1>'3_운영시간'!$K$7,B16<'3_운영시간'!$N$7),C16,"")
A17: 20시 | B17: 20 | C17: =SUMIFS('d_역'!$B$2:$B$2305,'d_역'!$A$2:$A$2305,'3_운영시간'!$B$7&"|"&'3_운영시간'!$E$7&"|"&'3_운영시간'!$H$7&"|승차|20-21") | D17: =SUMIFS('d_역'!$B$2:$B$2305,'d_역'!$A$2:$A$2305,'3_운영시간'!$B$7&"|"&'3_운영시간'!$E$7&"|"&'3_운영시간'!$H$7&"|하차|20-21") | E17: =IF(AND(B17+1>'3_운영시간'!$K$7,B17<'3_운영시간'!$N$7),C17,"")
A18: 21시 | B18: 21 | C18: =SUMIFS('d_역'!$B$2:$B$2305,'d_역'!$A$2:$A$2305,'3_운영시간'!$B$7&"|"&'3_운영시간'!$E$7&"|"&'3_운영시간'!$H$7&"|승차|21-22") | D18: =SUMIFS('d_역'!$B$2:$B$2305,'d_역'!$A$2:$A$2305,'3_운영시간'!$B$7&"|"&'3_운영시간'!$E$7&"|"&'3_운영시간'!$H$7&"|하차|21-22") | E18: =IF(AND(B18+1>'3_운영시간'!$K$7,B18<'3_운영시간'!$N$7),C18,"")
A19: 22시 | B19: 22 | C19: =SUMIFS('d_역'!$B$2:$B$2305,'d_역'!$A$2:$A$2305,'3_운영시간'!$B$7&"|"&'3_운영시간'!$E$7&"|"&'3_운영시간'!$H$7&"|승차|22-23") | D19: =SUMIFS('d_역'!$B$2:$B$2305,'d_역'!$A$2:$A$2305,'3_운영시간'!$B$7&"|"&'3_운영시간'!$E$7&"|"&'3_운영시간'!$H$7&"|하차|22-23") | E19: =IF(AND(B19+1>'3_운영시간'!$K$7,B19<'3_운영시간'!$N$7),C19,"")
A20: 23시 | B20: 23 | C20: =SUMIFS('d_역'!$B$2:$B$2305,'d_역'!$A$2:$A$2305,'3_운영시간'!$B$7&"|"&'3_운영시간'!$E$7&"|"&'3_운영시간'!$H$7&"|승차|23-24") | D20: =SUMIFS('d_역'!$B$2:$B$2305,'d_역'!$A$2:$A$2305,'3_운영시간'!$B$7&"|"&'3_운영시간'!$E$7&"|"&'3_운영시간'!$H$7&"|하차|23-24") | E20: =IF(AND(B20+1>'3_운영시간'!$K$7,B20<'3_운영시간'!$N$7),C20,"")

Sheet d_버스계산
A1: 시 | B1: 선택 노선 | C1: 안동역→원도심 | D1: 원도심→안동역 | E1: 원도심→월영교 | F1: 월영교→원도심 | G1: 안동역→월영교 | H1: 월영교→안동역 | I1: 원도심→월영교(추가 반영)
A2: 05시 | B2: =SUMIFS('d_버스'!$B$2:$B$529,'d_버스'!$A$2:$A$529,'4_버스'!$B$7&"|"&'4_버스'!$E$7&"|5") | C2: 0 | D2: 0 | E2: 0 | F2: 0 | G2: 0 | H2: 0 | I2: =E2+IF(AND(5>=19,5<21),'4_버스'!$H$7/2,0)
A3: 06시 | B3: =SUMIFS('d_버스'!$B$2:$B$529,'d_버스'!$A$2:$A$529,'4_버스'!$B$7&"|"&'4_버스'!$E$7&"|6") | C3: 22 | D3: 47 | E3: 0 | F3: 0 | G3: 0 | H3: 0 | I3: =E3+IF(AND(6>=19,6<21),'4_버스'!$H$7/2,0)
A4: 07시 | B4: =SUMIFS('d_버스'!$B$2:$B$529,'d_버스'!$A$2:$A$529,'4_버스'!$B$7&"|"&'4_버스'!$E$7&"|7") | C4: 38 | D4: 47 | E4: 0 | F4: 0 | G4: 0 | H4: 0 | I4: =E4+IF(AND(7>=19,7<21),'4_버스'!$H$7/2,0)
A5: 08시 | B5: =SUMIFS('d_버스'!$B$2:$B$529,'d_버스'!$A$2:$A$529,'4_버스'!$B$7&"|"&'4_버스'!$E$7&"|8") | C5: 39 | D5: 36 | E5: 1 | F5: 1 | G5: 1 | H5: 1 | I5: =E5+IF(AND(8>=19,8<21),'4_버스'!$H$7/2,0)
A6: 09시 | B6: =SUMIFS('d_버스'!$B$2:$B$529,'d_버스'!$A$2:$A$529,'4_버스'!$B$7&"|"&'4_버스'!$E$7&"|9") | C6: 37 | D6: 38 | E6: 0 | F6: 0 | G6: 0 | H6: 0 | I6: =E6+IF(AND(9>=19,9<21),'4_버스'!$H$7/2,0)
A7: 10시 | B7: =SUMIFS('d_버스'!$B$2:$B$529,'d_버스'!$A$2:$A$529,'4_버스'!$B$7&"|"&'4_버스'!$E$7&"|10") | C7: 39 | D7: 39 | E7: 1 | F7: 1 | G7: 1 | H7: 1 | I7: =E7+IF(AND(10>=19,10<21),'4_버스'!$H$7/2,0)
A8: 11시 | B8: =SUMIFS('d_버스'!$B$2:$B$529,'d_버스'!$A$2:$A$529,'4_버스'!$B$7&"|"&'4_버스'!$E$7&"|11") | C8: 35 | D8: 36 | E8: 0 | F8: 0 | G8: 0 | H8: 0 | I8: =E8+IF(AND(11>=19,11<21),'4_버스'!$H$7/2,0)
A9: 12시 | B9: =SUMIFS('d_버스'!$B$2:$B$529,'d_버스'!$A$2:$A$529,'4_버스'!$B$7&"|"&'4_버스'!$E$7&"|12") | C9: 34 | D9: 36 | E9: 1 | F9: 1 | G9: 1 | H9: 1 | I9: =E9+IF(AND(12>=19,12<21),'4_버스'!$H$7/2,0)
A10: 13시 | B10: =SUMIFS('d_버스'!$B$2:$B$529,'d_버스'!$A$2:$A$529,'4_버스'!$B$7&"|"&'4_버스'!$E$7&"|13") | C10: 34 | D10: 40 | E10: 0 | F10: 0 | G10: 0 | H10: 0 | I10: =E10+IF(AND(13>=19,13<21),'4_버스'!$H$7/2,0)
A11: 14시 | B11: =SUMIFS('d_버스'!$B$2:$B$529,'d_버스'!$A$2:$A$529,'4_버스'!$B$7&"|"&'4_버스'!$E$7&"|14") | C11: 38 | D11: 38 | E11: 0 | F11: 0 | G11: 0 | H11: 0 | I11: =E11+IF(AND(14>=19,14<21),'4_버스'!$H$7/2,0)
A12: 15시 | B12: =SUMIFS('d_버스'!$B$2:$B$529,'d_버스'!$A$2:$A$529,'4_버스'!$B$7&"|"&'4_버스'!$E$7&"|15") | C12: 39 | D12: 36 | E12: 0 | F12: 0 | G12: 0 | H12: 0 | I12: =E12+IF(AND(15>=19,15<21),'4_버스'!$H$7/2,0)
A13: 16시 | B13: =SUMIFS('d_버스'!$B$2:$B$529,'d_버스'!$A$2:$A$529,'4_버스'!$B$7&"|"&'4_버스'!$E$7&"|16") | C13: 37 | D13: 45 | E13: 1 | F13: 1 | G13: 1 | H13: 0 | I13: =E13+IF(AND(16>=19,16<21),'4_버스'!$H$7/2,0)
A14: 17시 | B14: =SUMIFS('d_버스'!$B$2:$B$529,'d_버스'!$A$2:$A$529,'4_버스'!$B$7&"|"&'4_버스'!$E$7&"|17") | C14: 36 | D14: 30 | E14: 1 | F14: 0 | G14: 0 | H14: 0 | I14: =E14+IF(AND(17>=19,17<21),'4_버스'!$H$7/2,0)
A15: 18시 | B15: =SUMIFS('d_버스'!$B$2:$B$529,'d_버스'!$A$2:$A$529,'4_버스'!$B$7&"|"&'4_버스'!$E$7&"|18") | C15: 37 | D15: 33 | E15: 1 | F15: 1 | G15: 0 | H15: 0 | I15: =E15+IF(AND(18>=19,18<21),'4_버스'!$H$7/2,0)
A16: 19시 | B16: =SUMIFS('d_버스'!$B$2:$B$529,'d_버스'!$A$2:$A$529,'4_버스'!$B$7&"|"&'4_버스'!$E$7&"|19") | C16: 25 | D16: 24 | E16: 0 | F16: 1 | G16: 0 | H16: 0 | I16: =E16+IF(AND(19>=19,19<21),'4_버스'!$H$7/2,0)
A17: 20시 | B17: =SUMIFS('d_버스'!$B$2:$B$529,'d_버스'!$A$2:$A$529,'4_버스'!$B$7&"|"&'4_버스'!$E$7&"|20") | C17: 18 | D17: 19 | E17: 0 | F17: 0 | G17: 0 | H17: 0 | I17: =E17+IF(AND(20>=19,20<21),'4_버스'!$H$7/2,0)
A18: 21시 | B18: =SUMIFS('d_버스'!$B$2:$B$529,'d_버스'!$A$2:$A$529,'4_버스'!$B$7&"|"&'4_버스'!$E$7&"|21") | C18: 18 | D18: 11 | E18: 0 | F18: 0 | G18: 0 | H18: 0 | I18: =E18+IF(AND(21>=19,21<21),'4_버스'!$H$7/2,0)
A19: 22시 | B19: =SUMIFS('d_버스'!$B$2:$B$529,'d_버스'!$A$2:$A$529,'4_버스'!$B$7&"|"&'4_버스'!$E$7&"|22") | C19: 4 | D19: 4 | E19: 0 | F19: 0 | G19: 0 | H19: 0 | I19: =E19+IF(AND(22>=19,22<21),'4_버스'!$H$7/2,0)
A20: 23시 | B20: =SUMIFS('d_버스'!$B$2:$B$529,'d_버스'!$A$2:$A$529,'4_버스'!$B$7&"|"&'4_버스'!$E$7&"|23") | C20: 0 | D20: 0 | E20: 0 | F20: 0 | G20: 0 | H20: 0 | I20: =E20+IF(AND(23>=19,23<21),'4_버스'!$H$7/2,0)

Sheet d_월영교
A1: 업체 | B1: 업종 | C1: 영업 종료(시) | D1: 식사 가능
A2: 안동댐간고등어직영식당 | B2: 한식 | C2: 20 | D2: 1
A3: 맛50년헛제사밥 | B3: 한식 | C3: 20 | D3: 1
A4: 호반정 | B4: 한식 | C4: 20 | D4: 1
A5: 옛날촌동네 | B5: 한식 | C5: 20 | D5: 1
A6: 삼일가든 | B6: 한식 | C6: 20.5 | D6: 1
A7: 이정식당 | B7: 한식 | C7: 20.5 | D7: 1
A8: 고센피제리아안동댐점 | B8: 서양식 | C8: 20.5 | D8: 1
A9: 안동김대감 | B9: 한식 | C9: 21 | D9: 1
A10: 와룡가든 | B10: 한식 | C10: 21 | D10: 1
A11: 라라룬 | B11: 카페 | C11: 22 | D11: 0
A12: 월영당 | B12: 카페 | C12: 22 | D12: 0
A13: 카페구름마루 | B13: 카페 | C13: 22 | D13: 0
... A17: 나우커피안동댐점 | B17: 카페 | C17: 24 | D17: 0
A18: 팝업 부스 | B18: 팝업 | C18: ='5_월영교'!$E$7 | D18: 1

Sheet d_업종구성
A1: 업종 | B1: 월영교 1km | C1: 원도심 1km
A2: 한식 | B2: 0.58823529 | C2: 0.44764398
A3: 카페(비알코올) | B3: 0.35294118 | C3: 0.16623037
A4: 주점 | B4: 0 | C4: 0.11256545
A5: 서양식 | B5: 0.058823529 | C5: 0.017015707
A6: 기타 | B6: 0 | C6: 0.2565445

Sheet d_시나리오
A1: 파라미터 | B1: 기본_하한 | C1: 기본_최빈 | D1: 기본_상한 | E1: 확대_하한 | F1: 확대_최빈 | G1: 확대_상한 | H1: 적용_하한 | I1: 적용_최빈 | J1: 적용_상한
A2: p | B2: 0.00098056563 | C2: 0.0045811505 | D2: 0.008999635 | E2: 0.0045811505 | F2: 0.02 | G2: 0.05 | H2: =IF('6_기대효과'!$B$7="확대안",E2,IF('6_기대효과'!$B$7="직접 입력",'6_기대효과'!$N$7*0.5,B2)) | I2: =IF('6_기대효과'!$B$7="확대안",F2,IF('6_기대효과'!$B$7="직접 입력",'6_기대효과'!$N$7*1,C2)) | J2: =IF('6_기대효과'!$B$7="확대안",G2,IF('6_기대효과'!$B$7="직접 입력",'6_기대효과'!$N$7*1.5,D2))
A3: qb | B3: 0.1 | C3: 0.25 | D3: 0.5 | E3: 0.1 | F3: 0.25 | G3: 0.5 | H3: =IF('6_기대효과'!$B$7="확대안",E3,B3) | I3: =IF('6_기대효과'!$B$7="확대안",F3,C3) | J3: =IF('6_기대효과'!$B$7="확대안",G3,D3)
A4: boat | B4: 7000 | C4: 9333 | D4: 12000 | E4: 7000 | F4: 9333 | G4: 12000 | H4: =IF('6_기대효과'!$B$7="확대안",E4,B4) | I4: =IF('6_기대효과'!$B$7="확대안",F4,C4) | J4: =IF('6_기대효과'!$B$7="확대안",G4,D4)
A5: qp | B5: 0.2 | C5: 0.4 | D5: 0.6 | E5: 0.2 | F5: 0.4 | G5: 0.6 | H5: =IF('6_기대효과'!$B$7="확대안",E5,B5) | I5: =IF('6_기대효과'!$B$7="확대안",F5,C5) | J5: =IF('6_기대효과'!$B$7="확대안",G5,D5)
A6: k | B6: 0.1 | C6: 0.25 | D6: 0.5 | E6: 0.1 | F6: 0.25 | G6: 0.5 | H6: =IF('6_기대효과'!$B$7="확대안",E6,B6) | I6: =IF('6_기대효과'!$B$7="확대안",F6,C6) | J6: =IF('6_기대효과'!$B$7="확대안",G6,D6)
A7: n1 | C7: 20 | F7: 83 | I7: =IF('6_기대효과'!$B$7="확대안",F7,IF('6_기대효과'!$B$7="직접 입력",'6_기대효과'!$E$7,C7))

Sheet d_분포
A1: 체험가격 | B1: 팝업객단가 | C1: 완주율
A2: 3000 | B2: 1388 | C2: 0.16869689
A3: 3000 | B3: 1933 | C3: 0.15625841
A4: 4000 | B4: 1945 | C4: 0.1594299
A5: 5000 | B5: 2149 | C5: 0.1476747
A6: 5000 | B6: 2642
A7: 6000 | B7: 2956
A8: 7000 | B8: 3181
A9: 8000 | B9: 3721
A10: 8000 | B10: 3982
A11: 10000 | B11: 4636
A12: 10000 | B12: 5757
A13: 10000 | B13: 5852
A14: 10000 | B14: 5962
A15: 12000 | B15: 6030
A16: 12000 | B16: 6111
A17: 15000 | B17: 6380
... A28: 39000 | B28: 8867
B29: 8981
B30: 9208
B31: 9309
B32: 9358
B33: 9362
B34: 9368
B35: 9568
B36: 9815
B37: 9922
B38: 9969
B39: 10124
B40: 10589
... B57: 18496

Sheet d_고정
A1: 중구동 월 외지인 방문 | B1: 272615.89
A2: 원도심 관광 식당 | B2: 83
A3: 월영교 주말 저녁 방문기회(8개월) | B3: 57604.507
A4: 강남동 외지인 관광소비(8개월) | B4: 10951039000
A5: 안동 외지인 방문(8개월) | B5: 11726312
A6: 현재 방문당 체험·문화 | B6: 152.66675
A7: 목표(전국 중앙 수준) | B7: 179.71399
A8: 목표까지 추가 소비(8개월) | B8: 3.1716433e+08
A9: 월영야행 부스(기준) | B9: 24
A10: 축제 식음 비중 | B10: 0.606
A11: 주말 일수(8개월) | B11: 70
A12: 주민증 월 이용 | B12: 887.5

Sheet d_모의실험
A1: u_p | B1: p | C1: r | D1: 체험가격 | E1: c | F1: u_qb | G1: q_b | H1: u_boat | I1: 문보트가격 | J1: u_qp | K1: q_p | L1: u_k | M1: k | N1: 팝업객단가 | O1: 반사실 | P1: 인증 | Q1: 낮체험 | R1: 저녁도착 | S1: 문보트 | T1: 체험결제 | U1: 체험추가 | V1: 팝업추가 | W1: 연결추가 | X1: 추가합 | Y1: 방문당증가율 | Z1: 격차비율
A2: =RAND() | B2: =IF('d_시나리오'!$J$2='d_시나리오'!$H$2,'d_시나리오'!$I$2,IF(A2<('d_시나리오'!$I$2-'d_시나리오'!$H$2)/('d_시나리오'!$J$2-'d_시나리오'!$H$2),'d_시나리오'!$H$2+SQRT(A2*('d_시나리오'!$J$2-'d_시나리오'!$H$2)*('d_시나리오'!$I$2-'d_시나리오'!$H$2)),'d_시나리오'!$J$2-SQRT((1-A2)*('d_시나리오'!$J$2-'d_시나리오'!$H$2)*('d_시나리오'!$J$2-'d_시나리오'!$I$2)))) | C2: =BETAINV(RAND(),2,6) | D2: =INDEX('d_분포'!$A$2:$A$28,RANDBETWEEN(1,27)) | E2: =INDEX('d_분포'!$C$2:$C$5,RANDBETWEEN(1,4))*(0.9+0.2*RAND()) | F2: =RAND() | G2: =IF('d_시나리오'!$J$3='d_시나리오'!$H$3,'d_시나리오'!$I$3,IF(F2<('d_시나리오'!$I$3-'d_시나리오'!$H$3)/('d_시나리오'!$J$3-'d_시나리오'!$H$3),'d_시나리오'!$H$3+SQRT(F2*('d_시나리오'!$J$3-'d_시나리오'!$H$3)*('d_시나리오'!$I$3-'d_시나리오'!$H$3)),'d_시나리오'!$J$3-SQRT((1-F2)*('d_시나리오'!$J$3-'d_시나리오'!$H$3)*('d_시나리오'!$J$3-'d_시나리오'!$I$3)))) | H2: =RAND() | I2: =IF('d_시나리오'!$J$4='d_시나리오'!$H$4,'d_시나리오'!$I$4,IF(H2<('d_시나리오'!$I$4-'d_시나리오'!$H$4)/('d_시나리오'!$J$4-'d_시나리오'!$H$4),'d_시나리오'!$H$4+SQRT(H2*('d_시나리오'!$J$4-'d_시나리오'!$H$4)*('d_시나리오'!$I$4-'d_시나리오'!$H$4)),'d_시나리오'!$J$4-SQRT((1-H2)*('d_시나리오'!$J$4-'d_시나리오'!$H$4)*('d_시나리오'!$J$4-'d_시나리오'!$I$4)))) | J2: =RAND() | K2: =IF('d_시나리오'!$J$5='d_시나리오'!$H$5,'d_시나리오'!$I$5,IF(J2<('d_시나리오'!$I$5-'d_시나리오'!$H$5)/('d_시나리오'!$J$5-'d_시나리오'!$H$5),'d_시나리오'!$H$5+SQRT(J2*('d_시나리오'!$J$5-'d_시나리오'!$H$5)*('d_시나리오'!$I$5-'d_시나리오'!$H$5)),'d_시나리오'!$J$5-SQRT((1-J2)*('d_시나리오'!$J$5-'d_시나리오'!$H$5)*('d_시나리오'!$J$5-'d_시나리오'!$I$5)))) | L2: =RAND() | M2: =IF('d_시나리오'!$J$6='d_시나리오'!$H$6,'d_시나리오'!$I$6,IF(L2<('d_시나리오'!$I$6-'d_시나리오'!$H$6)/('d_시나리오'!$J$6-'d_시나리오'!$H$6),'d_시나리오'!$H$6+SQRT(L2*('d_시나리오'!$J$6-'d_시나리오'!$H$6)*('d_시나리오'!$I$6-'d_시나리오'!$H$6)),'d_시나리오'!$J$6-SQRT((1-L2)*('d_시나리오'!$J$6-'d_시나리오'!$H$6)*('d_시나리오'!$J$6-'d_시나리오'!$I$6)))) | N2: =INDEX('d_분포'!$B$2:$B$57,RANDBETWEEN(1,56)) | O2: =BETAINV(RAND(),5,5) | P2: ='d_고정'!$B$1*'6_기대효과'!$H$7*('d_시나리오'!$I$7/'d_고정'!$B$2)*B2 | Q2: =P2*C2 | R2: =P2*E2 | S2: =R2*G2 | T2: =Q2+S2 | U2: =(Q2*D2+S2*I2)*(1-O2) | V2: =(R2*K2*N2+'d_고정'!$B$3*('6_기대효과'!$H$7/8)*N2*'d_고정'!$B$10*M2*('6_기대효과'!$K$7/'d_고정'!$B$9))*(1-O2) | W2: =(S2*I2+R2*MAX(K2-'d_고정'!$B$10*M2*('6_기대효과'!$K$7/'d_고정'!$B$9),0)*N2)*(1-O2) | X2: =U2+V2 | Y2: =U2/('d_고정'!$B$5*'6_기대효과'!$H$7/8)/'d_고정'!$B$6 | Z2: =U2/('d_고정'!$B$8*'6_기대효과'!$H$7/8)
A3: =RAND() | B3: =IF('d_시나리오'!$J$2='d_시나리오'!$H$2,'d_시나리오'!$I$2,IF(A3<('d_시나리오'!$I$2-'d_시나리오'!$H$2)/('d_시나리오'!$J$2-'d_시나리오'!$H$2),'d_시나리오'!$H$2+SQRT(A3*('d_시나리오'!$J$2-'d_시나리오'!$H$2)*('d_시나리오'!$I$2-'d_시나리오'!$H$2)),'d_시나리오'!$J$2-SQRT((1-A3)*('d_시나리오'!$J$2-'d_시나리오'!$H$2)*('d_시나리오'!$J$2-'d_시나리오'!$I$2)))) | C3: =BETAINV(RAND(),2,6) | D3: =INDEX('d_분포'!$A$2:$A$28,RANDBETWEEN(1,27)) | E3: =INDEX('d_분포'!$C$2:$C$5,RANDBETWEEN(1,4))*(0.9+0.2*RAND()) | F3: =RAND() | G3: =IF('d_시나리오'!$J$3='d_시나리오'!$H$3,'d_시나리오'!$I$3,IF(F3<('d_시나리오'!$I$3-'d_시나리오'!$H$3)/('d_시나리오'!$J$3-'d_시나리오'!$H$3),'d_시나리오'!$H$3+SQRT(F3*('d_시나리오'!$J$3-'d_시나리오'!$H$3)*('d_시나리오'!$I$3-'d_시나리오'!$H$3)),'d_시나리오'!$J$3-SQRT((1-F3)*('d_시나리오'!$J$3-'d_시나리오'!$H$3)*('d_시나리오'!$J$3-'d_시나리오'!$I$3)))) | H3: =RAND() | I3: =IF('d_시나리오'!$J$4='d_시나리오'!$H$4,'d_시나리오'!$I$4,IF(H3<('d_시나리오'!$I$4-'d_시나리오'!$H$4)/('d_시나리오'!$J$4-'d_시나리오'!$H$4),'d_시나리오'!$H$4+SQRT(H3*('d_시나리오'!$J$4-'d_시나리오'!$H$4)*('d_시나리오'!$I$4-'d_시나리오'!$H$4)),'d_시나리오'!$J$4-SQRT((1-H3)*('d_시나리오'!$J$4-'d_시나리오'!$H$4)*('d_시나리오'!$J$4-'d_시나리오'!$I$4)))) | J3: =RAND() | K3: =IF('d_시나리오'!$J$5='d_시나리오'!$H$5,'d_시나리오'!$I$5,IF(J3<('d_시나리오'!$I$5-'d_시나리오'!$H$5)/('d_시나리오'!$J$5-'d_시나리오'!$H$5),'d_시나리오'!$H$5+SQRT(J3*('d_시나리오'!$J$5-'d_시나리오'!$H$5)*('d_시나리오'!$I$5-'d_시나리오'!$H$5)),'d_시나리오'!$J$5-SQRT((1-J3)*('d_시나리오'!$J$5-'d_시나리오'!$H$5)*('d_시나리오'!$J$5-'d_시나리오'!$I$5)))) | L3: =RAND() | M3: =IF('d_시나리오'!$J$6='d_시나리오'!$H$6,'d_시나리오'!$I$6,IF(L3<('d_시나리오'!$I$6-'d_시나리오'!$H$6)/('d_시나리오'!$J$6-'d_시나리오'!$H$6),'d_시나리오'!$H$6+SQRT(L3*('d_시나리오'!$J$6-'d_시나리오'!$H$6)*('d_시나리오'!$I$6-'d_시나리오'!$H$6)),'d_시나리오'!$J$6-SQRT((1-L3)*('d_시나리오'!$J$6-'d_시나리오'!$H$6)*('d_시나리오'!$J$6-'d_시나리오'!$I$6)))) | N3: =INDEX('d_분포'!$B$2:$B$57,RANDBETWEEN(1,56)) | O3: =BETAINV(RAND(),5,5) | P3: ='d_고정'!$B$1*'6_기대효과'!$H$7*('d_시나리오'!$I$7/'d_고정'!$B$2)*B3 | Q3: =P3*C3 | R3: =P3*E3 | S3: =R3*G3 | T3: =Q3+S3 | U3: =(Q3*D3+S3*I3)*(1-O3) | V3: =(R3*K3*N3+'d_고정'!$B$3*('6_기대효과'!$H$7/8)*N3*'d_고정'!$B$10*M3*('6_기대효과'!$K$7/'d_고정'!$B$9))*(1-O3) | W3: =(S3*I3+R3*MAX(K3-'d_고정'!$B$10*M3*('6_기대효과'!$K$7/'d_고정'!$B$9),0)*N3)*(1-O3) | X3: =U3+V3 | Y3: =U3/('d_고정'!$B$5*'6_기대효과'!$H$7/8)/'d_고정'!$B$6 | Z3: =U3/('d_고정'!$B$8*'6_기대효과'!$H$7/8)
