Workbook

Sheet 한눈에
B2: 안동 이어드림 · 데이터 대시보드
B3: 데이터 기반 21시 이후 소비 릴레이 ‘안동 이어드림’: 원도심에서 월영교로
B4: 디지털 관광주민증 위 3단계 릴레이. 아래 칸을 누르면 그 화면으로 간다. 모든 효과는 시행 전 예측이다.
B7: 01 문제 | N7: 02 기대효과 | Z7: 03 우리 시·군 진단
B8: 방문 1회당 체험·문화 소비 | N8: 100명 중 2명 참여 시 방문당 체험·문화 소비 | Z8: 안동과 같은 문제 유형
B9: -0.16790571 | M9: › | N9: 157.95246 | Y9: › | Z9: 6
B10: 146개 시·군 중 22번째로 많이 줄었다 | N10: 지금 152.7원에서 +3.5% | Z10: 체험·문화 소비 하락 + 짧은 숙박
B11: 전국 중앙 −2.0% | N11: 월영교 저녁 이동 주말 하루 110명 | Z11: 영덕 · 양양 · 남해 · 울진 · 광명 · 강릉
B13: 빈 곳 세 군데: 1 원도심 혜택 0곳 · 2 19시 이후 버스 0회 · 3 월영교 주점 0곳 | N13: 시행 전 예측, 1만 번 계산의 가운데 값 | Z13: 시·군을 고르면 그 지역 진단이 나온다. 주민증 운영 52개 지자체에 적용 가능
Z14: 열기 +
B18: 릴레이 3단계 번호를 누르면 근거 화면으로 간다
B20: 1 | C20: 낮 · 원도심 식당 83곳에서 식사 → 체험 10% 할인 | N20: 2 | O20: 저녁 18:30~21:00 원도심 → 월영교 택시, 늘면 셔틀 | Z20: 3 | AA20: 밤 · 월영교 문보트 + 21시 이후 식사·주점 팝업
B22: 화면 바로가기 칸을 누르면 그 화면으로 간다. 화면마다 파란 칸으로 조건을 바꿀 수 있다
B24: 시·군 진단 → | I24: 운영 시간 → | P24: 버스 → | W24: 월영교 → | AD24: 설문조사 →
B25: 6곳 | I25: 18:30~21:00 | P25: 0회 | W25: 0곳 | AD25: 103명
B26: 안동과 같은 유형 | I26: 안동역 막차 21~22시 | P26: 19시 이후 원도심 → 월영교 | W26: 월영교 1km 주점 | AD26: 팀 설문(방문 경험 72명)
B27: ▼ 시·군 · 가중치 | I27: ▼ 연도 · 요일 · 열차 · 시작·종료 | P27: ▼ 노선 · 시간표 · 추가 운행 | W27: ▼ 팝업 부스 · 종료 시각 · 관광지 | AD27: ▼ 응답자 범위 · 이동수단
B30: 쓰는 법
B31: · 파란 테두리 칸은 누르면 ▼ 목록이 나오거나 숫자를 바꿀 수 있다. 바꾸면 카드·그래프·표가 바로 바뀐다.
B32: · 숫자 오른쪽 위 빨간 삼각형에 마우스를 올리면 출처와 계산 방법이 보인다.
B33: · 화면 아래 파란 띠(표로 보기)와 노란 띠(데이터 설명)는 왼쪽 여백의 [+] 를 누르면 펼쳐진다.
B34: · 빨강 = 줄었거나 문제인 것, 파랑 = 늘었거나 좋아진 것.
B36: 출처: 한국관광 데이터랩, 한국철도공사, 코레일, 소상공인 상가정보, 안동시 버스정보시스템·주민증 자료, 팀 온라인 설문 103명. 자세한 출처는 화면마다 「데이터 설명」.

Sheet 시·군 진단
B2: 시·군 진단
B3: 안동과 같은 문제를 가진 시·군 찾기
B4: 144개 시·군을 네 지표로 진단한다. 시·군을 고르면 위치와 문제 유형이 나오고, 가중치를 바꾸면 순위가 얼마나 흔들리는지 보인다.
B6: 화면 | E6: 한눈에 | J6: 시·군 진단 | O6: 운영 시간 | T6: 버스 | Y6: 월영교 | AD6: 설문조사
B8: 시·군 ▼ | K8: 가중치 · 체험·문화 | R8: 가중치 · 숙박일수 | Y8: 가중치 · 저녁 전환 | AF8: 가중치 · 야간 방문
B9: 안동시 | K9: 1 | R9: 1 | Y9: 1 | AF9: 1 | AM9: ='시·군 진단'!$B$9 -> 안동시
B11: 진단 점수 (100에 가까울수록 문제) | K11: 문제 유형 (하위 25%인 지표) | T11: 방문당 체험·문화 소비 변화 | AC11: 평균 숙박일수
B12: =INDEX(d_진단!$J$2:$J$145,MATCH('시·군 진단'!$B$9,d_진단!$A$2:$A$145,0)) -> 53.993056 | K12: =IF(INDEX(d_진단!$L$2:$L$145,MATCH('시·군 진단'!$B$9,d_진단!$A$2:$A$145,0))="","해당 없음",INDEX(d_진단!$L$2:$L$145,MATCH('시·군 진단'!$B$9,d_진단!$A$2:$A$145,0))) -> 체험·문화 · 숙박일수 | T12: =INDEX(d_진단!$B$2:$B$145,MATCH('시·군 진단'!$B$9,d_진단!$A$2:$A$145,0)) -> -0.16790571 | AC12: =INDEX(d_진단!$C$2:$C$145,MATCH('시·군 진단'!$B$9,d_진단!$A$2:$A$145,0)) -> 3.0658333
B13: ="144곳 중 "&INDEX(d_진단!$K$2:$K$145,MATCH('시·군 진단'!$B$9,d_진단!$A$2:$A$145,0))&"위 · 가중치 반영" -> 144곳 중 57위 · 가중치 반영 | K13: ="같은 유형 "&COUNTIF(d_진단!$L$2:$L$145,INDEX(d_진단!$L$2:$L$145,MATCH('시·군 진단'!$B$9,d_진단!$A$2:$A$145,0)))&"곳" -> 같은 유형 7곳 | T13: ="문제 백분위 "&TEXT(INDEX(d_진단!$F$2:$F$145,MATCH('시·군 진단'!$B$9,d_진단!$A$2:$A$145,0)),"0")&" · 중앙 "&TEXT(MEDIAN(d_진단!$B$2:$B$145),"+0.0%;−0.0%") -> 문제 백분위 85 · 중앙 −2.0% | AC13: ="문제 백분위 "&TEXT(INDEX(d_진단!$G$2:$G$145,MATCH('시·군 진단'!$B$9,d_진단!$A$2:$A$145,0)),"0")&" · 중앙 "&TEXT(MEDIAN(d_진단!$C$2:$C$145),"0.00")&"일" -> 문제 백분위 83 · 중앙 3.56일
B15: 출처 한국관광 데이터랩(외지인 카드 소비·방문 BDT_02_01_003·BDT_01_01_006, 평균 숙박일수 LN_02_01_013, 시간대별 방문) → 팀 전국 진단표 144곳
B17: 네 지표의 문제 백분위 75 이상 = 하위 25% | U17: 체험·문화 소비 변화 × 숙박일수 왼쪽 아래일수록 안동과 같은 유형
B18: ■ 고른 시·군 ■ 안동 | U18: ● 고른 시·군 ● 안동 ● 다른 시·군
B31: 출처 팀 전국 진단표(scripts/전국진단표.py), 데이터랩 2024·2026년 1~8월·2025년 자료 | U31: 가로 = 체험·문화 소비 변화 | AC31: 세로 = 평균 숙박일수(일)
B33: 진단 점수 상위 10곳 가중치를 바꾸면 바로 바뀐다 | X33: 안동과 같은 유형
B34: 순위 | D34: 시·군 | J34: 점수 | N34: 유형 | X34: 6곳 체험·문화 소비 하락 + 짧은 숙박
B35: 1 | D35: =INDEX(d_진단!$A$2:$A$145,MATCH(LARGE(d_진단!$M$2:$M$145,1),d_진단!$M$2:$M$145,0)) -> 기장군 | J35: =INDEX(d_진단!$J$2:$J$145,MATCH(LARGE(d_진단!$M$2:$M$145,1),d_진단!$M$2:$M$145,0)) -> 88.020833 | N35: =INDEX(d_진단!$L$2:$L$145,MATCH(LARGE(d_진단!$M$2:$M$145,1),d_진단!$M$2:$M$145,0)) -> 체험·문화 · 숙박일수 · 저녁전환 · 야간방문
B36: 2 | D36: =INDEX(d_진단!$A$2:$A$145,MATCH(LARGE(d_진단!$M$2:$M$145,2),d_진단!$M$2:$M$145,0)) -> 진안군 | J36: =INDEX(d_진단!$J$2:$J$145,MATCH(LARGE(d_진단!$M$2:$M$145,2),d_진단!$M$2:$M$145,0)) -> 86.805556 | N36: =INDEX(d_진단!$L$2:$L$145,MATCH(LARGE(d_진단!$M$2:$M$145,2),d_진단!$M$2:$M$145,0)) -> 체험·문화 · 저녁전환 · 야간방문 | X36: 영덕 · 양양 · 남해 · 울진 · 광명 · 강릉
B37: 3 | D37: =INDEX(d_진단!$A$2:$A$145,MATCH(LARGE(d_진단!$M$2:$M$145,3),d_진단!$M$2:$M$145,0)) -> 청도군 | J37: =INDEX(d_진단!$J$2:$J$145,MATCH(LARGE(d_진단!$M$2:$M$145,3),d_진단!$M$2:$M$145,0)) -> 79.340278 | N37: =INDEX(d_진단!$L$2:$L$145,MATCH(LARGE(d_진단!$M$2:$M$145,3),d_진단!$M$2:$M$145,0)) -> 체험·문화 · 저녁전환 · 야간방문
B38: 4 | D38: =INDEX(d_진단!$A$2:$A$145,MATCH(LARGE(d_진단!$M$2:$M$145,4),d_진단!$M$2:$M$145,0)) -> 합천군 | J38: =INDEX(d_진단!$J$2:$J$145,MATCH(LARGE(d_진단!$M$2:$M$145,4),d_진단!$M$2:$M$145,0)) -> 78.645833 | N38: =INDEX(d_진단!$L$2:$L$145,MATCH(LARGE(d_진단!$M$2:$M$145,4),d_진단!$M$2:$M$145,0)) -> 저녁전환 · 야간방문 | X38: 이어드림 방식을 옮겨 쓸 1차 후보. 디지털 관광주민증을 운영하는 52개 지자체에도 같은 틀을 적용할 수 있다.
B39: 5 | D39: =INDEX(d_진단!$A$2:$A$145,MATCH(LARGE(d_진단!$M$2:$M$145,5),d_진단!$M$2:$M$145,0)) -> 화순군 | J39: =INDEX(d_진단!$J$2:$J$145,MATCH(LARGE(d_진단!$M$2:$M$145,5),d_진단!$M$2:$M$145,0)) -> 76.909722 | N39: =INDEX(d_진단!$L$2:$L$145,MATCH(LARGE(d_진단!$M$2:$M$145,5),d_진단!$M$2:$M$145,0)) -> 체험·문화 · 저녁전환 · 야간방문
B40: 6 | D40: =INDEX(d_진단!$A$2:$A$145,MATCH(LARGE(d_진단!$M$2:$M$145,6),d_진단!$M$2:$M$145,0)) -> 완주군 | J40: =INDEX(d_진단!$J$2:$J$145,MATCH(LARGE(d_진단!$M$2:$M$145,6),d_진단!$M$2:$M$145,0)) -> 74.479167 | N40: =INDEX(d_진단!$L$2:$L$145,MATCH(LARGE(d_진단!$M$2:$M$145,6),d_진단!$M$2:$M$145,0)) -> 체험·문화 · 저녁전환 · 야간방문
B41: 7 | D41: =INDEX(d_진단!$A$2:$A$145,MATCH(LARGE(d_진단!$M$2:$M$145,7),d_진단!$M$2:$M$145,0)) -> 인제군 | J41: =INDEX(d_진단!$J$2:$J$145,MATCH(LARGE(d_진단!$M$2:$M$145,7),d_진단!$M$2:$M$145,0)) -> 74.305556 | N41: =INDEX(d_진단!$L$2:$L$145,MATCH(LARGE(d_진단!$M$2:$M$145,7),d_진단!$M$2:$M$145,0)) -> 체험·문화 · 저녁전환 · 야간방문 | X41: 가중치를 무작위로 바꾸면 안동 순위는 18~100위로 흔들린다. 그래서 점수보다 유형으로 읽는다.
B42: 8 | D42: =INDEX(d_진단!$A$2:$A$145,MATCH(LARGE(d_진단!$M$2:$M$145,8),d_진단!$M$2:$M$145,0)) -> 순창군 | J42: =INDEX(d_진단!$J$2:$J$145,MATCH(LARGE(d_진단!$M$2:$M$145,8),d_진단!$M$2:$M$145,0)) -> 73.611111 | N42: =INDEX(d_진단!$L$2:$L$145,MATCH(LARGE(d_진단!$M$2:$M$145,8),d_진단!$M$2:$M$145,0)) -> 저녁전환 · 야간방문
B43: 9 | D43: =INDEX(d_진단!$A$2:$A$145,MATCH(LARGE(d_진단!$M$2:$M$145,9),d_진단!$M$2:$M$145,0)) -> 담양군 | J43: =INDEX(d_진단!$J$2:$J$145,MATCH(LARGE(d_진단!$M$2:$M$145,9),d_진단!$M$2:$M$145,0)) -> 72.569444 | N43: =INDEX(d_진단!$L$2:$L$145,MATCH(LARGE(d_진단!$M$2:$M$145,9),d_진단!$M$2:$M$145,0)) -> 저녁전환 · 야간방문
B44: 10 | D44: =INDEX(d_진단!$A$2:$A$145,MATCH(LARGE(d_진단!$M$2:$M$145,10),d_진단!$M$2:$M$145,0)) -> 금산군 | J44: =INDEX(d_진단!$J$2:$J$145,MATCH(LARGE(d_진단!$M$2:$M$145,10),d_진단!$M$2:$M$145,0)) -> 71.527778 | N44: =INDEX(d_진단!$L$2:$L$145,MATCH(LARGE(d_진단!$M$2:$M$145,10),d_진단!$M$2:$M$145,0)) -> 저녁전환 · 야간방문
B45: 출처 팀 전국 진단표. 점수는 위 파란 칸 가중치로 다시 계산
B47: 144곳 전체 표로 보기 ▼ 네 지표 값·점수·순위·유형(가중치 반영, 진단표 순서). 왼쪽 여백의 [+] 를 누르면 펼쳐진다
B48: 시·군 | G48: 체험·문화 변화 | K48: 숙박일수 | N48: 저녁 전환율 | Q48: 야간 방문 | T48: 점수 | W48: 순위 | Y48: 유형
B49: =d_진단!A2 -> 기장군 | G49: =d_진단!B2 -> -0.17069615 | K49: =d_진단!C2 -> 3.0458333 | N49: =d_진단!D2 -> 0.45403383 | Q49: =d_진단!E2 -> 0.072846042 | T49: =d_진단!J2 -> 88.020833 | W49: =d_진단!K2 -> 1 | Y49: =d_진단!L2 -> 체험·문화 · 숙박일수 · 저녁전환 · 야간방문
B50: =d_진단!A3 -> 진안군 | G50: =d_진단!B3 -> -0.41449101 | K50: =d_진단!C3 -> 3.4691667 | N50: =d_진단!D3 -> 0.41782422 | Q50: =d_진단!E3 -> 0.07421261 | T50: =d_진단!J3 -> 86.805556 | W50: =d_진단!K3 -> 2 | Y50: =d_진단!L3 -> 체험·문화 · 저녁전환 · 야간방문
B51: =d_진단!A4 -> 청도군 | G51: =d_진단!B4 -> -0.23040739 | K51: =d_진단!C4 -> 3.4225 | N51: =d_진단!D4 -> 0.44780312 | Q51: =d_진단!E4 -> 0.082486299 | T51: =d_진단!J4 -> 79.340278 | W51: =d_진단!K4 -> 3 | Y51: =d_진단!L4 -> 체험·문화 · 저녁전환 · 야간방문
B52: =d_진단!A5 -> 합천군 | G52: =d_진단!B5 -> -0.085887649 | K52: =d_진단!C5 -> 3.2658333 | N52: =d_진단!D5 -> 0.44271466 | Q52: =d_진단!E5 -> 0.077971584 | T52: =d_진단!J5 -> 78.645833 | W52: =d_진단!K5 -> 4 | Y52: =d_진단!L5 -> 저녁전환 · 야간방문
B53: =d_진단!A6 -> 화순군 | G53: =d_진단!B6 -> -0.12739607 | K53: =d_진단!C6 -> 3.5483333 | N53: =d_진단!D6 -> 0.44088923 | Q53: =d_진단!E6 -> 0.075350065 | T53: =d_진단!J6 -> 76.909722 | W53: =d_진단!K6 -> 5 | Y53: =d_진단!L6 -> 체험·문화 · 저녁전환 · 야간방문
B54: =d_진단!A7 -> 완주군 | G54: =d_진단!B7 -> -0.34887626 | K54: =d_진단!C7 -> 3.6625 | N54: =d_진단!D7 -> 0.47268543 | Q54: =d_진단!E7 -> 0.073504909 | T54: =d_진단!J7 -> 74.479167 | W54: =d_진단!K7 -> 6 | Y54: =d_진단!L7 -> 체험·문화 · 저녁전환 · 야간방문
B55: =d_진단!A8 -> 인제군 | G55: =d_진단!B8 -> -0.38094579 | K55: =d_진단!C8 -> 3.5741667 | N55: =d_진단!D8 -> 0.47111241 | Q55: =d_진단!E8 -> 0.080605051 | T55: =d_진단!J8 -> 74.305556 | W55: =d_진단!K8 -> 7 | Y55: =d_진단!L8 -> 체험·문화 · 저녁전환 · 야간방문
B56: =d_진단!A9 -> 순창군 | G56: =d_진단!B9 -> -0.11446925 | K56: =d_진단!C9 -> 3.5775 | N56: =d_진단!D9 -> 0.41214914 | Q56: =d_진단!E9 -> 0.077426707 | T56: =d_진단!J9 -> 73.611111 | W56: =d_진단!K9 -> 8 | Y56: =d_진단!L9 -> 저녁전환 · 야간방문
B57: =d_진단!A10 -> 담양군 | G57: =d_진단!B10 -> 0.12572713 | K57: =d_진단!C10 -> 3.3641667 | N57: =d_진단!D10 -> 0.39403789 | Q57: =d_진단!E10 -> 0.058294063 | T57: =d_진단!J10 -> 72.569444 | W57: =d_진단!K10 -> 9 | Y57: =d_진단!L10 -> 저녁전환 · 야간방문
B58: =d_진단!A11 -> 금산군 | G58: =d_진단!B11 -> -0.11595326 | K58: =d_진단!C11 -> 3.5333333 | N58: =d_진단!D11 -> 0.45763084 | Q58: =d_진단!E11 -> 0.082358632 | T58: =d_진단!J11 -> 71.527778 | W58: =d_진단!K11 -> 10 | Y58: =d_진단!L11 -> 저녁전환 · 야간방문
B59: =d_진단!A12 -> 횡성군 | G59: =d_진단!B12 -> -0.15570733 | K59: =d_진단!C12 -> 3.4725 | N59: =d_진단!D12 -> 0.48819521 | Q59: =d_진단!E12 -> 0.085771007 | T59: =d_진단!J12 -> 70.833333 | W59: =d_진단!K12 -> 11 | Y59: =d_진단!L12 -> 체험·문화
B60: =d_진단!A13 -> 단양군 | G60: =d_진단!B13 -> -0.09673635 | K60: =d_진단!C13 -> 2.7383333 | N60: =d_진단!D13 -> 0.48144055 | Q60: =d_진단!E13 -> 0.095163112 | T60: =d_진단!J13 -> 70.833333 | W60: =d_진단!K13 -> 11 | Y60: =d_진단!L13 -> 숙박일수
...

Sheet 운영 시간
B2: 운영 시간
B3: 안동역 막차에 맞춘 18:30~21:00
B4: 주말 저녁 승차는 18~19시가 가장 많고(하루 최다는 오후) 막차는 21~22시다. 릴레이 시작·종료 시각을 바꿔 창 안에 드는 승차를 본다.
B6: 화면 | E6: 한눈에 | J6: 시·군 진단 | O6: 운영 시간 | T6: 버스 | Y6: 월영교 | AD6: 설문조사
B8: 연도 ▼ | H8: 요일 ▼ | O8: 열차 ▼ | V8: 릴레이 시작(시) | AB8: 릴레이 종료(시)
B9: 2026 | H9: 주말 | O9: 전체 | V9: 18.5 | AB9: 21 | AH9: ◥ 18.5 = 18:30
B11: 저녁(17~22시) 최대 승차 시간대 | K11: 마지막 승차 시간대(막차) | T11: 릴레이 창 안 승차 비중 | AC11: 종료 후 막차까지 여유
B12: =INDEX(d_역계산!$A$14:$A$18,MATCH(MAX(d_역계산!$C$14:$C$18),d_역계산!$C$14:$C$18,0)) -> 18시 | K12: =INDEX(d_역계산!$A$2:$A$20,MATCH(LOOKUP(2,1/(d_역계산!$C$2:$C$20>0),d_역계산!$B$2:$B$20),d_역계산!$B$2:$B$20,0)) -> 21시 | T12: =SUMIFS(d_역계산!$C$2:$C$20,d_역계산!$B$2:$B$20,">="&INT('운영 시간'!$V$9),d_역계산!$B$2:$B$20,"<"&'운영 시간'!$AB$9)/SUM(d_역계산!$C$2:$C$20) -> 0.18618674 | AC12: =MAX(0,LOOKUP(2,1/(d_역계산!$C$2:$C$20>0),d_역계산!$B$2:$B$20)+1-'운영 시간'!$AB$9) -> 1
B13: ="승차 "&TEXT(MAX(d_역계산!$C$14:$C$18),"#,##0")&"명 (1~8월 합계)" -> 승차 13,454명 (1~8월 합계) | K13: ="22시 이후 승차 "&TEXT(SUM(d_역계산!$C$19:$C$20),"#,##0")&"명" -> 22시 이후 승차 0명 | T13: ="창 "&TEXT('운영 시간'!$V$9/24,"hh:mm")&"~"&TEXT('운영 시간'!$AB$9/24,"hh:mm")&" 승차 ÷ 하루 승차" -> 창 18:30~21:00 승차 ÷ 하루 승차 | AC13: =IF('운영 시간'!$AB$9>LOOKUP(2,1/(d_역계산!$C$2:$C$20>0),d_역계산!$B$2:$B$20)+1,"막차 이후 → 귀가 수단 없음",IF('운영 시간'!$AB$9>LOOKUP(2,1/(d_역계산!$C$2:$C$20>0),d_역계산!$B$2:$B$20),"막차 시간대와 겹침 → 여유 없음","막차 전에 끝남")) -> 막차 전에 끝남
B15: 출처 코레일 안동역 월별·요일별·시간대별 승하차(KTX-이음·새마을·무궁화, 2024.1~2026.8, 팀원 취합), 1~8월 합계
B17: 안동역 시간대별 승차 고른 연도·요일·열차, 1~8월 합계 | AA17: ■ 릴레이 창 안 ■ 창 밖
B30: 출처 코레일 안동역 시간대별 승하차(2024.1~2026.8, 팀원 취합). 승차에는 주민이 섞여 있다
B32: 안동역 시간대별 하차(도착) 같은 조건 | AA32: ━ 하차
B41: 출처 코레일 안동역 시간대별 승하차(2024.1~2026.8, 팀원 취합)
B43: 설문 당일 귀가한 방문자 40명 중 23명(58%)이 20~22시 막차 시간대에 귀가했다. 릴레이가 21시 전에 끝나야 하는 이유와 같은 방향이다.
B45: 시간대별 승하차 표로 보기 ▼ 위 그래프의 숫자(고른 조건 그대로). 왼쪽 여백의 [+] 를 누르면 펼쳐진다
B46: 시간대 | H46: 승차 | O46: 하차 | V46: 릴레이 창 안 승차
B47: =d_역계산!A2 -> 05시 | H47: =d_역계산!C2 -> 0 | O47: =d_역계산!D2 -> 0 | V47: =IFERROR(d_역계산!E2,"") | AC47: =IF(ISNUMBER(d_역계산!E2),"창 안","")&IF(AND(d_역계산!C2>0,N(d_역계산!C3)=0)," 막차 시간대","")
B48: =d_역계산!A3 -> 06시 | H48: =d_역계산!C3 -> 5297 | O48: =d_역계산!D3 -> 0 | V48: =IFERROR(d_역계산!E3,"") | AC48: =IF(ISNUMBER(d_역계산!E3),"창 안","")&IF(AND(d_역계산!C3>0,N(d_역계산!C4)=0)," 막차 시간대","")
B49: =d_역계산!A4 -> 07시 | H49: =d_역계산!C4 -> 12235 | O49: =d_역계산!D4 -> 4122 | V49: =IFERROR(d_역계산!E4,"") | AC49: =IF(ISNUMBER(d_역계산!E4),"창 안","")&IF(AND(d_역계산!C4>0,N(d_역계산!C5)=0)," 막차 시간대","")
B50: =d_역계산!A5 -> 08시 | H50: =d_역계산!C5 -> 3846 | O50: =d_역계산!D5 -> 3282 | V50: =IFERROR(d_역계산!E5,"") | AC50: =IF(ISNUMBER(d_역계산!E5),"창 안","")&IF(AND(d_역계산!C5>0,N(d_역계산!C6)=0)," 막차 시간대","")
B51: =d_역계산!A6 -> 09시 | H51: =d_역계산!C6 -> 2752 | O51: =d_역계산!D6 -> 3329 | V51: =IFERROR(d_역계산!E6,"") | AC51: =IF(ISNUMBER(d_역계산!E6),"창 안","")&IF(AND(d_역계산!C6>0,N(d_역계산!C7)=0)," 막차 시간대","")
B52: =d_역계산!A7 -> 10시 | H52: =d_역계산!C7 -> 12336 | O52: =d_역계산!D7 -> 7001 | V52: =IFERROR(d_역계산!E7,"") | AC52: =IF(ISNUMBER(d_역계산!E7),"창 안","")&IF(AND(d_역계산!C7>0,N(d_역계산!C8)=0)," 막차 시간대","")
B53: =d_역계산!A8 -> 11시 | H53: =d_역계산!C8 -> 4638 | O53: =d_역계산!D8 -> 9270 | V53: =IFERROR(d_역계산!E8,"") | AC53: =IF(ISNUMBER(d_역계산!E8),"창 안","")&IF(AND(d_역계산!C8>0,N(d_역계산!C9)=0)," 막차 시간대","")
B54: =d_역계산!A9 -> 12시 | H54: =d_역계산!C9 -> 7289 | O54: =d_역계산!D9 -> 4272 | V54: =IFERROR(d_역계산!E9,"") | AC54: =IF(ISNUMBER(d_역계산!E9),"창 안","")&IF(AND(d_역계산!C9>0,N(d_역계산!C10)=0)," 막차 시간대","")
B55: =d_역계산!A10 -> 13시 | H55: =d_역계산!C10 -> 4325 | O55: =d_역계산!D10 -> 9693 | V55: =IFERROR(d_역계산!E10,"") | AC55: =IF(ISNUMBER(d_역계산!E10),"창 안","")&IF(AND(d_역계산!C10>0,N(d_역계산!C11)=0)," 막차 시간대","")
B56: =d_역계산!A11 -> 14시 | H56: =d_역계산!C11 -> 13740 | O56: =d_역계산!D11 -> 5056 | V56: =IFERROR(d_역계산!E11,"") | AC56: =IF(ISNUMBER(d_역계산!E11),"창 안","")&IF(AND(d_역계산!C11>0,N(d_역계산!C12)=0)," 막차 시간대","")
B57: =d_역계산!A12 -> 15시 | H57: =d_역계산!C12 -> 14770 | O57: =d_역계산!D12 -> 15957 | V57: =IFERROR(d_역계산!E12,"") | AC57: =IF(ISNUMBER(d_역계산!E12),"창 안","")&IF(AND(d_역계산!C12>0,N(d_역계산!C13)=0)," 막차 시간대","")
B58: =d_역계산!A13 -> 16시 | H58: =d_역계산!C13 -> 10803 | O58: =d_역계산!D13 -> 10304 | V58: =IFERROR(d_역계산!E13,"") | AC58: =IF(ISNUMBER(d_역계산!E13),"창 안","")&IF(AND(d_역계산!C13>0,N(d_역계산!C14)=0)," 막차 시간대","")
... B65: =d_역계산!A20 -> 23시 | H65: =d_역계산!C20 -> 0 | O65: =d_역계산!D20 -> 9048 | V65: =IFERROR(d_역계산!E20,"") | AC65: =IF(ISNUMBER(d_역계산!E20),"창 안","")&IF(AND(d_역계산!C20>0,N(d_역계산!C21)=0)," 막차 시간대","")
B67: 데이터 설명 ▼ 계산 방법·기간·출처. 왼쪽 여백의 [+] 를 누르면 펼쳐지고 [−] 를 누르면 접힌다
B68: 읽는 법 | I68: 시간 분포에는 열차 시각표가 반영된다(22시 이후 0 = 열차가 없음). 릴레이는 막차 전에 역에 닿도록 18:30에 시작해 21:00에 끝낸다
B69: 주의 | I69: 승차 인원에는 주민이 섞여 있어 "관광객"이라 부르지 않는다. 값은 그 달 해당 요일 전체의 합이다. 떠나는 시각이 아니라 주말 안동역 승차 분포로 읽는다
B70: 출처 | I70: 코레일 안동역 월별·요일별·시간대별 승하차(KTX-이음·새마을·무궁화, 2024.1~2026.8, 팀원 취합). 연도 간 비교를 위해 1~8월만 합산

Sheet 버스
B2: 버스
B3: 19시 이후 원도심 → 월영교 버스 0회
B4: 안동역 ↔ 원도심은 밤 10시까지 다니지만 원도심 → 월영교는 112번 한 노선뿐이다. 노선을 고르고, 저녁 운행을 더해 본다.
B6: 화면 | E6: 한눈에 | J6: 시·군 진단 | O6: 운영 시간 | T6: 버스 | Y6: 월영교 | AD6: 설문조사
B8: 노선 ▼ | I8: 시간표 ▼ | Q8: 19~21시 원도심→월영교 추가(회)
B9: 112 | I9: 평일 | Q9: 0 | Z9: ◥ 추가 운행은 택시·셔틀로 채운다고 본 가정 값. 0 = 지금
B11: 고른 노선 운행 횟수 | K11: 원도심 → 월영교 19시 이후 | T11: 안동역 → 원도심 19시 이후 | AC11: 버스정보 안내기 있는 정류장
B12: =SUM(d_버스계산!$B$2:$B$20) -> 9 | K12: =SUM(d_버스계산!$I$16:$I$20) -> 0 | T12: =SUM(d_버스계산!$C$16:$C$20) -> 65 | AC12: 316
B13: =IF(SUM(d_버스계산!$B$2:$B$20)=0,"이 시간표에는 운행 없음","첫차 "&TEXT(MIN(d_버스출발!$D$2:$D$1398),"hh:mm")&" · 막차 "&TEXT(MAX(d_버스출발!$D$2:$D$1398),"hh:mm")) -> 첫차 07:40 · 막차 19:00 | K13: 추가 전 0회 · 112번 원도심 출발 막차 18:45(평일) | T13: 막차 22:10 · 원도심 → 안동역 막차 22:40 | AC13: 전체 3,309곳 중 · 월영교 500m 4곳 중 1곳
B15: 출처 안동시 버스정보시스템 공개 시간표·노선·정류장(2026-09-22 조회, 46개 노선·3,309개 정류장, 안내기 = bitYn)
B17: 고른 노선의 시간대별 출발 기점 출발 횟수 | U17: 구간별 시간대 운행 평일, 기점 출발
B18: ■ 고른 노선 | U18: ━ 원도심→월영교(추가 반영) ━ 안동역→원도심 ━ 원도심→안동역
B29: 출처 안동시 버스정보시스템 시간표(2026-09-22 조회), 조사 01 시간대별 운행표. 시각은 기점 출발 기준
B31: 안동 시내 지도 위 112번 노선 원도심과 월영교를 잇는 유일한 시내버스
B32: ━ 112번 노선(모든 방향) ○ 112번 정류장 ● 안동역·원도심·월영교 ■ 낙동강·안동호 ┅ 행정동 경계
AC33: 지도 읽는 법
AC34: 빨간 선이 112번이 실제로 다니는 길이다(버스정보시스템 노선 선형, 모든 방향). 흰 점은 정류장. 원도심에서 월영교까지 3.2km. 이 길을 잇는 시내버스는 112번 하나이고, 원도심 출발 막차는 18:45(평일)다. 안동역·터미널은 원도심에서 서쪽으로 떨어져 있어 역 → 원도심 → 월영교가 버스 한 번으로 이어지지 않는다.
B56: 출처 지도 © OpenStreetMap contributors(ODbL)·OpenFreeMap 2026-09-13 · 행정동 경계 통계청 SGIS(vuski/admdongkor 2026.7) · 112번 노선 선형·정류장 안동시 버스정보시스템(2026-09-29 수집)
B58: 설문 시내버스로 다닌 방문자 30명 중 22명(73%)이 불편했다. 이동이 불편해 포기한 곳 1위는 월영교 같은 야간 명소(46%, 33/71명).
B60: 시간대별 운행 표로 보기 ▼ 고른 노선과 주요 구간의 시간대별 기점 출발 횟수. 왼쪽 여백의 [+] 를 누르면 펼쳐진다
B61: 시간대 | G61: 고른 노선 | M61: 안동역→원도심 | T61: 원도심→안동역 | AA61: 원도심→월영교(추가 반영)
B62: =d_버스계산!A2 -> 05시 | G62: =d_버스계산!B2 -> 0 | M62: =d_버스계산!C2 -> 0 | T62: =d_버스계산!D2 -> 0 | AA62: =d_버스계산!I2 -> 0
B63: =d_버스계산!A3 -> 06시 | G63: =d_버스계산!B3 -> 0 | M63: =d_버스계산!C3 -> 22 | T63: =d_버스계산!D3 -> 47 | AA63: =d_버스계산!I3 -> 0
B64: =d_버스계산!A4 -> 07시 | G64: =d_버스계산!B4 -> 1 | M64: =d_버스계산!C4 -> 38 | T64: =d_버스계산!D4 -> 47 | AA64: =d_버스계산!I4 -> 0
B65: =d_버스계산!A5 -> 08시 | G65: =d_버스계산!B5 -> 1 | M65: =d_버스계산!C5 -> 39 | T65: =d_버스계산!D5 -> 36 | AA65: =d_버스계산!I5 -> 1
B66: =d_버스계산!A6 -> 09시 | G66: =d_버스계산!B6 -> 0 | M66: =d_버스계산!C6 -> 37 | T66: =d_버스계산!D6 -> 38 | AA66: =d_버스계산!I6 -> 0
B67: =d_버스계산!A7 -> 10시 | G67: =d_버스계산!B7 -> 1 | M67: =d_버스계산!C7 -> 39 | T67: =d_버스계산!D7 -> 39 | AA67: =d_버스계산!I7 -> 1
B68: =d_버스계산!A8 -> 11시 | G68: =d_버스계산!B8 -> 0 | M68: =d_버스계산!C8 -> 35 | T68: =d_버스계산!D8 -> 36 | AA68: =d_버스계산!I8 -> 0
B69: =d_버스계산!A9 -> 12시 | G69: =d_버스계산!B9 -> 1 | M69: =d_버스계산!C9 -> 34 | T69: =d_버스계산!D9 -> 36 | AA69: =d_버스계산!I9 -> 1
B70: =d_버스계산!A10 -> 13시 | G70: =d_버스계산!B10 -> 0 | M70: =d_버스계산!C10 -> 34 | T70: =d_버스계산!D10 -> 40 | AA70: =d_버스계산!I10 -> 0
B71: =d_버스계산!A11 -> 14시 | G71: =d_버스계산!B11 -> 0 | M71: =d_버스계산!C11 -> 38 | T71: =d_버스계산!D11 -> 38 | AA71: =d_버스계산!I11 -> 0
B72: =d_버스계산!A12 -> 15시 | G72: =d_버스계산!B12 -> 0 | M72: =d_버스계산!C12 -> 39 | T72: =d_버스계산!D12 -> 36 | AA72: =d_버스계산!I12 -> 0
B73: =d_버스계산!A13 -> 16시 | G73: =d_버스계산!B13 -> 1 | M73: =d_버스계산!C13 -> 37 | T73: =d_버스계산!D13 -> 45 | AA73: =d_버스계산!I13 -> 1
... B80: =d_버스계산!A20 -> 23시 | G80: =d_버스계산!B20 -> 0 | M80: =d_버스계산!C20 -> 0 | T80: =d_버스계산!D20 -> 0 | AA80: =d_버스계산!I20 -> 0
B82: 데이터 설명 ▼ 계산 방법·기간·출처. 왼쪽 여백의 [+] 를 누르면 펼쳐지고 [−] 를 누르면 접힌다
B83: 읽는 법 | I83: 버스 시각은 기점 출발 시각이라 구간 통과는 더 늦다. 공휴일 시간표가 없는 노선이 많아 토요일 운행은 단정하지 않는다
B84: 추가 운행 칸 | I84: 관광택시 저녁 배치나 셔틀로 19~21시에 몇 회를 채우면 그래프가 어떻게 바뀌는지 보는 가정이다. 차량 대수·배차 간격은 이용량·회차 시간·견적 없이 정하지 않는다
B85: 출처 | I85: 안동시 버스정보시스템 공개 시간표·노선·정류장(2026-09-22 조회, 46개 노선·3,309개 정류장, 안내기 = bitYn), 국토교통부 전국 버스정류장 위치정보(대조)

Sheet 월영교
B2: 월영교
B3: 사람은 모이지만 21시 이후 식사·주점이 거의 없다
B4: 외곽 관광지 방문자의 54.8%가 월영교에 들르지만 소비 전환 배율은 0.40. 팝업 부스를 넣어 빈자리를 채워 본다(부스 수는 가정).
B6: 화면 | E6: 한눈에 | J6: 시·군 진단 | O6: 운영 시간 | T6: 버스 | Y6: 월영교 | AD6: 설문조사
B8: 팝업 식사·주점 부스(개) | I8: 팝업 종료 시각(시) | P8: 관광지 ▼
B9: 0 | I9: 22 | P9: 월영교 | Z9: ◥ 부스 수는 가정 값. 0 = 지금 상태
B11: 21시까지 식사 가능한 곳 | K11: 주점 | T11: 고른 관광지 소비 전환 배율 | AC11: 외곽 방문자 중 월영교도 방문
B12: =COUNTIFS(d_월영교!$D$2:$D$17,1,d_월영교!$C$2:$C$17,">=21")+IF(월영교!$I$9>=21,월영교!$B$9,0) -> 3 | K12: =IF(월영교!$I$9>=21,월영교!$B$9,0) -> 0 | T12: =INDEX(d_철도!$D$2:$D$20,MATCH(월영교!$P$9,d_철도!$A$2:$A$20,0)) -> 0.4 | AC12: 0.548
B13: ="영업 16곳 중 · 팝업 전 "&COUNTIFS(d_월영교!$D$2:$D$17,1,d_월영교!$C$2:$C$17,">=21")&"곳" -> 영업 16곳 중 · 팝업 전 3곳 | K13: 팝업 전 0곳 · 원도심 1km는 764곳 중 86곳 | T13: ="방문 "&TEXT(INDEX(d_철도!$B$2:$B$20,MATCH(월영교!$P$9,d_철도!$A$2:$A$20,0)),"0.0")&"% vs 소비 건수 "&TEXT(INDEX(d_철도!$C$2:$C$20,MATCH(월영교!$P$9,d_철도!$A$2:$A$20,0)),"0.0")&"% (2022.4~6)" -> 방문 15.2% vs 소비 건수 6.1% (2022.4~6) | AC13: 만휴정 54.8% · 도산서원 54.2% (철도공사)
B15: 출처 소상공인 상가(상권)정보 2026.6(반경 1km) · 팀 확인(영업 종료, 조사 16번) · 한국철도공사 8대 도시(안동) 관광 형태 분석 2022.4~6(소비 = 건수)
B17: 월영교 1km 영업 음식점의 문 닫는 시각 맨 아래 = 팝업 | U17: 음식점 업종 구성 월영교 1km vs 원도심 1km
B18: ■ 21시 전 종료 ■ 21시 이후까지 | U18: ■ 월영교 1km 17곳 ■ 원도심 1km 764곳
B33: 출처 소상공인 상가정보 2026.6(반경 1km), 문 닫는 시각은 팀 확인(조사 16번, 조사일 기록 보완 중) | U33: 출처 소상공인 상가(상권)정보 2026.6, 반경 1km 업종 중분류
B35: 관광지별 방문 vs 소비 점유율 철도공사 2022.4~6, 소비 = 건수 | AA35: ■ 방문 점유율 ■ 소비 건수 점유율
B52: 출처 한국철도공사 8대 도시(안동) 관광 형태 분석, 가명결합, 2022.4~6. 소비 = 건수라 데이터랩 숫자와 한 표에 올리지 않는다
B54: 설문 20시 이후 월영교 주변 식당·편의시설이 부족했다 53%(38/72명), 충분했다 3%. 21~23시 팝업 포차는 방문자 82%가 긍정(의향이지 이용률이 아니다).
B56: 월영교 1km 영업 음식점 16곳 표로 보기 ▼ 업종·문 닫는 시각(팀 확인). 왼쪽 여백의 [+] 를 누르면 펼쳐진다
B57: 업체 | N57: 업종 | T57: 문 닫는 시각 | Z57: 21시 이후 식사
B58: 안동댐간고등어직영식당 | N58: 한식 | T58: 20:00
B59: 맛50년헛제사밥 | N59: 한식 | T59: 20:00
B60: 호반정 | N60: 한식 | T60: 20:00
B61: 옛날촌동네 | N61: 한식 | T61: 20:00
B62: 삼일가든 | N62: 한식 | T62: 20:30
B63: 이정식당 | N63: 한식 | T63: 20:30
B64: 고센피제리아안동댐점 | N64: 서양식 | T64: 20:30
B65: 안동김대감 | N65: 한식 | T65: 21:00 | Z65: 가능
B66: 와룡가든 | N66: 한식 | T66: 21:00 | Z66: 가능
B67: 라라룬 | N67: 카페 | T67: 22:00
B68: 월영당 | N68: 카페 | T68: 22:00
B69: 카페구름마루 | N69: 카페 | T69: 22:00
B70: 콩깍지 | N70: 한식 | T70: 22:00 | Z70: 가능
B71: 월영교달방 | N71: 카페 | T71: 23:00
B72: 핸즈안동댐점 | N72: 카페 | T72: 23:00
B73: 나우커피안동댐점 | N73: 카페 | T73: 24:00
B75: 관광지별 방문·소비 표로 보기 ▼ 방문 점유율, 소비 건수 점유율, 소비 전환 배율. 왼쪽 여백의 [+] 를 누르면 펼쳐진다
B76: 관광지 | N76: 방문 점유율 | U76: 소비 건수 점유율 | AB76: 소비 전환 배율
B77: =d_철도!A2 -> 월영교 | N77: =d_철도!B2 -> 15.24 | U77: =d_철도!C2 -> 6.05 | AB77: =d_철도!D2 -> 0.4
B78: =d_철도!A3 -> 안동문화관광단지 | N78: =d_철도!B3 -> 11.02 | U78: =d_철도!C3 -> 2.28 | AB78: =d_철도!D3 -> 0.21
B79: =d_철도!A4 -> 안동하회마을 | N79: =d_철도!B4 -> 6.29 | U79: =d_철도!C4 -> 0.4 | AB79: =d_철도!D4 -> 0.06
B80: =d_철도!A5 -> 낙강물길공원 | N80: =d_철도!B5 -> 2.37 | U80: =d_철도!C5 -> 0 | AB80: =d_철도!D5 -> 0
...

Sheet 설문조사
B2: 설문조사
B3: 방문객이 직접 말한 불편과 의향
B4: 팀 온라인 설문 103명(방문 경험 72명, 2026.9.23~24). 응답자 범위와 이동수단을 바꿔 본다. 불편은 근거로 읽고, 의향은 참여율로 쓰지 않는다.
B6: 화면 | E6: 한눈에 | J6: 시·군 진단 | O6: 운영 시간 | T6: 버스 | Y6: 월영교 | AD6: 설문조사
B8: 응답자 범위 ▼ | J8: 이동수단 ▼
B9: 방문자만 | J9: 전체 | R9: ="고른 응답자 "&d_설문계산!$B$3&"명" -> 고른 응답자 72명
B11: 시내버스 이용자 중 "불편했다" | K11: 이동이 불편해 야간 명소(월영교) 포기 | T11: 20시 이후 월영교 식당·편의시설 부족 | AC11: 당일 귀가자 중 20~22시(막차) 귀가
B12: =IFERROR(COUNTIFS(d_설문!$A$2:$A$104,d_설문계산!$B$1,d_설문!$B$2:$B$104,d_설문계산!$B$2,d_설문!$C$2:$C$104,1,d_설문!$D$2:$D$104,"불편했다")/COUNTIFS(d_설문!$A$2:$A$104,d_설문계산!$B$1,d_설문!$B$2:$B$104,d_설문계산!$B$2,d_설문!$C$2:$C$104,1),"해당 없음") -> 0.73333333 | K12: =IFERROR(COUNTIFS(d_설문!$A$2:$A$104,d_설문계산!$B$1,d_설문!$B$2:$B$104,d_설문계산!$B$2,d_설문!$I$2:$I$104,1,d_설문!$F$2:$F$104,1)/COUNTIFS(d_설문!$A$2:$A$104,d_설문계산!$B$1,d_설문!$B$2:$B$104,d_설문계산!$B$2,d_설문!$I$2:$I$104,1),"해당 없음") -> 0.46478873 | T12: =IFERROR(COUNTIFS(d_설문!$A$2:$A$104,d_설문계산!$B$1,d_설문!$B$2:$B$104,d_설문계산!$B$2,d_설문!$J$2:$J$104,"부족")/COUNTIFS(d_설문!$A$2:$A$104,d_설문계산!$B$1,d_설문!$B$2:$B$104,d_설문계산!$B$2,d_설문!$J$2:$J$104,"<>미응답"),"해당 없음") -> 0.52777778 | AC12: =IFERROR(COUNTIFS(d_설문!$A$2:$A$104,d_설문계산!$B$1,d_설문!$B$2:$B$104,d_설문계산!$B$2,d_설문!$L$2:$L$104,"20-22시(막차)")/COUNTIFS(d_설문!$A$2:$A$104,d_설문계산!$B$1,d_설문!$B$2:$B$104,d_설문계산!$B$2,d_설문!$L$2:$L$104,"<>미응답",d_설문!$L$2:$L$104,"<>숙박"),"해당 없음") -> 0.575
B13: ="주 이동수단이 시내버스인 사람 중 "&COUNTIFS(d_설문!$A$2:$A$104,d_설문계산!$B$1,d_설문!$B$2:$B$104,d_설문계산!$B$2,d_설문!$C$2:$C$104,1,d_설문!$D$2:$D$104,"불편했다")&"명 / "&COUNTIFS(d_설문!$A$2:$A$104,d_설문계산!$B$1,d_설문!$B$2:$B$104,d_설문계산!$B$2,d_설문!$C$2:$C$104,1)&"명" -> 주 이동수단이 시내버스인 사람 중 22명 / 30명 | K13: ="포기한 곳 문항 응답자 중 "&COUNTIFS(d_설문!$A$2:$A$104,d_설문계산!$B$1,d_설문!$B$2:$B$104,d_설문계산!$B$2,d_설문!$I$2:$I$104,1,d_설문!$F$2:$F$104,1)&"명 / "&COUNTIFS(d_설문!$A$2:$A$104,d_설문계산!$B$1,d_설문!$B$2:$B$104,d_설문계산!$B$2,d_설문!$I$2:$I$104,1)&"명" -> 포기한 곳 문항 응답자 중 33명 / 71명 | T13: ="부족·매우 부족 "&COUNTIFS(d_설문!$A$2:$A$104,d_설문계산!$B$1,d_설문!$B$2:$B$104,d_설문계산!$B$2,d_설문!$J$2:$J$104,"부족")&"명 / "&COUNTIFS(d_설문!$A$2:$A$104,d_설문계산!$B$1,d_설문!$B$2:$B$104,d_설문계산!$B$2,d_설문!$J$2:$J$104,"<>미응답")&"명" -> 부족·매우 부족 38명 / 72명 | AC13: ="숙박자 제외 "&COUNTIFS(d_설문!$A$2:$A$104,d_설문계산!$B$1,d_설문!$B$2:$B$104,d_설문계산!$B$2,d_설문!$L$2:$L$104,"20-22시(막차)")&"명 / "&COUNTIFS(d_설문!$A$2:$A$104,d_설문계산!$B$1,d_설문!$B$2:$B$104,d_설문계산!$B$2,d_설문!$L$2:$L$104,"<>미응답",d_설문!$L$2:$L$104,"<>숙박")&"명" -> 숙박자 제외 23명 / 40명
B15: 출처 팀 온라인 설문(구글폼, 2026.9.23~24, 응답 103명·방문 경험 72명, 편의 표본)
B17: 이용 의향 (5점) 고른 응답자 중 비율. 의향은 참여율이 아니다 | U17: ■ 매우 있다 ■ 있다 ■ 보통 ■ 별로 없다 ■ 전혀 없다
B27: 출처 팀 온라인 설문 6·8·10·12번 문항(5점 척도), 2026.9.23~24, 응답 103명
B29: 이동이 불편해 포기한 곳 중복 선택 | U29: 유료 체험을 망설인 가장 큰 이유 가격보다 정보·예약·시간
B38: 출처 팀 온라인 설문 4번(중복 선택)·11번 문항, 2026.9.23~24
B40: 설문 응답한 방문자 중 차 없는 사람이 46%로 실제(철도공사 추정 철도+버스 10.5%)보다 많다. 10.5 : 89.5로 다시 가중하면 긍정(있다+매우 있다)은 체험 쿠폰 76% · 셔틀 70% · 팝업 76% · 축제 혜택 78%.
B42: 의향 5점 분포 표로 보기 ▼ 고른 응답자 중 비율. 왼쪽 여백의 [+] 를 누르면 펼쳐진다
B43: 문항 | M43: 매우 있다 | R43: 있다 | W43: 보통 | AB43: 별로 없다 | AG43: 전혀 없다
B44: =d_설문계산!D2 -> 체험 쿠폰(영수증 인증) | M44: =d_설문계산!E2 -> 0.54166667 | R44: =d_설문계산!F2 -> 0.25 | W44: =d_설문계산!G2 -> 0.125 | AB44: =d_설문계산!H2 -> 0.069444444 | AG44: =d_설문계산!I2 -> 0.013888889
B45: =d_설문계산!D3 -> 야간 택시·셔틀(18:30~21:00) | M45: =d_설문계산!E3 -> 0.47222222 | R45: =d_설문계산!F3 -> 0.31944444 | W45: =d_설문계산!G3 -> 0.055555556 | AB45: =d_설문계산!H3 -> 0.15277778 | AG45: =d_설문계산!I3 -> 0
B46: =d_설문계산!D4 -> 월영교 야간 팝업(21~23시) | M46: =d_설문계산!E4 -> 0.48611111 | R46: =d_설문계산!F4 -> 0.33333333 | W46: =d_설문계산!G4 -> 0.125 | AB46: =d_설문계산!H4 -> 0.041666667 | AG46: =d_설문계산!I4 -> 0.013888889
B47: =d_설문계산!D5 -> 축제 혜택(영수증) | M47: =d_설문계산!E5 -> 0.4 | R47: =d_설문계산!F5 -> 0.42857143 | W47: =d_설문계산!G5 -> 0.15714286 | AB47: =d_설문계산!H5 -> 0 | AG47: =d_설문계산!I5 -> 0.014285714
B49: 포기한 곳 · 망설인 이유 표로 보기 ▼ 고른 응답자 중 비율. 왼쪽 여백의 [+] 를 누르면 펼쳐진다
B50: 포기한 곳 | M50: 비율 | U50: 망설인 이유 | AF50: 비율
B51: =IF(d_설문계산!K2="","",d_설문계산!K2) -> 외곽 관광지(하회·도산) | M51: =IF(d_설문계산!K2="","",d_설문계산!L2) -> 0.4084507 | U51: =d_설문계산!N2 -> 정보 부족 | AF51: =d_설문계산!O2 -> 0.40277778
B52: =IF(d_설문계산!K3="","",d_설문계산!K3) -> 야간 명소(월영교) | M52: =IF(d_설문계산!K3="","",d_설문계산!L3) -> 0.46478873 | U52: =d_설문계산!N3 -> 줄·예약 불편 | AF52: =d_설문계산!O3 -> 0.30555556
B53: =IF(d_설문계산!K4="","",d_설문계산!K4) -> 원도심 밤 가게·식당 | M53: =IF(d_설문계산!K4="","",d_설문계산!L4) -> 0.25352113 | U53: =d_설문계산!N4 -> 이동 시간 부족 | AF53: =d_설문계산!O4 -> 0.125
B54: =IF(d_설문계산!K5="","",d_설문계산!K5) -> 없음(모두 방문) | M54: =IF(d_설문계산!K5="","",d_설문계산!L5) -> 0.21126761 | U54: =d_설문계산!N5 -> 가격 부담 | AF54: =d_설문계산!O5 -> 0.15277778
B55: =IF(d_설문계산!K6="","",d_설문계산!K6) | M55: =IF(d_설문계산!K6="","",d_설문계산!L6) | U55: =d_설문계산!N6 -> 기타 | AF55: =d_설문계산!O6 -> 0.013888889
B57: 데이터 설명 ▼ 계산 방법·기간·출처. 왼쪽 여백의 [+] 를 누르면 펼쳐지고 [−] 를 누르면 접힌다
B58: 읽는 법 | I58: "불편했다·부족했다·막차에 귀가"는 방문 경험이라 기존 데이터(112번 막차 18:45, 월영교 1km 주점 0곳, 안동역 막차 21~22시)를 뒷받침하는 근거로 쓴다
B59: 의향 | I59: "이용하겠다"는 의향이라 참여율로 바로 쓰지 않는다. 기대효과 모의실험에서는 체험 결제율과 저녁 이동 배수 두 곳에만 실현율(0.33~0.40)로 보정해 쓴다
B60: 가격 | I60: 가격 때문에 망설인다는 응답은 14%뿐이라 1단계 혜택은 할인 폭(10%)보다 체험 정보·예약·동선을 잇는 데 무게를 둔다
B61: 출처 | I61: 팀 온라인 설문(구글폼, 2026-09-23~24, 응답 103명, 편의 표본, 인구통계·개인정보 문항 없음). 정제 scripts/설문_정제.py · 집계 scripts/설문_분석.py

Sheet 출처
B2: 출처
B3: 대시보드에 쓴 자료
B4: 대시보드 숫자는 아래 자료로 계산했다. 계산 스크립트는 공개 저장소 scripts/ 폴더에 있다.
B6: 자료 | C6: 기관 | D6: 기간 | E6: 쓴 화면
B7: 외지인 방문 연인원 (BDT_01_01_006) | C7: 한국관광 데이터랩 | D7: 2024·2026년 1~8월 | E7: 한눈에, 시·군 진단
B8: 외지인 신용카드 소비, 업종 중분류 (BDT_02_01_003) | C8: 한국관광 데이터랩 | D8: 2024·2026년 1~8월 | E8: 한눈에, 시·군 진단
B9: 평균 숙박일수 (LN_02_01_013) | C9: 한국관광 데이터랩 | D9: 2025년 | E9: 시·군 진단
B10: 시간대별 방문(저녁 전환율, 야간 방문 비중) | C10: 한국관광 데이터랩 | D10: 2026년 1~8월 | E10: 시·군 진단
B11: 전국 진단표 144개 시·군 (scripts/전국진단표.py) | C11: 팀 분석 | D11: 2026.9.23 | E11: 한눈에, 시·군 진단
B12: 안동역 월별·요일별·시간대별 승하차 (KTX-이음·새마을·무궁화) | C12: 코레일 (팀원 취합) | D12: 2024.1~2026.8 | E12: 운영 시간
B13: 시내버스 시간표·노선·정류장 (46개 노선, 3,309개 정류장) | C13: 안동시 버스정보시스템 | D13: 2026.9.22 조회 | E13: 한눈에, 버스
B14: 112번 노선 선형·정류장 | C14: 안동시 버스정보시스템 | D14: 2026.9.29 수집 | E14: 버스
B15: 지도 배경 | C15: OpenStreetMap contributors (ODbL) · OpenFreeMap | D15: 2026.9.13 | E15: 버스
B16: 행정동 경계 | C16: 통계청 SGIS (vuski/admdongkor) | D16: 2026.7 | E16: 버스
B17: 디지털관광주민증 혜택업체·이용 실적 | C17: 안동시 (정보공개청구) | D17: 2024.6~2026.8 | E17: 한눈에
... B22: 이어드림 기대효과 모의실험 1만 번 (scripts/이어드림_시뮬레이션.py) | C22: 팀 분석 | D22: 2026.9 | E22: 한눈에
B24: · 한국철도공사 자료는 소비를 건수로 세어 데이터랩 숫자와 한 표에 올리지 않는다.
B25: · 설문 의향 %는 참여율이 아니다. 기대효과 계산에는 실현율 0.33~0.40으로 보정한 값만 쓴다.
B26: · 모든 효과는 시행 전 예측(모의실험 1만 번의 가운데 값)이며 시행 첫 달 기록으로 다시 계산한다.
B27: · 화면마다 숫자 오른쪽 위 빨간 삼각형(메모)과 「데이터 설명」에 계산 방법이 있다.

Sheet d_진단
A1: 시군 | B1: 체험 | C1: 숙박 | D1: 저녁 | E1: 야간 | F1: 문제① | G1: 문제② | H1: 문제③ | I1: 문제④ | J1: 점수 | K1: 순위 | L1: 유형 | M1: 정렬키
A2: 기장군 | B2: -0.17069615 | C2: 3.0458333 | D2: 0.45403383 | E2: 0.072846042 | F2: =100*(1-(COUNTIF($B$2:$B$145,"<"&B2)+1)/COUNT($B$2:$B$145)) -> 85.416667 | G2: =100*(1-(COUNTIF($C$2:$C$145,"<"&C2)+1)/COUNT($C$2:$C$145)) -> 86.805556 | H2: =100*(1-(COUNTIF($D$2:$D$145,"<"&D2)+1)/COUNT($D$2:$D$145)) -> 85.416667 | I2: =100*(1-(COUNTIF($E$2:$E$145,"<"&E2)+1)/COUNT($E$2:$E$145)) -> 94.444444 | J2: =IF(('시·군 진단'!$K$9+'시·군 진단'!$R$9+'시·군 진단'!$Y$9+'시·군 진단'!$AF$9)<=0,AVERAGE(F2:I2),(F2*'시·군 진단'!$K$9+G2*'시·군 진단'!$R$9+H2*'시·군 진단'!$Y$9+I2*'시·군 진단'!$AF$9)/('시·군 진단'!$K$9+'시·군 진단'!$R$9+'시·군 진단'!$Y$9+'시·군 진단'!$AF$9)) -> 88.020833 | K2: =RANK(J2,$J$2:$J$145,0) -> 1 | L2: =SUBSTITUTE(TRIM(IF(F2>=75,"체험·문화 ","")&IF(G2>=75,"숙박일수 ","")&IF(H2>=75,"저녁전환 ","")&IF(I2>=75,"야간방문",""))," "," · ") -> 체험·문화 · 숙박일수 · 저녁전환 · 야간방문 | M2: =J2-ROW()/10000000 -> 88.020833
A3: 진안군 | B3: -0.41449101 | C3: 3.4691667 | D3: 0.41782422 | E3: 0.07421261 | F3: =100*(1-(COUNTIF($B$2:$B$145,"<"&B3)+1)/COUNT($B$2:$B$145)) -> 97.916667 | G3: =100*(1-(COUNTIF($C$2:$C$145,"<"&C3)+1)/COUNT($C$2:$C$145)) -> 63.194444 | H3: =100*(1-(COUNTIF($D$2:$D$145,"<"&D3)+1)/COUNT($D$2:$D$145)) -> 94.444444 | I3: =100*(1-(COUNTIF($E$2:$E$145,"<"&E3)+1)/COUNT($E$2:$E$145)) -> 91.666667 | J3: =IF(('시·군 진단'!$K$9+'시·군 진단'!$R$9+'시·군 진단'!$Y$9+'시·군 진단'!$AF$9)<=0,AVERAGE(F3:I3),(F3*'시·군 진단'!$K$9+G3*'시·군 진단'!$R$9+H3*'시·군 진단'!$Y$9+I3*'시·군 진단'!$AF$9)/('시·군 진단'!$K$9+'시·군 진단'!$R$9+'시·군 진단'!$Y$9+'시·군 진단'!$AF$9)) -> 86.805556 | K3: =RANK(J3,$J$2:$J$145,0) -> 2 | L3: =SUBSTITUTE(TRIM(IF(F3>=75,"체험·문화 ","")&IF(G3>=75,"숙박일수 ","")&IF(H3>=75,"저녁전환 ","")&IF(I3>=75,"야간방문",""))," "," · ") -> 체험·문화 · 저녁전환 · 야간방문 | M3: =J3-ROW()/10000000 -> 86.805555
A4: 청도군 | B4: -0.23040739 | C4: 3.4225 | D4: 0.44780312 | E4: 0.082486299 | F4: =100*(1-(COUNTIF($B$2:$B$145,"<"&B4)+1)/COUNT($B$2:$B$145)) -> 90.277778 | G4: =100*(1-(COUNTIF($C$2:$C$145,"<"&C4)+1)/COUNT($C$2:$C$145)) -> 64.583333 | H4: =100*(1-(COUNTIF($D$2:$D$145,"<"&D4)+1)/COUNT($D$2:$D$145)) -> 86.805556 | I4: =100*(1-(COUNTIF($E$2:$E$145,"<"&E4)+1)/COUNT($E$2:$E$145)) -> 75.694444 | J4: =IF(('시·군 진단'!$K$9+'시·군 진단'!$R$9+'시·군 진단'!$Y$9+'시·군 진단'!$AF$9)<=0,AVERAGE(F4:I4),(F4*'시·군 진단'!$K$9+G4*'시·군 진단'!$R$9+H4*'시·군 진단'!$Y$9+I4*'시·군 진단'!$AF$9)/('시·군 진단'!$K$9+'시·군 진단'!$R$9+'시·군 진단'!$Y$9+'시·군 진단'!$AF$9)) -> 79.340278 | K4: =RANK(J4,$J$2:$J$145,0) -> 3 | L4: =SUBSTITUTE(TRIM(IF(F4>=75,"체험·문화 ","")&IF(G4>=75,"숙박일수 ","")&IF(H4>=75,"저녁전환 ","")&IF(I4>=75,"야간방문",""))," "," · ") -> 체험·문화 · 저녁전환 · 야간방문 | M4: =J4-ROW()/10000000 -> 79.340277
A5: 합천군 | B5: -0.085887649 | C5: 3.2658333 | D5: 0.44271466 | E5: 0.077971584 | F5: =100*(1-(COUNTIF($B$2:$B$145,"<"&B5)+1)/COUNT($B$2:$B$145)) -> 68.055556 | G5: =100*(1-(COUNTIF($C$2:$C$145,"<"&C5)+1)/COUNT($C$2:$C$145)) -> 74.305556 | H5: =100*(1-(COUNTIF($D$2:$D$145,"<"&D5)+1)/COUNT($D$2:$D$145)) -> 88.888889 | I5: =100*(1-(COUNTIF($E$2:$E$145,"<"&E5)+1)/COUNT($E$2:$E$145)) -> 83.333333 | J5: =IF(('시·군 진단'!$K$9+'시·군 진단'!$R$9+'시·군 진단'!$Y$9+'시·군 진단'!$AF$9)<=0,AVERAGE(F5:I5),(F5*'시·군 진단'!$K$9+G5*'시·군 진단'!$R$9+H5*'시·군 진단'!$Y$9+I5*'시·군 진단'!$AF$9)/('시·군 진단'!$K$9+'시·군 진단'!$R$9+'시·군 진단'!$Y$9+'시·군 진단'!$AF$9)) -> 78.645833 | K5: =RANK(J5,$J$2:$J$145,0) -> 4 | L5: =SUBSTITUTE(TRIM(IF(F5>=75,"체험·문화 ","")&IF(G5>=75,"숙박일수 ","")&IF(H5>=75,"저녁전환 ","")&IF(I5>=75,"야간방문",""))," "," · ") -> 저녁전환 · 야간방문 | M5: =J5-ROW()/10000000 -> 78.645833
A6: 화순군 | B6: -0.12739607 | C6: 3.5483333 | D6: 0.44088923 | E6: 0.075350065 | F6: =100*(1-(COUNTIF($B$2:$B$145,"<"&B6)+1)/COUNT($B$2:$B$145)) -> 77.777778 | G6: =100*(1-(COUNTIF($C$2:$C$145,"<"&C6)+1)/COUNT($C$2:$C$145)) -> 50.694444 | H6: =100*(1-(COUNTIF($D$2:$D$145,"<"&D6)+1)/COUNT($D$2:$D$145)) -> 90.277778 | I6: =100*(1-(COUNTIF($E$2:$E$145,"<"&E6)+1)/COUNT($E$2:$E$145)) -> 88.888889 | J6: =IF(('시·군 진단'!$K$9+'시·군 진단'!$R$9+'시·군 진단'!$Y$9+'시·군 진단'!$AF$9)<=0,AVERAGE(F6:I6),(F6*'시·군 진단'!$K$9+G6*'시·군 진단'!$R$9+H6*'시·군 진단'!$Y$9+I6*'시·군 진단'!$AF$9)/('시·군 진단'!$K$9+'시·군 진단'!$R$9+'시·군 진단'!$Y$9+'시·군 진단'!$AF$9)) -> 76.909722 | K6: =RANK(J6,$J$2:$J$145,0) -> 5 | L6: =SUBSTITUTE(TRIM(IF(F6>=75,"체험·문화 ","")&IF(G6>=75,"숙박일수 ","")&IF(H6>=75,"저녁전환 ","")&IF(I6>=75,"야간방문",""))," "," · ") -> 체험·문화 · 저녁전환 · 야간방문 | M6: =J6-ROW()/10000000 -> 76.909722
A7: 완주군 | B7: -0.34887626 | C7: 3.6625 | D7: 0.47268543 | E7: 0.073504909 | F7: =100*(1-(COUNTIF($B$2:$B$145,"<"&B7)+1)/COUNT($B$2:$B$145)) -> 95.833333 | G7: =100*(1-(COUNTIF($C$2:$C$145,"<"&C7)+1)/COUNT($C$2:$C$145)) -> 29.166667 | H7: =100*(1-(COUNTIF($D$2:$D$145,"<"&D7)+1)/COUNT($D$2:$D$145)) -> 79.166667 | I7: =100*(1-(COUNTIF($E$2:$E$145,"<"&E7)+1)/COUNT($E$2:$E$145)) -> 93.75 | J7: =IF(('시·군 진단'!$K$9+'시·군 진단'!$R$9+'시·군 진단'!$Y$9+'시·군 진단'!$AF$9)<=0,AVERAGE(F7:I7),(F7*'시·군 진단'!$K$9+G7*'시·군 진단'!$R$9+H7*'시·군 진단'!$Y$9+I7*'시·군 진단'!$AF$9)/('시·군 진단'!$K$9+'시·군 진단'!$R$9+'시·군 진단'!$Y$9+'시·군 진단'!$AF$9)) -> 74.479167 | K7: =RANK(J7,$J$2:$J$145,0) -> 6 | L7: =SUBSTITUTE(TRIM(IF(F7>=75,"체험·문화 ","")&IF(G7>=75,"숙박일수 ","")&IF(H7>=75,"저녁전환 ","")&IF(I7>=75,"야간방문",""))," "," · ") -> 체험·문화 · 저녁전환 · 야간방문 | M7: =J7-ROW()/10000000 -> 74.479166
A8: 인제군 | B8: -0.38094579 | C8: 3.5741667 | D8: 0.47111241 | E8: 0.080605051 | F8: =100*(1-(COUNTIF($B$2:$B$145,"<"&B8)+1)/COUNT($B$2:$B$145)) -> 96.527778 | G8: =100*(1-(COUNTIF($C$2:$C$145,"<"&C8)+1)/COUNT($C$2:$C$145)) -> 42.361111 | H8: =100*(1-(COUNTIF($D$2:$D$145,"<"&D8)+1)/COUNT($D$2:$D$145)) -> 79.861111 | I8: =100*(1-(COUNTIF($E$2:$E$145,"<"&E8)+1)/COUNT($E$2:$E$145)) -> 78.472222 | J8: =IF(('시·군 진단'!$K$9+'시·군 진단'!$R$9+'시·군 진단'!$Y$9+'시·군 진단'!$AF$9)<=0,AVERAGE(F8:I8),(F8*'시·군 진단'!$K$9+G8*'시·군 진단'!$R$9+H8*'시·군 진단'!$Y$9+I8*'시·군 진단'!$AF$9)/('시·군 진단'!$K$9+'시·군 진단'!$R$9+'시·군 진단'!$Y$9+'시·군 진단'!$AF$9)) -> 74.305556 | K8: =RANK(J8,$J$2:$J$145,0) -> 7 | L8: =SUBSTITUTE(TRIM(IF(F8>=75,"체험·문화 ","")&IF(G8>=75,"숙박일수 ","")&IF(H8>=75,"저녁전환 ","")&IF(I8>=75,"야간방문",""))," "," · ") -> 체험·문화 · 저녁전환 · 야간방문 | M8: =J8-ROW()/10000000 -> 74.305555
A9: 순창군 | B9: -0.11446925 | C9: 3.5775 | D9: 0.41214914 | E9: 0.077426707 | F9: =100*(1-(COUNTIF($B$2:$B$145,"<"&B9)+1)/COUNT($B$2:$B$145)) -> 72.916667 | G9: =100*(1-(COUNTIF($C$2:$C$145,"<"&C9)+1)/COUNT($C$2:$C$145)) -> 41.666667 | H9: =100*(1-(COUNTIF($D$2:$D$145,"<"&D9)+1)/COUNT($D$2:$D$145)) -> 95.833333 | I9: =100*(1-(COUNTIF($E$2:$E$145,"<"&E9)+1)/COUNT($E$2:$E$145)) -> 84.027778 | J9: =IF(('시·군 진단'!$K$9+'시·군 진단'!$R$9+'시·군 진단'!$Y$9+'시·군 진단'!$AF$9)<=0,AVERAGE(F9:I9),(F9*'시·군 진단'!$K$9+G9*'시·군 진단'!$R$9+H9*'시·군 진단'!$Y$9+I9*'시·군 진단'!$AF$9)/('시·군 진단'!$K$9+'시·군 진단'!$R$9+'시·군 진단'!$Y$9+'시·군 진단'!$AF$9)) -> 73.611111 | K9: =RANK(J9,$J$2:$J$145,0) -> 8 | L9: =SUBSTITUTE(TRIM(IF(F9>=75,"체험·문화 ","")&IF(G9>=75,"숙박일수 ","")&IF(H9>=75,"저녁전환 ","")&IF(I9>=75,"야간방문",""))," "," · ") -> 저녁전환 · 야간방문 | M9: =J9-ROW()/10000000 -> 73.61111
A10: 담양군 | B10: 0.12572713 | C10: 3.3641667 | D10: 0.39403789 | E10: 0.058294063 | F10: =100*(1-(COUNTIF($B$2:$B$145,"<"&B10)+1)/COUNT($B$2:$B$145)) -> 24.305556 | G10: =100*(1-(COUNTIF($C$2:$C$145,"<"&C10)+1)/COUNT($C$2:$C$145)) -> 68.055556 | H10: =100*(1-(COUNTIF($D$2:$D$145,"<"&D10)+1)/COUNT($D$2:$D$145)) -> 98.611111 | I10: =100*(1-(COUNTIF($E$2:$E$145,"<"&E10)+1)/COUNT($E$2:$E$145)) -> 99.305556 | J10: =IF(('시·군 진단'!$K$9+'시·군 진단'!$R$9+'시·군 진단'!$Y$9+'시·군 진단'!$AF$9)<=0,AVERAGE(F10:I10),(F10*'시·군 진단'!$K$9+G10*'시·군 진단'!$R$9+H10*'시·군 진단'!$Y$9+I10*'시·군 진단'!$AF$9)/('시·군 진단'!$K$9+'시·군 진단'!$R$9+'시·군 진단'!$Y$9+'시·군 진단'!$AF$9)) -> 72.569444 | K10: =RANK(J10,$J$2:$J$145,0) -> 9 | L10: =SUBSTITUTE(TRIM(IF(F10>=75,"체험·문화 ","")&IF(G10>=75,"숙박일수 ","")&IF(H10>=75,"저녁전환 ","")&IF(I10>=75,"야간방문",""))," "," · ") -> 저녁전환 · 야간방문 | M10: =J10-ROW()/10000000 -> 72.569443
A11: 금산군 | B11: -0.11595326 | C11: 3.5333333 | D11: 0.45763084 | E11: 0.082358632 | F11: =100*(1-(COUNTIF($B$2:$B$145,"<"&B11)+1)/COUNT($B$2:$B$145)) -> 73.611111 | G11: =100*(1-(COUNTIF($C$2:$C$145,"<"&C11)+1)/COUNT($C$2:$C$145)) -> 52.777778 | H11: =100*(1-(COUNTIF($D$2:$D$145,"<"&D11)+1)/COUNT($D$2:$D$145)) -> 83.333333 | I11: =100*(1-(COUNTIF($E$2:$E$145,"<"&E11)+1)/COUNT($E$2:$E$145)) -> 76.388889 | J11: =IF(('시·군 진단'!$K$9+'시·군 진단'!$R$9+'시·군 진단'!$Y$9+'시·군 진단'!$AF$9)<=0,AVERAGE(F11:I11),(F11*'시·군 진단'!$K$9+G11*'시·군 진단'!$R$9+H11*'시·군 진단'!$Y$9+I11*'시·군 진단'!$AF$9)/('시·군 진단'!$K$9+'시·군 진단'!$R$9+'시·군 진단'!$Y$9+'시·군 진단'!$AF$9)) -> 71.527778 | K11: =RANK(J11,$J$2:$J$145,0) -> 10 | L11: =SUBSTITUTE(TRIM(IF(F11>=75,"체험·문화 ","")&IF(G11>=75,"숙박일수 ","")&IF(H11>=75,"저녁전환 ","")&IF(I11>=75,"야간방문",""))," "," · ") -> 저녁전환 · 야간방문 | M11: =J11-ROW()/10000000 -> 71.527777
A12: 횡성군 | B12: -0.15570733 | C12: 3.4725 | D12: 0.48819521 | E12: 0.085771007 | F12: =100*(1-(COUNTIF($B$2:$B$145,"<"&B12)+1)/COUNT($B$2:$B$145)) -> 82.638889 | G12: =100*(1-(COUNTIF($C$2:$C$145,"<"&C12)+1)/COUNT($C$2:$C$145)) -> 61.805556 | H12: =100*(1-(COUNTIF($D$2:$D$145,"<"&D12)+1)/COUNT($D$2:$D$145)) -> 70.833333 | I12: =100*(1-(COUNTIF($E$2:$E$145,"<"&E12)+1)/COUNT($E$2:$E$145)) -> 68.055556 | J12: =IF(('시·군 진단'!$K$9+'시·군 진단'!$R$9+'시·군 진단'!$Y$9+'시·군 진단'!$AF$9)<=0,AVERAGE(F12:I12),(F12*'시·군 진단'!$K$9+G12*'시·군 진단'!$R$9+H12*'시·군 진단'!$Y$9+I12*'시·군 진단'!$AF$9)/('시·군 진단'!$K$9+'시·군 진단'!$R$9+'시·군 진단'!$Y$9+'시·군 진단'!$AF$9)) -> 70.833333 | K12: =RANK(J12,$J$2:$J$145,0) -> 11 | L12: =SUBSTITUTE(TRIM(IF(F12>=75,"체험·문화 ","")&IF(G12>=75,"숙박일수 ","")&IF(H12>=75,"저녁전환 ","")&IF(I12>=75,"야간방문",""))," "," · ") -> 체험·문화 | M12: =J12-ROW()/10000000 -> 70.833332
A13: 단양군 | B13: -0.09673635 | C13: 2.7383333 | D13: 0.48144055 | E13: 0.095163112 | F13: =100*(1-(COUNTIF($B$2:$B$145,"<"&B13)+1)/COUNT($B$2:$B$145)) -> 70.138889 | G13: =100*(1-(COUNTIF($C$2:$C$145,"<"&C13)+1)/COUNT($C$2:$C$145)) -> 94.444444 | H13: =100*(1-(COUNTIF($D$2:$D$145,"<"&D13)+1)/COUNT($D$2:$D$145)) -> 74.305556 | I13: =100*(1-(COUNTIF($E$2:$E$145,"<"&E13)+1)/COUNT($E$2:$E$145)) -> 44.444444 | J13: =IF(('시·군 진단'!$K$9+'시·군 진단'!$R$9+'시·군 진단'!$Y$9+'시·군 진단'!$AF$9)<=0,AVERAGE(F13:I13),(F13*'시·군 진단'!$K$9+G13*'시·군 진단'!$R$9+H13*'시·군 진단'!$Y$9+I13*'시·군 진단'!$AF$9)/('시·군 진단'!$K$9+'시·군 진단'!$R$9+'시·군 진단'!$Y$9+'시·군 진단'!$AF$9)) -> 70.833333 | K13: =RANK(J13,$J$2:$J$145,0) -> 11 | L13: =SUBSTITUTE(TRIM(IF(F13>=75,"체험·문화 ","")&IF(G13>=75,"숙박일수 ","")&IF(H13>=75,"저녁전환 ","")&IF(I13>=75,"야간방문",""))," "," · ") -> 숙박일수 | M13: =J13-ROW()/10000000 -> 70.833332
... A145: 영양군 | B145: 0.65902343 | C145: 4.0816667 | D145: 0.53106367 | E145: 0.1150527 | F145: =100*(1-(COUNTIF($B$2:$B$145,"<"&B145)+1)/COUNT($B$2:$B$145)) -> 4.1666667 | G145: =100*(1-(COUNTIF($C$2:$C$145,"<"&C145)+1)/COUNT($C$2:$C$145)) -> 2.7777778 | H145: =100*(1-(COUNTIF($D$2:$D$145,"<"&D145)+1)/COUNT($D$2:$D$145)) -> 43.055556 | I145: =100*(1-(COUNTIF($E$2:$E$145,"<"&E145)+1)/COUNT($E$2:$E$145)) -> 10.416667 | J145: =IF(('시·군 진단'!$K$9+'시·군 진단'!$R$9+'시·군 진단'!$Y$9+'시·군 진단'!$AF$9)<=0,AVERAGE(F145:I145),(F145*'시·군 진단'!$K$9+G145*'시·군 진단'!$R$9+H145*'시·군 진단'!$Y$9+I145*'시·군 진단'!$AF$9)/('시·군 진단'!$K$9+'시·군 진단'!$R$9+'시·군 진단'!$Y$9+'시·군 진단'!$AF$9)) -> 15.104167 | K145: =RANK(J145,$J$2:$J$145,0) -> 144 | L145: =SUBSTITUTE(TRIM(IF(F145>=75,"체험·문화 ","")&IF(G145>=75,"숙박일수 ","")&IF(H145>=75,"저녁전환 ","")&IF(I145>=75,"야간방문",""))," "," · ") | M145: =J145-ROW()/10000000 -> 15.104152

Sheet d_목록
A1: 시군
A2: 가평군
A3: 강릉시
A4: 강진군
A5: 강화군
A6: 거제시
A7: 거창군
A8: 경산시
A9: 경주시
A10: 계룡시
A11: 고령군
A12: 고창군
... A145: 횡성군

Sheet d_진단비교
A1: 지표 | B1: 고른 시·군 | C1: 안동
A2: 체험·문화 | B2: =INDEX(d_진단!$F$2:$F$145,MATCH('시·군 진단'!$B$9,d_진단!$A$2:$A$145,0)) -> 84.722222 | C2: =INDEX(d_진단!$F$2:$F$145,MATCH("안동시",d_진단!$A$2:$A$145,0)) -> 84.722222
A3: 숙박일수 | B3: =INDEX(d_진단!$G$2:$G$145,MATCH('시·군 진단'!$B$9,d_진단!$A$2:$A$145,0)) -> 82.638889 | C3: =INDEX(d_진단!$G$2:$G$145,MATCH("안동시",d_진단!$A$2:$A$145,0)) -> 82.638889
A4: 저녁 전환 | B4: =INDEX(d_진단!$H$2:$H$145,MATCH('시·군 진단'!$B$9,d_진단!$A$2:$A$145,0)) -> 25.694444 | C4: =INDEX(d_진단!$H$2:$H$145,MATCH("안동시",d_진단!$A$2:$A$145,0)) -> 25.694444
A5: 야간 방문 | B5: =INDEX(d_진단!$I$2:$I$145,MATCH('시·군 진단'!$B$9,d_진단!$A$2:$A$145,0)) -> 22.916667 | C5: =INDEX(d_진단!$I$2:$I$145,MATCH("안동시",d_진단!$A$2:$A$145,0)) -> 22.916667
A7: 점 | B7: x | C7: y
A8: 고른 | B8: =INDEX(d_진단!$B$2:$B$145,MATCH('시·군 진단'!$B$9,d_진단!$A$2:$A$145,0)) -> -0.16790571 | C8: =INDEX(d_진단!$C$2:$C$145,MATCH('시·군 진단'!$B$9,d_진단!$A$2:$A$145,0)) -> 3.0658333
A9: 안동 | B9: =INDEX(d_진단!$B$2:$B$145,MATCH("안동시",d_진단!$A$2:$A$145,0)) -> -0.16790571 | C9: =INDEX(d_진단!$C$2:$C$145,MATCH("안동시",d_진단!$A$2:$A$145,0)) -> 3.0658333

Sheet d_역
A1: 키 | B1: 인원
A2: 2024|공휴일|KTX-이음|승차|00-01 | B2: 0
A3: 2024|공휴일|KTX-이음|승차|01-02 | B3: 0
A4: 2024|공휴일|KTX-이음|승차|02-03 | B4: 0
A5: 2024|공휴일|KTX-이음|승차|03-04 | B5: 0
A6: 2024|공휴일|KTX-이음|승차|04-05 | B6: 0
A7: 2024|공휴일|KTX-이음|승차|05-06 | B7: 529
A8: 2024|공휴일|KTX-이음|승차|06-07 | B8: 0
A9: 2024|공휴일|KTX-이음|승차|07-08 | B9: 0
A10: 2024|공휴일|KTX-이음|승차|08-09 | B10: 884
A11: 2024|공휴일|KTX-이음|승차|09-10 | B11: 0
A12: 2024|공휴일|KTX-이음|승차|10-11 | B12: 1045
A13: 2024|공휴일|KTX-이음|승차|11-12 | B13: 1026
... A2305: 2026|평일|전체|하차|23-24 | B2305: 14060

Sheet d_역계산
A1: 시간대 | B1: 시 | C1: 승차 | D1: 하차 | E1: 창 안 승차 | F1: 창 밖 승차
A2: 05시 | B2: 5 | C2: =SUMIFS(d_역!$B$2:$B$2305,d_역!$A$2:$A$2305,'운영 시간'!$B$9&"|"&'운영 시간'!$H$9&"|"&'운영 시간'!$O$9&"|승차|05-06") -> 0 | D2: =SUMIFS(d_역!$B$2:$B$2305,d_역!$A$2:$A$2305,'운영 시간'!$B$9&"|"&'운영 시간'!$H$9&"|"&'운영 시간'!$O$9&"|하차|05-06") -> 0 | E2: =IF(AND(B2+1>'운영 시간'!$V$9,B2<'운영 시간'!$AB$9),C2,NA()) -> #N/A | F2: =IF(AND(B2+1>'운영 시간'!$V$9,B2<'운영 시간'!$AB$9),NA(),C2) -> 0
A3: 06시 | B3: 6 | C3: =SUMIFS(d_역!$B$2:$B$2305,d_역!$A$2:$A$2305,'운영 시간'!$B$9&"|"&'운영 시간'!$H$9&"|"&'운영 시간'!$O$9&"|승차|06-07") -> 5297 | D3: =SUMIFS(d_역!$B$2:$B$2305,d_역!$A$2:$A$2305,'운영 시간'!$B$9&"|"&'운영 시간'!$H$9&"|"&'운영 시간'!$O$9&"|하차|06-07") -> 0 | E3: =IF(AND(B3+1>'운영 시간'!$V$9,B3<'운영 시간'!$AB$9),C3,NA()) -> #N/A | F3: =IF(AND(B3+1>'운영 시간'!$V$9,B3<'운영 시간'!$AB$9),NA(),C3) -> 5297
A4: 07시 | B4: 7 | C4: =SUMIFS(d_역!$B$2:$B$2305,d_역!$A$2:$A$2305,'운영 시간'!$B$9&"|"&'운영 시간'!$H$9&"|"&'운영 시간'!$O$9&"|승차|07-08") -> 12235 | D4: =SUMIFS(d_역!$B$2:$B$2305,d_역!$A$2:$A$2305,'운영 시간'!$B$9&"|"&'운영 시간'!$H$9&"|"&'운영 시간'!$O$9&"|하차|07-08") -> 4122 | E4: =IF(AND(B4+1>'운영 시간'!$V$9,B4<'운영 시간'!$AB$9),C4,NA()) -> #N/A | F4: =IF(AND(B4+1>'운영 시간'!$V$9,B4<'운영 시간'!$AB$9),NA(),C4) -> 12235
A5: 08시 | B5: 8 | C5: =SUMIFS(d_역!$B$2:$B$2305,d_역!$A$2:$A$2305,'운영 시간'!$B$9&"|"&'운영 시간'!$H$9&"|"&'운영 시간'!$O$9&"|승차|08-09") -> 3846 | D5: =SUMIFS(d_역!$B$2:$B$2305,d_역!$A$2:$A$2305,'운영 시간'!$B$9&"|"&'운영 시간'!$H$9&"|"&'운영 시간'!$O$9&"|하차|08-09") -> 3282 | E5: =IF(AND(B5+1>'운영 시간'!$V$9,B5<'운영 시간'!$AB$9),C5,NA()) -> #N/A | F5: =IF(AND(B5+1>'운영 시간'!$V$9,B5<'운영 시간'!$AB$9),NA(),C5) -> 3846
A6: 09시 | B6: 9 | C6: =SUMIFS(d_역!$B$2:$B$2305,d_역!$A$2:$A$2305,'운영 시간'!$B$9&"|"&'운영 시간'!$H$9&"|"&'운영 시간'!$O$9&"|승차|09-10") -> 2752 | D6: =SUMIFS(d_역!$B$2:$B$2305,d_역!$A$2:$A$2305,'운영 시간'!$B$9&"|"&'운영 시간'!$H$9&"|"&'운영 시간'!$O$9&"|하차|09-10") -> 3329 | E6: =IF(AND(B6+1>'운영 시간'!$V$9,B6<'운영 시간'!$AB$9),C6,NA()) -> #N/A | F6: =IF(AND(B6+1>'운영 시간'!$V$9,B6<'운영 시간'!$AB$9),NA(),C6) -> 2752
A7: 10시 | B7: 10 | C7: =SUMIFS(d_역!$B$2:$B$2305,d_역!$A$2:$A$2305,'운영 시간'!$B$9&"|"&'운영 시간'!$H$9&"|"&'운영 시간'!$O$9&"|승차|10-11") -> 12336 | D7: =SUMIFS(d_역!$B$2:$B$2305,d_역!$A$2:$A$2305,'운영 시간'!$B$9&"|"&'운영 시간'!$H$9&"|"&'운영 시간'!$O$9&"|하차|10-11") -> 7001 | E7: =IF(AND(B7+1>'운영 시간'!$V$9,B7<'운영 시간'!$AB$9),C7,NA()) -> #N/A | F7: =IF(AND(B7+1>'운영 시간'!$V$9,B7<'운영 시간'!$AB$9),NA(),C7) -> 12336
A8: 11시 | B8: 11 | C8: =SUMIFS(d_역!$B$2:$B$2305,d_역!$A$2:$A$2305,'운영 시간'!$B$9&"|"&'운영 시간'!$H$9&"|"&'운영 시간'!$O$9&"|승차|11-12") -> 4638 | D8: =SUMIFS(d_역!$B$2:$B$2305,d_역!$A$2:$A$2305,'운영 시간'!$B$9&"|"&'운영 시간'!$H$9&"|"&'운영 시간'!$O$9&"|하차|11-12") -> 9270 | E8: =IF(AND(B8+1>'운영 시간'!$V$9,B8<'운영 시간'!$AB$9),C8,NA()) -> #N/A | F8: =IF(AND(B8+1>'운영 시간'!$V$9,B8<'운영 시간'!$AB$9),NA(),C8) -> 4638
A9: 12시 | B9: 12 | C9: =SUMIFS(d_역!$B$2:$B$2305,d_역!$A$2:$A$2305,'운영 시간'!$B$9&"|"&'운영 시간'!$H$9&"|"&'운영 시간'!$O$9&"|승차|12-13") -> 7289 | D9: =SUMIFS(d_역!$B$2:$B$2305,d_역!$A$2:$A$2305,'운영 시간'!$B$9&"|"&'운영 시간'!$H$9&"|"&'운영 시간'!$O$9&"|하차|12-13") -> 4272 | E9: =IF(AND(B9+1>'운영 시간'!$V$9,B9<'운영 시간'!$AB$9),C9,NA()) -> #N/A | F9: =IF(AND(B9+1>'운영 시간'!$V$9,B9<'운영 시간'!$AB$9),NA(),C9) -> 7289
A10: 13시 | B10: 13 | C10: =SUMIFS(d_역!$B$2:$B$2305,d_역!$A$2:$A$2305,'운영 시간'!$B$9&"|"&'운영 시간'!$H$9&"|"&'운영 시간'!$O$9&"|승차|13-14") -> 4325 | D10: =SUMIFS(d_역!$B$2:$B$2305,d_역!$A$2:$A$2305,'운영 시간'!$B$9&"|"&'운영 시간'!$H$9&"|"&'운영 시간'!$O$9&"|하차|13-14") -> 9693 | E10: =IF(AND(B10+1>'운영 시간'!$V$9,B10<'운영 시간'!$AB$9),C10,NA()) -> #N/A | F10: =IF(AND(B10+1>'운영 시간'!$V$9,B10<'운영 시간'!$AB$9),NA(),C10) -> 4325
A11: 14시 | B11: 14 | C11: =SUMIFS(d_역!$B$2:$B$2305,d_역!$A$2:$A$2305,'운영 시간'!$B$9&"|"&'운영 시간'!$H$9&"|"&'운영 시간'!$O$9&"|승차|14-15") -> 13740 | D11: =SUMIFS(d_역!$B$2:$B$2305,d_역!$A$2:$A$2305,'운영 시간'!$B$9&"|"&'운영 시간'!$H$9&"|"&'운영 시간'!$O$9&"|하차|14-15") -> 5056 | E11: =IF(AND(B11+1>'운영 시간'!$V$9,B11<'운영 시간'!$AB$9),C11,NA()) -> #N/A | F11: =IF(AND(B11+1>'운영 시간'!$V$9,B11<'운영 시간'!$AB$9),NA(),C11) -> 13740
A12: 15시 | B12: 15 | C12: =SUMIFS(d_역!$B$2:$B$2305,d_역!$A$2:$A$2305,'운영 시간'!$B$9&"|"&'운영 시간'!$H$9&"|"&'운영 시간'!$O$9&"|승차|15-16") -> 14770 | D12: =SUMIFS(d_역!$B$2:$B$2305,d_역!$A$2:$A$2305,'운영 시간'!$B$9&"|"&'운영 시간'!$H$9&"|"&'운영 시간'!$O$9&"|하차|15-16") -> 15957 | E12: =IF(AND(B12+1>'운영 시간'!$V$9,B12<'운영 시간'!$AB$9),C12,NA()) -> #N/A | F12: =IF(AND(B12+1>'운영 시간'!$V$9,B12<'운영 시간'!$AB$9),NA(),C12) -> 14770
A13: 16시 | B13: 16 | C13: =SUMIFS(d_역!$B$2:$B$2305,d_역!$A$2:$A$2305,'운영 시간'!$B$9&"|"&'운영 시간'!$H$9&"|"&'운영 시간'!$O$9&"|승차|16-17") -> 10803 | D13: =SUMIFS(d_역!$B$2:$B$2305,d_역!$A$2:$A$2305,'운영 시간'!$B$9&"|"&'운영 시간'!$H$9&"|"&'운영 시간'!$O$9&"|하차|16-17") -> 10304 | E13: =IF(AND(B13+1>'운영 시간'!$V$9,B13<'운영 시간'!$AB$9),C13,NA()) -> #N/A | F13: =IF(AND(B13+1>'운영 시간'!$V$9,B13<'운영 시간'!$AB$9),NA(),C13) -> 10803
A14: 17시 | B14: 17 | C14: =SUMIFS(d_역!$B$2:$B$2305,d_역!$A$2:$A$2305,'운영 시간'!$B$9&"|"&'운영 시간'!$H$9&"|"&'운영 시간'!$O$9&"|승차|17-18") -> 2217 | D14: =SUMIFS(d_역!$B$2:$B$2305,d_역!$A$2:$A$2305,'운영 시간'!$B$9&"|"&'운영 시간'!$H$9&"|"&'운영 시간'!$O$9&"|하차|17-18") -> 3371 | E14: =IF(AND(B14+1>'운영 시간'!$V$9,B14<'운영 시간'!$AB$9),C14,NA()) -> #N/A | F14: =IF(AND(B14+1>'운영 시간'!$V$9,B14<'운영 시간'!$AB$9),NA(),C14) -> 2217
A15: 18시 | B15: 18 | C15: =SUMIFS(d_역!$B$2:$B$2305,d_역!$A$2:$A$2305,'운영 시간'!$B$9&"|"&'운영 시간'!$H$9&"|"&'운영 시간'!$O$9&"|승차|18-19") -> 13454 | D15: =SUMIFS(d_역!$B$2:$B$2305,d_역!$A$2:$A$2305,'운영 시간'!$B$9&"|"&'운영 시간'!$H$9&"|"&'운영 시간'!$O$9&"|하차|18-19") -> 13982 | E15: =IF(AND(B15+1>'운영 시간'!$V$9,B15<'운영 시간'!$AB$9),C15,NA()) -> 13454 | F15: =IF(AND(B15+1>'운영 시간'!$V$9,B15<'운영 시간'!$AB$9),NA(),C15) -> #N/A
A16: 19시 | B16: 19 | C16: =SUMIFS(d_역!$B$2:$B$2305,d_역!$A$2:$A$2305,'운영 시간'!$B$9&"|"&'운영 시간'!$H$9&"|"&'운영 시간'!$O$9&"|승차|19-20") -> 7110 | D16: =SUMIFS(d_역!$B$2:$B$2305,d_역!$A$2:$A$2305,'운영 시간'!$B$9&"|"&'운영 시간'!$H$9&"|"&'운영 시간'!$O$9&"|하차|19-20") -> 6962 | E16: =IF(AND(B16+1>'운영 시간'!$V$9,B16<'운영 시간'!$AB$9),C16,NA()) -> 7110 | F16: =IF(AND(B16+1>'운영 시간'!$V$9,B16<'운영 시간'!$AB$9),NA(),C16) -> #N/A
A17: 20시 | B17: 20 | C17: =SUMIFS(d_역!$B$2:$B$2305,d_역!$A$2:$A$2305,'운영 시간'!$B$9&"|"&'운영 시간'!$H$9&"|"&'운영 시간'!$O$9&"|승차|20-21") -> 2625 | D17: =SUMIFS(d_역!$B$2:$B$2305,d_역!$A$2:$A$2305,'운영 시간'!$B$9&"|"&'운영 시간'!$H$9&"|"&'운영 시간'!$O$9&"|하차|20-21") -> 10943 | E17: =IF(AND(B17+1>'운영 시간'!$V$9,B17<'운영 시간'!$AB$9),C17,NA()) -> 2625 | F17: =IF(AND(B17+1>'운영 시간'!$V$9,B17<'운영 시간'!$AB$9),NA(),C17) -> #N/A
A18: 21시 | B18: 21 | C18: =SUMIFS(d_역!$B$2:$B$2305,d_역!$A$2:$A$2305,'운영 시간'!$B$9&"|"&'운영 시간'!$H$9&"|"&'운영 시간'!$O$9&"|승차|21-22") -> 7110 | D18: =SUMIFS(d_역!$B$2:$B$2305,d_역!$A$2:$A$2305,'운영 시간'!$B$9&"|"&'운영 시간'!$H$9&"|"&'운영 시간'!$O$9&"|하차|21-22") -> 7087 | E18: =IF(AND(B18+1>'운영 시간'!$V$9,B18<'운영 시간'!$AB$9),C18,NA()) -> #N/A | F18: =IF(AND(B18+1>'운영 시간'!$V$9,B18<'운영 시간'!$AB$9),NA(),C18) -> 7110
A19: 22시 | B19: 22 | C19: =SUMIFS(d_역!$B$2:$B$2305,d_역!$A$2:$A$2305,'운영 시간'!$B$9&"|"&'운영 시간'!$H$9&"|"&'운영 시간'!$O$9&"|승차|22-23") -> 0 | D19: =SUMIFS(d_역!$B$2:$B$2305,d_역!$A$2:$A$2305,'운영 시간'!$B$9&"|"&'운영 시간'!$H$9&"|"&'운영 시간'!$O$9&"|하차|22-23") -> 0 | E19: =IF(AND(B19+1>'운영 시간'!$V$9,B19<'운영 시간'!$AB$9),C19,NA()) -> #N/A | F19: =IF(AND(B19+1>'운영 시간'!$V$9,B19<'운영 시간'!$AB$9),NA(),C19) -> 0
A20: 23시 | B20: 23 | C20: =SUMIFS(d_역!$B$2:$B$2305,d_역!$A$2:$A$2305,'운영 시간'!$B$9&"|"&'운영 시간'!$H$9&"|"&'운영 시간'!$O$9&"|승차|23-24") -> 0 | D20: =SUMIFS(d_역!$B$2:$B$2305,d_역!$A$2:$A$2305,'운영 시간'!$B$9&"|"&'운영 시간'!$H$9&"|"&'운영 시간'!$O$9&"|하차|23-24") -> 9048 | E20: =IF(AND(B20+1>'운영 시간'!$V$9,B20<'운영 시간'!$AB$9),C20,NA()) -> #N/A | F20: =IF(AND(B20+1>'운영 시간'!$V$9,B20<'운영 시간'!$AB$9),NA(),C20) -> 0

Sheet d_버스
A1: 키 | B1: 회
A2: 110|평일|6 | B2: 7
A3: 110|평일|7 | B3: 10
A4: 110|평일|8 | B4: 10
A5: 110|평일|9 | B5: 10
A6: 110|평일|10 | B6: 9
A7: 110|평일|11 | B7: 9
A8: 110|평일|12 | B8: 10
A9: 110|평일|13 | B9: 8
A10: 110|평일|14 | B10: 9
A11: 110|평일|15 | B11: 8
A12: 110|평일|16 | B12: 9
A13: 110|평일|17 | B13: 9
... A529: 풍천3-1|평일|17 | B529: 1

Sheet d_버스출발
A1: 노선번호 | B1: 시간표 구분 | C1: 시각값 | D1: 선택 노선 시각
A2: 110 | B2: 평일 | C2: 0.27777778 | D2: =IF(AND(A2&""=버스!$B$9&"",B2=버스!$I$9),C2,"")
A3: 110 | B3: 평일 | C3: 0.29166667 | D3: =IF(AND(A3&""=버스!$B$9&"",B3=버스!$I$9),C3,"")
A4: 110 | B4: 평일 | C4: 0.30416667 | D4: =IF(AND(A4&""=버스!$B$9&"",B4=버스!$I$9),C4,"")
A5: 110 | B5: 평일 | C5: 0.3125 | D5: =IF(AND(A5&""=버스!$B$9&"",B5=버스!$I$9),C5,"")
A6: 110 | B6: 평일 | C6: 0.31944444 | D6: =IF(AND(A6&""=버스!$B$9&"",B6=버스!$I$9),C6,"")
A7: 110 | B7: 평일 | C7: 0.325 | D7: =IF(AND(A7&""=버스!$B$9&"",B7=버스!$I$9),C7,"")
A8: 110 | B8: 평일 | C8: 0.33333333 | D8: =IF(AND(A8&""=버스!$B$9&"",B8=버스!$I$9),C8,"")
A9: 110 | B9: 평일 | C9: 0.34027778 | D9: =IF(AND(A9&""=버스!$B$9&"",B9=버스!$I$9),C9,"")
A10: 110 | B10: 평일 | C10: 0.35069444 | D10: =IF(AND(A10&""=버스!$B$9&"",B10=버스!$I$9),C10,"")
A11: 110 | B11: 평일 | C11: 0.36111111 | D11: =IF(AND(A11&""=버스!$B$9&"",B11=버스!$I$9),C11,"")
A12: 110 | B12: 평일 | C12: 0.36805556 | D12: =IF(AND(A12&""=버스!$B$9&"",B12=버스!$I$9),C12,"")
A13: 110 | B13: 평일 | C13: 0.37708333 | D13: =IF(AND(A13&""=버스!$B$9&"",B13=버스!$I$9),C13,"")
... A1398: 풍천3-1 | B1398: 평일 | C1398: 0.70833333 | D1398: =IF(AND(A1398&""=버스!$B$9&"",B1398=버스!$I$9),C1398,"")

Sheet d_노선목록
A1: 노선
A2: 110
A3: 111
A4: 112
A5: 113
A6: 114
A7: 210
A8: 211
A9: 212
A10: 213
A11: 310
A12: 311
... A47: 풍천3-1

Sheet d_버스계산
A1: 시 | B1: 선택 노선 | C1: 안동역→원도심 | D1: 원도심→안동역 | E1: 원도심→월영교 | F1: 월영교→원도심 | G1: 안동역→월영교 | H1: 월영교→안동역 | I1: 원도심→월영교(추가 반영)
A2: 05시 | B2: =SUMIFS(d_버스!$B$2:$B$529,d_버스!$A$2:$A$529,버스!$B$9&"|"&버스!$I$9&"|5") -> 0 | C2: 0 | D2: 0 | E2: 0 | F2: 0 | G2: 0 | H2: 0 | I2: =E2+IF(AND(5>=19,5<21),버스!$Q$9/2,0) -> 0
A3: 06시 | B3: =SUMIFS(d_버스!$B$2:$B$529,d_버스!$A$2:$A$529,버스!$B$9&"|"&버스!$I$9&"|6") -> 0 | C3: 22 | D3: 47 | E3: 0 | F3: 0 | G3: 0 | H3: 0 | I3: =E3+IF(AND(6>=19,6<21),버스!$Q$9/2,0) -> 0
A4: 07시 | B4: =SUMIFS(d_버스!$B$2:$B$529,d_버스!$A$2:$A$529,버스!$B$9&"|"&버스!$I$9&"|7") -> 1 | C4: 38 | D4: 47 | E4: 0 | F4: 0 | G4: 0 | H4: 0 | I4: =E4+IF(AND(7>=19,7<21),버스!$Q$9/2,0) -> 0
A5: 08시 | B5: =SUMIFS(d_버스!$B$2:$B$529,d_버스!$A$2:$A$529,버스!$B$9&"|"&버스!$I$9&"|8") -> 1 | C5: 39 | D5: 36 | E5: 1 | F5: 1 | G5: 1 | H5: 1 | I5: =E5+IF(AND(8>=19,8<21),버스!$Q$9/2,0) -> 1
A6: 09시 | B6: =SUMIFS(d_버스!$B$2:$B$529,d_버스!$A$2:$A$529,버스!$B$9&"|"&버스!$I$9&"|9") -> 0 | C6: 37 | D6: 38 | E6: 0 | F6: 0 | G6: 0 | H6: 0 | I6: =E6+IF(AND(9>=19,9<21),버스!$Q$9/2,0) -> 0
A7: 10시 | B7: =SUMIFS(d_버스!$B$2:$B$529,d_버스!$A$2:$A$529,버스!$B$9&"|"&버스!$I$9&"|10") -> 1 | C7: 39 | D7: 39 | E7: 1 | F7: 1 | G7: 1 | H7: 1 | I7: =E7+IF(AND(10>=19,10<21),버스!$Q$9/2,0) -> 1
A8: 11시 | B8: =SUMIFS(d_버스!$B$2:$B$529,d_버스!$A$2:$A$529,버스!$B$9&"|"&버스!$I$9&"|11") -> 0 | C8: 35 | D8: 36 | E8: 0 | F8: 0 | G8: 0 | H8: 0 | I8: =E8+IF(AND(11>=19,11<21),버스!$Q$9/2,0) -> 0
A9: 12시 | B9: =SUMIFS(d_버스!$B$2:$B$529,d_버스!$A$2:$A$529,버스!$B$9&"|"&버스!$I$9&"|12") -> 1 | C9: 34 | D9: 36 | E9: 1 | F9: 1 | G9: 1 | H9: 1 | I9: =E9+IF(AND(12>=19,12<21),버스!$Q$9/2,0) -> 1
A10: 13시 | B10: =SUMIFS(d_버스!$B$2:$B$529,d_버스!$A$2:$A$529,버스!$B$9&"|"&버스!$I$9&"|13") -> 0 | C10: 34 | D10: 40 | E10: 0 | F10: 0 | G10: 0 | H10: 0 | I10: =E10+IF(AND(13>=19,13<21),버스!$Q$9/2,0) -> 0
A11: 14시 | B11: =SUMIFS(d_버스!$B$2:$B$529,d_버스!$A$2:$A$529,버스!$B$9&"|"&버스!$I$9&"|14") -> 0 | C11: 38 | D11: 38 | E11: 0 | F11: 0 | G11: 0 | H11: 0 | I11: =E11+IF(AND(14>=19,14<21),버스!$Q$9/2,0) -> 0
A12: 15시 | B12: =SUMIFS(d_버스!$B$2:$B$529,d_버스!$A$2:$A$529,버스!$B$9&"|"&버스!$I$9&"|15") -> 0 | C12: 39 | D12: 36 | E12: 0 | F12: 0 | G12: 0 | H12: 0 | I12: =E12+IF(AND(15>=19,15<21),버스!$Q$9/2,0) -> 0
A13: 16시 | B13: =SUMIFS(d_버스!$B$2:$B$529,d_버스!$A$2:$A$529,버스!$B$9&"|"&버스!$I$9&"|16") -> 1 | C13: 37 | D13: 45 | E13: 1 | F13: 1 | G13: 1 | H13: 0 | I13: =E13+IF(AND(16>=19,16<21),버스!$Q$9/2,0) -> 1
A14: 17시 | B14: =SUMIFS(d_버스!$B$2:$B$529,d_버스!$A$2:$A$529,버스!$B$9&"|"&버스!$I$9&"|17") -> 1 | C14: 36 | D14: 30 | E14: 1 | F14: 0 | G14: 0 | H14: 0 | I14: =E14+IF(AND(17>=19,17<21),버스!$Q$9/2,0) -> 1
A15: 18시 | B15: =SUMIFS(d_버스!$B$2:$B$529,d_버스!$A$2:$A$529,버스!$B$9&"|"&버스!$I$9&"|18") -> 2 | C15: 37 | D15: 33 | E15: 1 | F15: 1 | G15: 0 | H15: 0 | I15: =E15+IF(AND(18>=19,18<21),버스!$Q$9/2,0) -> 1
A16: 19시 | B16: =SUMIFS(d_버스!$B$2:$B$529,d_버스!$A$2:$A$529,버스!$B$9&"|"&버스!$I$9&"|19") -> 1 | C16: 25 | D16: 24 | E16: 0 | F16: 1 | G16: 0 | H16: 0 | I16: =E16+IF(AND(19>=19,19<21),버스!$Q$9/2,0) -> 0
A17: 20시 | B17: =SUMIFS(d_버스!$B$2:$B$529,d_버스!$A$2:$A$529,버스!$B$9&"|"&버스!$I$9&"|20") -> 0 | C17: 18 | D17: 19 | E17: 0 | F17: 0 | G17: 0 | H17: 0 | I17: =E17+IF(AND(20>=19,20<21),버스!$Q$9/2,0) -> 0
A18: 21시 | B18: =SUMIFS(d_버스!$B$2:$B$529,d_버스!$A$2:$A$529,버스!$B$9&"|"&버스!$I$9&"|21") -> 0 | C18: 18 | D18: 11 | E18: 0 | F18: 0 | G18: 0 | H18: 0 | I18: =E18+IF(AND(21>=19,21<21),버스!$Q$9/2,0) -> 0
A19: 22시 | B19: =SUMIFS(d_버스!$B$2:$B$529,d_버스!$A$2:$A$529,버스!$B$9&"|"&버스!$I$9&"|22") -> 0 | C19: 4 | D19: 4 | E19: 0 | F19: 0 | G19: 0 | H19: 0 | I19: =E19+IF(AND(22>=19,22<21),버스!$Q$9/2,0) -> 0
A20: 23시 | B20: =SUMIFS(d_버스!$B$2:$B$529,d_버스!$A$2:$A$529,버스!$B$9&"|"&버스!$I$9&"|23") -> 0 | C20: 0 | D20: 0 | E20: 0 | F20: 0 | G20: 0 | H20: 0 | I20: =E20+IF(AND(23>=19,23<21),버스!$Q$9/2,0) -> 0

Sheet d_철도
A1: 관광지명 | B1: 방문점유율_pct | C1: 방문객소비건수점유율_pct | D1: 소비방문배율
A2: 월영교 | B2: 15.24 | C2: 6.05 | D2: 0.4
A3: 안동문화관광단지 | B3: 11.02 | C3: 2.28 | D3: 0.21
A4: 안동하회마을 | B4: 6.29 | C4: 0.4 | D4: 0.06
A5: 낙강물길공원 | B5: 2.37 | C5: 0 | D5: 0
A6: 만휴정 | B6: 2.23 | C6: 0 | D6: 0
A7: 봉정사 | B7: 1.71 | C7: 0.02 | D7: 0.01
A8: 도산서원 | B8: 2.27 | C8: 0.65 | D8: 0.29
A9: 병산서원 | B9: 1.13 | C9: 0.06 | D9: 0.05
A10: 권정생동화나라 | B10: 0.43 | C10: 0.01 | D10: 0.03
A11: 안동민속촌 | B11: 1.1 | C11: 0.75 | D11: 0.68
A12: 유교문화박물관 | B12: 0.36 | C12: 0.13 | D12: 0.37
A13: 안동포마을 | B13: 0.07 | C13: 0 | D13: 0
... A20: 안동문화의거리 | B20: 18.85 | C20: 32.66 | D20: 1.73

Sheet d_월영교
A1: 업체 | B1: 업종 | C1: 영업 종료(시) | D1: 식사 가능 | E1: 21시 전 종료 | F1: 21시 이후
A2: 안동댐간고등어직영식당 | B2: 한식 | C2: 20 | D2: 1 | E2: =IF(AND(ISNUMBER(C2),C2<21),C2,NA()) -> 20 | F2: =IF(AND(ISNUMBER(C2),C2>=21),C2,NA()) -> #N/A
A3: 맛50년헛제사밥 | B3: 한식 | C3: 20 | D3: 1 | E3: =IF(AND(ISNUMBER(C3),C3<21),C3,NA()) -> 20 | F3: =IF(AND(ISNUMBER(C3),C3>=21),C3,NA()) -> #N/A
A4: 호반정 | B4: 한식 | C4: 20 | D4: 1 | E4: =IF(AND(ISNUMBER(C4),C4<21),C4,NA()) -> 20 | F4: =IF(AND(ISNUMBER(C4),C4>=21),C4,NA()) -> #N/A
A5: 옛날촌동네 | B5: 한식 | C5: 20 | D5: 1 | E5: =IF(AND(ISNUMBER(C5),C5<21),C5,NA()) -> 20 | F5: =IF(AND(ISNUMBER(C5),C5>=21),C5,NA()) -> #N/A
A6: 삼일가든 | B6: 한식 | C6: 20.5 | D6: 1 | E6: =IF(AND(ISNUMBER(C6),C6<21),C6,NA()) -> 20.5 | F6: =IF(AND(ISNUMBER(C6),C6>=21),C6,NA()) -> #N/A
A7: 이정식당 | B7: 한식 | C7: 20.5 | D7: 1 | E7: =IF(AND(ISNUMBER(C7),C7<21),C7,NA()) -> 20.5 | F7: =IF(AND(ISNUMBER(C7),C7>=21),C7,NA()) -> #N/A
A8: 고센피제리아안동댐점 | B8: 서양식 | C8: 20.5 | D8: 1 | E8: =IF(AND(ISNUMBER(C8),C8<21),C8,NA()) -> 20.5 | F8: =IF(AND(ISNUMBER(C8),C8>=21),C8,NA()) -> #N/A
A9: 안동김대감 | B9: 한식 | C9: 21 | D9: 1 | E9: =IF(AND(ISNUMBER(C9),C9<21),C9,NA()) -> #N/A | F9: =IF(AND(ISNUMBER(C9),C9>=21),C9,NA()) -> 21
A10: 와룡가든 | B10: 한식 | C10: 21 | D10: 1 | E10: =IF(AND(ISNUMBER(C10),C10<21),C10,NA()) -> #N/A | F10: =IF(AND(ISNUMBER(C10),C10>=21),C10,NA()) -> 21
A11: 라라룬 | B11: 카페 | C11: 22 | D11: 0 | E11: =IF(AND(ISNUMBER(C11),C11<21),C11,NA()) -> #N/A | F11: =IF(AND(ISNUMBER(C11),C11>=21),C11,NA()) -> 22
A12: 월영당 | B12: 카페 | C12: 22 | D12: 0 | E12: =IF(AND(ISNUMBER(C12),C12<21),C12,NA()) -> #N/A | F12: =IF(AND(ISNUMBER(C12),C12>=21),C12,NA()) -> 22
A13: 카페구름마루 | B13: 카페 | C13: 22 | D13: 0 | E13: =IF(AND(ISNUMBER(C13),C13<21),C13,NA()) -> #N/A | F13: =IF(AND(ISNUMBER(C13),C13>=21),C13,NA()) -> 22
... A17: 나우커피안동댐점 | B17: 카페 | C17: 24 | D17: 0 | E17: =IF(AND(ISNUMBER(C17),C17<21),C17,NA()) -> #N/A | F17: =IF(AND(ISNUMBER(C17),C17>=21),C17,NA()) -> 24
A18: 팝업 부스 | B18: 팝업 | C18: =IF(월영교!$B$9>0,월영교!$I$9,NA()) -> #N/A | D18: 1 | E18: =IF(AND(ISNUMBER(C18),C18<21),C18,NA()) -> #N/A | F18: =IF(AND(ISNUMBER(C18),C18>=21),C18,NA()) -> #N/A

Sheet d_업종구성
A1: 업종 | B1: 월영교 1km | C1: 원도심 1km
A2: 한식 | B2: 0.58823529 | C2: 0.44764398
A3: 카페 | B3: 0.35294118 | C3: 0.16623037
A4: 주점 | B4: 0 | C4: 0.11256545
A5: 서양식 | B5: 0.058823529 | C5: 0.017015707
A6: 기타 | B6: 0 | C6: 0.2565445

Sheet d_설문
A1: 방문 | B1: 이동 | C1: 버스주이용 | D1: Q3 | E1: 포기_외곽 | F1: 포기_월영교 | G1: 포기_원도심 | H1: 포기_없음 | I1: Q4응답 | J1: Q9 | K1: Q11 | L1: Q13 | M1: Q6 | N1: Q8 | O1: Q10 | P1: Q12
A2: 예 | B2: 차 없음 | C2: 1 | D2: 불편했다 | E2: 1 | F2: 1 | G2: 1 | H2: 0 | I2: 1 | J2: 충분 | K2: 줄·예약 불편 | L2: 18시 이전 | M2: 5 | N2: 5 | O2: 5 | P2: 0
A3: 예 | B3: 자가용 | C3: 0 | D3: 이용하지 않았다 / 잘 모르겠다 | E3: 0 | F3: 0 | G3: 1 | H3: 0 | I3: 1 | J3: 보통 | K3: 가격 부담 | L3: 숙박 | M3: 5 | N3: 5 | O3: 4 | P3: 4
A4: 예 | B4: 자가용 | C4: 0 | D4: 이용하지 않았다 / 잘 모르겠다 | E4: 0 | F4: 0 | G4: 0 | H4: 1 | I4: 1 | J4: 보통 | K4: 줄·예약 불편 | L4: 숙박 | M4: 5 | N4: 5 | O4: 5 | P4: 5
A5: 예 | B5: 자가용 | C5: 0 | D5: 이용하지 않았다 / 잘 모르겠다 | E5: 0 | F5: 0 | G5: 1 | H5: 0 | I5: 1 | J5: 보통 | K5: 정보 부족 | L5: 20-22시(막차) | M5: 5 | N5: 5 | O5: 5 | P5: 5
A6: 예 | B6: 자가용 | C6: 0 | D6: 이용하지 않았다 / 잘 모르겠다 | E6: 0 | F6: 0 | G6: 1 | H6: 0 | I6: 1 | J6: 보통 | K6: 정보 부족 | L6: 숙박 | M6: 4 | N6: 2 | O6: 2 | P6: 4
A7: 예 | B7: 자가용 | C7: 0 | D7: 이용하지 않았다 / 잘 모르겠다 | E7: 0 | F7: 0 | G7: 0 | H7: 1 | I7: 1 | J7: 보통 | K7: 정보 부족 | L7: 18-20시 | M7: 5 | N7: 4 | O7: 4 | P7: 5
A8: 아니오 | B8: 차 없음 | C8: 0 | D8: 이용하지 않았다 / 잘 모르겠다 | E8: 0 | F8: 0 | G8: 0 | H8: 1 | I8: 1 | J8: 충분 | K8: 정보 부족 | L8: 18-20시 | M8: 3 | N8: 4 | O8: 3 | P8: 3
A9: 아니오 | B9: 자가용 | C9: 0 | D9: 이용하지 않았다 / 잘 모르겠다 | E9: 1 | F9: 0 | G9: 0 | H9: 0 | I9: 1 | J9: 보통 | K9: 가격 부담 | L9: 숙박 | M9: 4 | N9: 2 | O9: 3 | P9: 4
A10: 예 | B10: 자가용 | C10: 0 | D10: 이용하지 않았다 / 잘 모르겠다 | E10: 0 | F10: 0 | G10: 0 | H10: 1 | I10: 1 | J10: 부족 | K10: 정보 부족 | L10: 숙박 | M10: 4 | N10: 2 | O10: 5 | P10: 5
A11: 예 | B11: 차 없음 | C11: 1 | D11: 불편했다 | E11: 0 | F11: 1 | G11: 0 | H11: 0 | I11: 1 | J11: 부족 | K11: 줄·예약 불편 | L11: 18-20시 | M11: 3 | N11: 5 | O11: 5 | P11: 5
A12: 예 | B12: 차 없음 | C12: 1 | D12: 불편했다 | E12: 1 | F12: 0 | G12: 0 | H12: 0 | I12: 1 | J12: 부족 | K12: 가격 부담 | L12: 20-22시(막차) | M12: 2 | N12: 5 | O12: 5 | P12: 4
A13: 예 | B13: 차 없음 | C13: 1 | D13: 불편했다 | E13: 1 | F13: 1 | G13: 0 | H13: 0 | I13: 1 | J13: 보통 | K13: 정보 부족 | L13: 18시 이전 | M13: 5 | N13: 5 | O13: 5 | P13: 4
... A104: 예 | B104: 자가용 | C104: 0 | D104: 불편했다 | E104: 0 | F104: 1 | G104: 0 | H104: 0 | I104: 1 | J104: 보통 | K104: 정보 부족 | L104: 숙박 | M104: 3 | N104: 3 | O104: 3 | P104: 5

Sheet d_설문계산
A1: 방문 조건 | B1: =IF(설문조사!$B$9="방문자만","예","*") -> 예 | D1: 문항 | E1: 매우 있다 | F1: 있다 | G1: 보통 | H1: 별로 없다 | I1: 전혀 없다 | K1: 포기한 곳 | L1: 비율 | N1: 망설임 이유 | O1: 비율
