Workbook

Sheet 100선
A1: 시도 | B1: 시군 | C1: 명소명 | D1: 유형 | E1: 운영기간 | F1: 권역 | G1: 문체부 발표 표기 | H1: 구석구석 번호 | I1: 구석구석 상세 URL | J1: 출처 URL | K1: 게시일 | L1: 보조 출처 URL(유형·기간) | M1: 보조 게시일 | N1: 조사일 | O1: 비고
A2: 서울 | C2: DDP | D2: 미디어아트 | E2: 연중 | F2: 수도권 | G2: 동대문디자인플라자 | H2: 1 | I2: https://korean.visitkorea.or.kr/detail/ms_detail.do?cotid=758fb4e9-533f-4636-8753-73b8d059c54d | J2: https://korean.visitkorea.or.kr/detail/rem_detail.do?cotid=ec1515b2-8a5c-45c9-99dc-a8c23fea9f9b | K2: 2023-10-31 등록 · 2024-02-19 수정 | L2: https://www.latimes.kr/news/articleView.html?idxno=51248 | M2: 2023-11-08 | N2: 46286 | O2: 특별·광역시: 원문에 구 표기 없음; 발표 표기와 다름
A3: 서울 | C3: 남산 서울타워 | D3: 야간경관 | E3: 연중 | F3: 수도권 | G3: 남산 서울타워 | H3: 17 | I3: https://korean.visitkorea.or.kr/detail/ms_detail.do?cotid=ad931739-fca3-4135-a878-cc7fb82920ba | J3: https://korean.visitkorea.or.kr/detail/rem_detail.do?cotid=ec1515b2-8a5c-45c9-99dc-a8c23fea9f9b | K3: 2023-10-31 등록 · 2024-02-19 수정 | L3: https://www.latimes.kr/news/articleView.html?idxno=51248 | M3: 2023-11-08 | N3: 46286 | O3: 특별·광역시: 원문에 구 표기 없음
A4: 서울 | C4: 덕수궁 | D4: 야간경관 | E4: 연중 | F4: 수도권 | G4: 덕수궁 | H4: 28 | I4: https://korean.visitkorea.or.kr/detail/ms_detail.do?cotid=e413abf3-f8a7-486d-95fd-4fb12598aefc | J4: https://korean.visitkorea.or.kr/detail/rem_detail.do?cotid=ec1515b2-8a5c-45c9-99dc-a8c23fea9f9b | K4: 2023-10-31 등록 · 2024-02-19 수정 | L4: https://www.latimes.kr/news/articleView.html?idxno=51248 | M4: 2023-11-08 | N4: 46286 | O4: 특별·광역시: 원문에 구 표기 없음
A5: 서울 | C5: 롯데월드타워와 석촌호수 | D5: 야간경관 | E5: 연중 | F5: 수도권 | G5: 롯데월드타워와 석촌호수 | H5: 32 | I5: https://korean.visitkorea.or.kr/detail/ms_detail.do?cotid=7e26f7f5-dde8-4eab-b2e9-42d6d37aded1 | J5: https://korean.visitkorea.or.kr/detail/rem_detail.do?cotid=ec1515b2-8a5c-45c9-99dc-a8c23fea9f9b | K5: 2023-10-31 등록 · 2024-02-19 수정 | L5: https://www.latimes.kr/news/articleView.html?idxno=51248 | M5: 2023-11-08 | N5: 46286 | O5: 특별·광역시: 원문에 구 표기 없음
A6: 서울 | C6: 서울빛초롱축제와 광화문 광장마켓 | D6: 축제/이벤트 | E6: 계절형(겨울) | F6: 수도권 | G6: 서울빛초롱축제와 광화문 광장마켓 | H6: 55 | I6: https://korean.visitkorea.or.kr/detail/fes_detail.do?cotid=6ea28be2-79ab-4d79-b2a1-2aa9a0f04ae4 | J6: https://korean.visitkorea.or.kr/detail/rem_detail.do?cotid=ec1515b2-8a5c-45c9-99dc-a8c23fea9f9b | K6: 2023-10-31 등록 · 2024-02-19 수정 | L6: https://www.latimes.kr/news/articleView.html?idxno=51248 | M6: 2023-11-08 | N6: 46286 | O6: 특별·광역시: 원문에 구 표기 없음
A7: 서울 | C7: 세빛섬과 반포대교 달빛무지개분수 | D7: 축제/이벤트 | E7: 연중(동절기 제외) | F7: 수도권 | G7: 세빛섬과 반포대교 달빛무지개분수 | H7: 58 | I7: https://korean.visitkorea.or.kr/detail/ms_detail.do?cotid=b0e66d42-5c48-46f0-b6d7-1961fa3694d2 | J7: https://korean.visitkorea.or.kr/detail/rem_detail.do?cotid=ec1515b2-8a5c-45c9-99dc-a8c23fea9f9b | K7: 2023-10-31 등록 · 2024-02-19 수정 | L7: https://www.latimes.kr/news/articleView.html?idxno=51248 | M7: 2023-11-08 | N7: 46286 | O7: 특별·광역시: 원문에 구 표기 없음
A8: 서울 | C8: 한강불빛공연과 드론라이트쇼 | D8: 축제/이벤트 | E8: 계절형(봄·가을) | F8: 수도권 | G8: 한강불빛공연(드론라이트쇼) | H8: 93 | I8: https://korean.visitkorea.or.kr/detail/fes_detail.do?cotid=6d7bc7b7-aa29-453a-b903-f7e88e361c69 | J8: https://korean.visitkorea.or.kr/detail/rem_detail.do?cotid=ec1515b2-8a5c-45c9-99dc-a8c23fea9f9b | K8: 2023-10-31 등록 · 2024-02-19 수정 | L8: https://www.latimes.kr/news/articleView.html?idxno=51248 | M8: 2023-11-08 | N8: 46286 | O8: 특별·광역시: 원문에 구 표기 없음; 발표 표기와 다름
A9: 서울 | C9: 한양도성 낙산구간 | D9: 야간경관 | E9: 연중 | F9: 수도권 | G9: 한양도성 낙산구간 | H9: 94 | I9: https://korean.visitkorea.or.kr/detail/ms_detail.do?cotid=3c98e24b-9fb9-4ecf-b8a2-f26a5890748f | J9: https://korean.visitkorea.or.kr/detail/rem_detail.do?cotid=ec1515b2-8a5c-45c9-99dc-a8c23fea9f9b | K9: 2023-10-31 등록 · 2024-02-19 수정 | L9: https://www.latimes.kr/news/articleView.html?idxno=51248 | M9: 2023-11-08 | N9: 46286 | O9: 특별·광역시: 원문에 구 표기 없음
A10: 부산 | C10: 광복로 빛축제와 용두산공원 부산타워 | D10: 축제/이벤트 | E10: 계절형(겨울) | F10: 경상권 | G10: 광복로 빛축제와 용두산공원 부산타워 | H10: 7 | I10: (구석구석 상세 링크 없음) | J10: https://korean.visitkorea.or.kr/detail/rem_detail.do?cotid=ec1515b2-8a5c-45c9-99dc-a8c23fea9f9b | K10: 2023-10-31 등록 · 2024-02-19 수정 | L10: https://www.latimes.kr/news/articleView.html?idxno=51248 | M10: 2023-11-08 | N10: 46286 | O10: 특별·광역시: 원문에 구 표기 없음
A11: 부산 | C11: 광안리 M드론라이트쇼 | D11: 축제/이벤트 | E11: 연중 | F11: 경상권 | G11: 광안리 M드론라이트쇼 | H11: 8 | I11: https://korean.visitkorea.or.kr/detail/fes_detail.do?cotid=0c8f4aa0-b00e-4f6e-8974-b07503c6bf7d | J11: https://korean.visitkorea.or.kr/detail/rem_detail.do?cotid=ec1515b2-8a5c-45c9-99dc-a8c23fea9f9b | K11: 2023-10-31 등록 · 2024-02-19 수정 | L11: https://www.latimes.kr/news/articleView.html?idxno=51248 | M11: 2023-11-08 | N11: 46286 | O11: 특별·광역시: 원문에 구 표기 없음
A12: 부산 | C12: 다대포 낙조분수 | D12: 축제/이벤트 | E12: 연중(동절기 제외) | F12: 경상권 | G12: 다대포 낙조분수 | H12: 21 | I12: https://korean.visitkorea.or.kr/detail/ms_detail.do?cotid=0c3f5d56-ac09-4b34-915d-620035c29238 | J12: https://korean.visitkorea.or.kr/detail/rem_detail.do?cotid=ec1515b2-8a5c-45c9-99dc-a8c23fea9f9b | K12: 2023-10-31 등록 · 2024-02-19 수정 | L12: https://www.latimes.kr/news/articleView.html?idxno=51248 | M12: 2023-11-08 | N12: 46286 | O12: 특별·광역시: 원문에 구 표기 없음
A13: 부산 | C13: 달빛갈맷길걷기 | D13: 투어프로그램 | E13: 계절형(가을) | F13: 경상권 | G13: 달빛갈맷길걷기 | H13: 24 | I13: https://korean.visitkorea.or.kr/detail/ms_detail.do?cotid=2c53ae63-15ab-4f9e-9d66-2cbb008601d7 | J13: https://korean.visitkorea.or.kr/detail/rem_detail.do?cotid=ec1515b2-8a5c-45c9-99dc-a8c23fea9f9b | K13: 2023-10-31 등록 · 2024-02-19 수정 | L13: https://www.latimes.kr/news/articleView.html?idxno=51248 | M13: 2023-11-08 | N13: 46286 | O13: 특별·광역시: 원문에 구 표기 없음
... A37: 세종 | C37: 이응다리 금강보행교 | D37: 야간경관 | E37: 연중 | F37: 충청권 | G37: 이응다리 금강보행교 | H37: 81 | I37: https://korean.visitkorea.or.kr/detail/ms_detail.do?cotid=c95db770-ff20-4a0c-bf2b-c45bc2a6335d | J37: https://korean.visitkorea.or.kr/detail/rem_detail.do?cotid=ec1515b2-8a5c-45c9-99dc-a8c23fea9f9b | K37: 2023-10-31 등록 · 2024-02-19 수정 | L37: https://www.latimes.kr/news/articleView.html?idxno=51248 | M37: 2023-11-08 | N37: 46286 | O37: 특별·광역시: 원문에 구 표기 없음
A38: 경기 | B38: 가평 | C38: 아침고요수목원 | D38: 야간경관 | E38: 계절형(겨울) | F38: 수도권 | G38: 아침고요수목원 오색별빛정원전 | H38: 63 | I38: https://korean.visitkorea.or.kr/detail/ms_detail.do?cotid=e8660b54-9a93-4e87-9bb8-6ff0cb934b19 | J38: https://korean.visitkorea.or.kr/detail/rem_detail.do?cotid=ec1515b2-8a5c-45c9-99dc-a8c23fea9f9b | K38: 2023-10-31 등록 · 2024-02-19 수정 | L38: https://www.latimes.kr/news/articleView.html?idxno=51248 | M38: 2023-11-08 | N38: 46286 | O38: 발표 표기와 다름
A39: 경기 | B39: 고양 | C39: 행주가(街) 예술이야(夜) | D39: 축제/이벤트 | E39: 계절형(봄·가을) | F39: 수도권 | G39: 행주가(街)예술이야(夜) | H39: 99 | I39: https://korean.visitkorea.or.kr/detail/fes_detail.do?cotid=72c61e4f-6a63-48f0-b590-249463c372d3 | J39: https://korean.visitkorea.or.kr/detail/rem_detail.do?cotid=ec1515b2-8a5c-45c9-99dc-a8c23fea9f9b | K39: 2023-10-31 등록 · 2024-02-19 수정 | L39: https://www.latimes.kr/news/articleView.html?idxno=51248 | M39: 2023-11-08 | N39: 46286
A40: 경기 | B40: 광주 | C40: 남한산성 서문전망대 | D40: 야간경관 | E40: 연중 | F40: 수도권 | G40: 남한산성 서문전망대 | H40: 18 | I40: https://korean.visitkorea.or.kr/detail/ms_detail.do?cotid=37ce975b-c2bd-4ea1-83aa-cba93120a746 | J40: https://korean.visitkorea.or.kr/detail/rem_detail.do?cotid=ec1515b2-8a5c-45c9-99dc-a8c23fea9f9b | K40: 2023-10-31 등록 · 2024-02-19 수정 | L40: https://www.latimes.kr/news/articleView.html?idxno=51248 | M40: 2023-11-08 | N40: 46286
A41: 경기 | B41: 김포 | C41: 라베니체 | D41: 야간경관 | E41: 연중 | F41: 수도권 | G41: 라베니체 | H41: 31 | I41: https://korean.visitkorea.or.kr/detail/ms_detail.do?cotid=a62d5503-2483-4a7d-95d3-925bc8c067e3 | J41: https://korean.visitkorea.or.kr/detail/rem_detail.do?cotid=ec1515b2-8a5c-45c9-99dc-a8c23fea9f9b | K41: 2023-10-31 등록 · 2024-02-19 수정 | L41: https://www.latimes.kr/news/articleView.html?idxno=51248 | M41: 2023-11-08 | N41: 46286
A42: 경기 | B42: 용인 | C42: 에버랜드 리조트 | D42: 유원시설 | E42: 연중 | F42: 수도권 | G42: 에버랜드 리조트 | H42: 65 | I42: https://korean.visitkorea.or.kr/detail/ms_detail.do?cotid=7be6babf-e785-44da-9f4c-f7117f83ab23 | J42: https://korean.visitkorea.or.kr/detail/rem_detail.do?cotid=ec1515b2-8a5c-45c9-99dc-a8c23fea9f9b | K42: 2023-10-31 등록 · 2024-02-19 수정 | L42: https://www.latimes.kr/news/articleView.html?idxno=51248 | M42: 2023-11-08 | N42: 46286
A43: 경기 | B43: 화성 | C43: 동탄호수공원 루나쇼 | D43: 축제/이벤트 | E43: 연중(동절기 제외) | F43: 수도권 | G43: 동탄호수공원(루나쇼) | H43: 90 | I43: https://korean.visitkorea.or.kr/detail/ms_detail.do?cotid=9601cbf8-f259-4ad4-aea1-337c3c634fad | J43: https://korean.visitkorea.or.kr/detail/rem_detail.do?cotid=ec1515b2-8a5c-45c9-99dc-a8c23fea9f9b | K43: 2023-10-31 등록 · 2024-02-19 수정 | L43: https://www.latimes.kr/news/articleView.html?idxno=51248 | M43: 2023-11-08 | N43: 46286
A44: 강원 | B44: 고성 | C44: 미시령옛길 울산바위은하수 | D44: 야간경관 | E44: 연중 | F44: 강원권 | G44: 미시령옛길 울산바위은하수 | H44: 38 | I44: https://korean.visitkorea.or.kr/detail/ms_detail.do?cotid=eee5ecee-a493-4dc0-b82f-fe8f6c08dbd7 | J44: https://korean.visitkorea.or.kr/detail/rem_detail.do?cotid=ec1515b2-8a5c-45c9-99dc-a8c23fea9f9b | K44: 2023-10-31 등록 · 2024-02-19 수정 | L44: https://www.latimes.kr/news/articleView.html?idxno=51248 | M44: 2023-11-08 | N44: 46286
A45: 강원 | B45: 고성 | C45: 화진포 응봉노을 | D45: 야간경관 | E45: 연중 | F45: 강원권 | G45: 화진포 응봉노을 | H45: 100 | I45: https://korean.visitkorea.or.kr/detail/ms_detail.do?cotid=484e2027-1d0c-4a1b-ac33-0f7b61e02cde | J45: https://korean.visitkorea.or.kr/detail/rem_detail.do?cotid=ec1515b2-8a5c-45c9-99dc-a8c23fea9f9b | K45: 2023-10-31 등록 · 2024-02-19 수정 | L45: https://www.latimes.kr/news/articleView.html?idxno=51248 | M45: 2023-11-08 | N45: 46286
A46: 강원 | B46: 동해 | C46: 추암해변 | D46: 야간경관 | E46: 연중 | F46: 강원권 | G46: 추암해변 | H46: 88 | I46: https://korean.visitkorea.or.kr/detail/ms_detail.do?cotid=1545e671-68f3-4680-b8c1-8bfac00191eb | J46: https://korean.visitkorea.or.kr/detail/rem_detail.do?cotid=ec1515b2-8a5c-45c9-99dc-a8c23fea9f9b | K46: 2023-10-31 등록 · 2024-02-19 수정 | L46: https://www.latimes.kr/news/articleView.html?idxno=51248 | M46: 2023-11-08 | N46: 46286
A47: 강원 | B47: 영월 | C47: 별마로 천문대 | D47: 야간경관 | E47: 연중 | F47: 강원권 | G47: 별마로 천문대 | H47: 40 | I47: https://korean.visitkorea.or.kr/detail/ms_detail.do?cotid=0c661c4e-6d1f-4dd2-8264-3ffb88a6bbc2 | J47: https://korean.visitkorea.or.kr/detail/rem_detail.do?cotid=ec1515b2-8a5c-45c9-99dc-a8c23fea9f9b | K47: 2023-10-31 등록 · 2024-02-19 수정 | L47: https://www.latimes.kr/news/articleView.html?idxno=51248 | M47: 2023-11-08 | N47: 46286
A48: 강원 | B48: 원주 | C48: 나오라쇼 '나이트 오브 라이트' | D48: 축제/이벤트 | E48: 연중(동절기 제외) | F48: 강원권 | G48: 나오라쇼 '나이트 오브 라이트 | H48: 15 | I48: https://korean.visitkorea.or.kr/detail/fes_detail.do?cotid=5b14ce01-d312-46ed-8474-e041898e8b83 | J48: https://korean.visitkorea.or.kr/detail/rem_detail.do?cotid=ec1515b2-8a5c-45c9-99dc-a8c23fea9f9b | K48: 2023-10-31 등록 · 2024-02-19 수정 | L48: https://www.latimes.kr/news/articleView.html?idxno=51248 | M48: 2023-11-08 | N48: 46286
A49: 강원 | B49: 춘천 | C49: 삼악산 호수케이블카 | D49: 유원시설 | E49: 연중 | F49: 강원권 | G49: 삼악산 호수케이블카 | H49: 50 | I49: https://korean.visitkorea.or.kr/detail/ms_detail.do?cotid=8abcb54d-20cc-4712-99c0-2ccbc5370c51 | J49: https://korean.visitkorea.or.kr/detail/rem_detail.do?cotid=ec1515b2-8a5c-45c9-99dc-a8c23fea9f9b | K49: 2023-10-31 등록 · 2024-02-19 수정 | L49: https://www.latimes.kr/news/articleView.html?idxno=51248 | M49: 2023-11-08 | N49: 46286
A50: 강원 | B50: 춘천 | C50: 춘천대교분수 | D50: 축제/이벤트 | E50: 연중(동절기 제외) | F50: 강원권 | G50: 춘천대교분수 | H50: 89 | I50: https://korean.visitkorea.or.kr/detail/ms_detail.do?cotid=1ee41394-2efa-4ae3-9ffb-e8b29c94201b | J50: https://korean.visitkorea.or.kr/detail/rem_detail.do?cotid=ec1515b2-8a5c-45c9-99dc-a8c23fea9f9b | K50: 2023-10-31 등록 · 2024-02-19 수정 | L50: https://www.latimes.kr/news/articleView.html?idxno=51248 | M50: 2023-11-08 | N50: 46286
... A70: 전남 | B70: 광양 | C70: 구봉산 전망대와 광양만 야경 | D70: 야간경관 | E70: 연중 | F70: 전라권 | G70: 구봉산 전망대와 광양만 야경 | H70: 11 | I70: https://korean.visitkorea.or.kr/detail/ms_detail.do?cotid=3f5ee0d8-eae1-4506-bce0-b8e10436723b | J70: https://korean.visitkorea.or.kr/detail/rem_detail.do?cotid=ec1515b2-8a5c-45c9-99dc-a8c23fea9f9b | K70: 2023-10-31 등록 · 2024-02-19 수정 | L70: https://www.latimes.kr/news/articleView.html?idxno=51248 | M70: 2023-11-08 | N70: 46286
A71: 전남 | B71: 여수 | C71: 낭만포차거리 | D71: 야시장 | E71: 연중 | F71: 전라권 | G71: 종포해양공원 낭만포차거리 | H71: 19 | I71: https://korean.visitkorea.or.kr/detail/ms_detail.do?cotid=f3435a31-7d31-4808-adad-0696272126ab | J71: https://korean.visitkorea.or.kr/detail/rem_detail.do?cotid=ec1515b2-8a5c-45c9-99dc-a8c23fea9f9b | K71: 2023-10-31 등록 · 2024-02-19 수정 | L71: https://www.latimes.kr/news/articleView.html?idxno=51248 | M71: 2023-11-08 | N71: 46286 | O71: 발표 표기와 다름
A72: 전남 | B72: 여수 | C72: 빅오쇼 (Big-O Show) | D72: 축제/이벤트 | E72: 연중(동절기 제외) | F72: 전라권 | G72: 빅오쇼(Big-O Show) | H72: 45 | I72: https://korean.visitkorea.or.kr/detail/fes_detail.do?cotid=1201bb55-0ca1-47b2-bfc4-3c88f165613b | J72: https://korean.visitkorea.or.kr/detail/rem_detail.do?cotid=ec1515b2-8a5c-45c9-99dc-a8c23fea9f9b | K72: 2023-10-31 등록 · 2024-02-19 수정 | L72: https://www.latimes.kr/news/articleView.html?idxno=51248 | M72: 2023-11-08 | N72: 46286
A73: 전남 | B73: 여수 | C73: 여수 야간시티투어 '시간을 달리는 버스커' | D73: 투어프로그램 | E73: 연중(동절기 제외) | F73: 전라권 | G73: 여수야간시티투어'시간을 달리는버스커' | H73: 67 | I73: (구석구석 상세 링크 없음) | J73: https://korean.visitkorea.or.kr/detail/rem_detail.do?cotid=ec1515b2-8a5c-45c9-99dc-a8c23fea9f9b | K73: 2023-10-31 등록 · 2024-02-19 수정 | L73: https://www.latimes.kr/news/articleView.html?idxno=51248 | M73: 2023-11-08 | N73: 46286
A74: 전남 | B74: 여수 | C74: 여수밤바다 낭만버스킹 | D74: 축제/이벤트 | E74: 연중(동절기 제외) | F74: 전라권 | G74: 여수밤바다 낭만버스킹 | H74: 68 | I74: (구석구석 상세 링크 없음) | J74: https://korean.visitkorea.or.kr/detail/rem_detail.do?cotid=ec1515b2-8a5c-45c9-99dc-a8c23fea9f9b | K74: 2023-10-31 등록 · 2024-02-19 수정 | L74: https://www.latimes.kr/news/articleView.html?idxno=51248 | M74: 2023-11-08 | N74: 46286
A75: 전남 | B75: 영암 | C75: 영암달빛축제 | D75: 축제/이벤트 | E75: 계절형(가을) | F75: 전라권 | G75: 영암달빛축제 | H75: 70 | I75: (구석구석 상세 링크 없음) | J75: https://korean.visitkorea.or.kr/detail/rem_detail.do?cotid=ec1515b2-8a5c-45c9-99dc-a8c23fea9f9b | K75: 2023-10-31 등록 · 2024-02-19 수정 | L75: https://www.latimes.kr/news/articleView.html?idxno=51248 | M75: 2023-11-08 | N75: 46286
A76: 전남 | B76: 함평 | C76: 함평엑스포공원 | D76: 야간경관 | E76: 연중 | F76: 전라권 | G76: 함평엑스포공원 | H76: 96 | I76: https://korean.visitkorea.or.kr/detail/ms_detail.do?cotid=b9a1511c-98d9-4197-88dc-1a73aa3be740 | J76: https://korean.visitkorea.or.kr/detail/rem_detail.do?cotid=ec1515b2-8a5c-45c9-99dc-a8c23fea9f9b | K76: 2023-10-31 등록 · 2024-02-19 수정 | L76: https://www.latimes.kr/news/articleView.html?idxno=51248 | M76: 2023-11-08 | N76: 46286
A77: 전남 | B77: 해남 | C77: 우수영관광지 | D77: 야간경관 | E77: 연중 | F77: 전라권 | G77: 우수영관광지 | H77: 73 | I77: https://korean.visitkorea.or.kr/detail/ms_detail.do?cotid=7770a339-d073-4b39-ad71-b08eb7e5d308 | J77: https://korean.visitkorea.or.kr/detail/rem_detail.do?cotid=ec1515b2-8a5c-45c9-99dc-a8c23fea9f9b | K77: 2023-10-31 등록 · 2024-02-19 수정 | L77: https://www.latimes.kr/news/articleView.html?idxno=51248 | M77: 2023-11-08 | N77: 46286
A78: 경북 | B78: 경주 | C78: 대릉원 | D78: 야간경관 | E78: 연중 | F78: 경상권 | G78: 대릉원 | H78: 25 | I78: https://korean.visitkorea.or.kr/detail/ms_detail.do?cotid=6da54421-9ab9-4853-80d6-1eadbf0ad73b | J78: https://korean.visitkorea.or.kr/detail/rem_detail.do?cotid=ec1515b2-8a5c-45c9-99dc-a8c23fea9f9b | K78: 2023-10-31 등록 · 2024-02-19 수정 | L78: https://www.latimes.kr/news/articleView.html?idxno=51248 | M78: 2023-11-08 | N78: 46286
A79: 경북 | B79: 경주 | C79: 동궁과 월지 | D79: 야간경관 | E79: 연중 | F79: 경상권 | G79: 동궁과 월지 | H79: 29 | I79: https://korean.visitkorea.or.kr/detail/ms_detail.do?cotid=b046dbdc-67db-49f0-acca-fffa75befdf9 | J79: https://korean.visitkorea.or.kr/detail/rem_detail.do?cotid=ec1515b2-8a5c-45c9-99dc-a8c23fea9f9b | K79: 2023-10-31 등록 · 2024-02-19 수정 | L79: https://www.latimes.kr/news/articleView.html?idxno=51248 | M79: 2023-11-08 | N79: 46286
A80: 경북 | B80: 경주 | C80: 월정교 | D80: 야간경관 | E80: 연중 | F80: 경상권 | G80: 월정교 | H80: 78 | I80: https://korean.visitkorea.or.kr/detail/ms_detail.do?cotid=ec28bc85-95ba-4b58-a36d-3f02988eeae1 | J80: https://korean.visitkorea.or.kr/detail/rem_detail.do?cotid=ec1515b2-8a5c-45c9-99dc-a8c23fea9f9b | K80: 2023-10-31 등록 · 2024-02-19 수정 | L80: https://www.latimes.kr/news/articleView.html?idxno=51248 | M80: 2023-11-08 | N80: 46286
A81: 경북 | B81: 김천 | C81: 사명대사공원 | D81: 야간경관 | E81: 연중 | F81: 경상권 | G81: 사명대사공원 | H81: 47 | I81: https://korean.visitkorea.or.kr/detail/ms_detail.do?cotid=f2ddf685-03cd-4936-b819-71102e909961 | J81: https://korean.visitkorea.or.kr/detail/rem_detail.do?cotid=ec1515b2-8a5c-45c9-99dc-a8c23fea9f9b | K81: 2023-10-31 등록 · 2024-02-19 수정 | L81: https://www.latimes.kr/news/articleView.html?idxno=51248 | M81: 2023-11-08 | N81: 46286
A82: 경북 | B82: 김천 | C82: 연화지와 황산폭포 | D82: 야간경관 | E82: 연중 | F82: 경상권 | G82: 연화지와 황산폭포 | H82: 69 | I82: https://korean.visitkorea.or.kr/detail/ms_detail.do?cotid=bab0ebe9-31cc-4305-82a2-904542009326 | J82: https://korean.visitkorea.or.kr/detail/rem_detail.do?cotid=ec1515b2-8a5c-45c9-99dc-a8c23fea9f9b | K82: 2023-10-31 등록 · 2024-02-19 수정 | L82: https://www.latimes.kr/news/articleView.html?idxno=51248 | M82: 2023-11-08 | N82: 46286
...

Sheet 집계
A1: 시도 \ 유형 | B1: 야간경관 | C1: 축제/이벤트 | D1: 투어프로그램 | E1: 유원시설 | F1: 미디어아트 | G1: 야시장 | H1: 합계
A2: 서울 | B2: =COUNTIFS('100선'!$A:$A,$A2,'100선'!$D:$D,B$1) -> 4 | C2: =COUNTIFS('100선'!$A:$A,$A2,'100선'!$D:$D,C$1) -> 3 | D2: =COUNTIFS('100선'!$A:$A,$A2,'100선'!$D:$D,D$1) -> 0 | E2: =COUNTIFS('100선'!$A:$A,$A2,'100선'!$D:$D,E$1) -> 0 | F2: =COUNTIFS('100선'!$A:$A,$A2,'100선'!$D:$D,F$1) -> 1 | G2: =COUNTIFS('100선'!$A:$A,$A2,'100선'!$D:$D,G$1) -> 0 | H2: =SUM(B2:G2) -> 8
A3: 부산 | B3: =COUNTIFS('100선'!$A:$A,$A3,'100선'!$D:$D,B$1) -> 0 | C3: =COUNTIFS('100선'!$A:$A,$A3,'100선'!$D:$D,C$1) -> 6 | D3: =COUNTIFS('100선'!$A:$A,$A3,'100선'!$D:$D,D$1) -> 2 | E3: =COUNTIFS('100선'!$A:$A,$A3,'100선'!$D:$D,E$1) -> 0 | F3: =COUNTIFS('100선'!$A:$A,$A3,'100선'!$D:$D,F$1) -> 0 | G3: =COUNTIFS('100선'!$A:$A,$A3,'100선'!$D:$D,G$1) -> 0 | H3: =SUM(B3:G3) -> 8
A4: 대구 | B4: =COUNTIFS('100선'!$A:$A,$A4,'100선'!$D:$D,B$1) -> 0 | C4: =COUNTIFS('100선'!$A:$A,$A4,'100선'!$D:$D,C$1) -> 1 | D4: =COUNTIFS('100선'!$A:$A,$A4,'100선'!$D:$D,D$1) -> 1 | E4: =COUNTIFS('100선'!$A:$A,$A4,'100선'!$D:$D,E$1) -> 1 | F4: =COUNTIFS('100선'!$A:$A,$A4,'100선'!$D:$D,F$1) -> 0 | G4: =COUNTIFS('100선'!$A:$A,$A4,'100선'!$D:$D,G$1) -> 2 | H4: =SUM(B4:G4) -> 5
A5: 인천 | B5: =COUNTIFS('100선'!$A:$A,$A5,'100선'!$D:$D,B$1) -> 3 | C5: =COUNTIFS('100선'!$A:$A,$A5,'100선'!$D:$D,C$1) -> 0 | D5: =COUNTIFS('100선'!$A:$A,$A5,'100선'!$D:$D,D$1) -> 1 | E5: =COUNTIFS('100선'!$A:$A,$A5,'100선'!$D:$D,E$1) -> 1 | F5: =COUNTIFS('100선'!$A:$A,$A5,'100선'!$D:$D,F$1) -> 0 | G5: =COUNTIFS('100선'!$A:$A,$A5,'100선'!$D:$D,G$1) -> 0 | H5: =SUM(B5:G5) -> 5
A6: 광주 | B6: =COUNTIFS('100선'!$A:$A,$A6,'100선'!$D:$D,B$1) -> 1 | C6: =COUNTIFS('100선'!$A:$A,$A6,'100선'!$D:$D,C$1) -> 0 | D6: =COUNTIFS('100선'!$A:$A,$A6,'100선'!$D:$D,D$1) -> 1 | E6: =COUNTIFS('100선'!$A:$A,$A6,'100선'!$D:$D,E$1) -> 0 | F6: =COUNTIFS('100선'!$A:$A,$A6,'100선'!$D:$D,F$1) -> 0 | G6: =COUNTIFS('100선'!$A:$A,$A6,'100선'!$D:$D,G$1) -> 0 | H6: =SUM(B6:G6) -> 2
A7: 대전 | B7: =COUNTIFS('100선'!$A:$A,$A7,'100선'!$D:$D,B$1) -> 1 | C7: =COUNTIFS('100선'!$A:$A,$A7,'100선'!$D:$D,C$1) -> 2 | D7: =COUNTIFS('100선'!$A:$A,$A7,'100선'!$D:$D,D$1) -> 0 | E7: =COUNTIFS('100선'!$A:$A,$A7,'100선'!$D:$D,E$1) -> 0 | F7: =COUNTIFS('100선'!$A:$A,$A7,'100선'!$D:$D,F$1) -> 0 | G7: =COUNTIFS('100선'!$A:$A,$A7,'100선'!$D:$D,G$1) -> 0 | H7: =SUM(B7:G7) -> 3
A8: 울산 | B8: =COUNTIFS('100선'!$A:$A,$A8,'100선'!$D:$D,B$1) -> 1 | C8: =COUNTIFS('100선'!$A:$A,$A8,'100선'!$D:$D,C$1) -> 0 | D8: =COUNTIFS('100선'!$A:$A,$A8,'100선'!$D:$D,D$1) -> 0 | E8: =COUNTIFS('100선'!$A:$A,$A8,'100선'!$D:$D,E$1) -> 1 | F8: =COUNTIFS('100선'!$A:$A,$A8,'100선'!$D:$D,F$1) -> 1 | G8: =COUNTIFS('100선'!$A:$A,$A8,'100선'!$D:$D,G$1) -> 1 | H8: =SUM(B8:G8) -> 4
A9: 세종 | B9: =COUNTIFS('100선'!$A:$A,$A9,'100선'!$D:$D,B$1) -> 1 | C9: =COUNTIFS('100선'!$A:$A,$A9,'100선'!$D:$D,C$1) -> 0 | D9: =COUNTIFS('100선'!$A:$A,$A9,'100선'!$D:$D,D$1) -> 0 | E9: =COUNTIFS('100선'!$A:$A,$A9,'100선'!$D:$D,E$1) -> 0 | F9: =COUNTIFS('100선'!$A:$A,$A9,'100선'!$D:$D,F$1) -> 0 | G9: =COUNTIFS('100선'!$A:$A,$A9,'100선'!$D:$D,G$1) -> 0 | H9: =SUM(B9:G9) -> 1
A10: 경기 | B10: =COUNTIFS('100선'!$A:$A,$A10,'100선'!$D:$D,B$1) -> 3 | C10: =COUNTIFS('100선'!$A:$A,$A10,'100선'!$D:$D,C$1) -> 2 | D10: =COUNTIFS('100선'!$A:$A,$A10,'100선'!$D:$D,D$1) -> 0 | E10: =COUNTIFS('100선'!$A:$A,$A10,'100선'!$D:$D,E$1) -> 1 | F10: =COUNTIFS('100선'!$A:$A,$A10,'100선'!$D:$D,F$1) -> 0 | G10: =COUNTIFS('100선'!$A:$A,$A10,'100선'!$D:$D,G$1) -> 0 | H10: =SUM(B10:G10) -> 6
A11: 강원 | B11: =COUNTIFS('100선'!$A:$A,$A11,'100선'!$D:$D,B$1) -> 4 | C11: =COUNTIFS('100선'!$A:$A,$A11,'100선'!$D:$D,C$1) -> 2 | D11: =COUNTIFS('100선'!$A:$A,$A11,'100선'!$D:$D,D$1) -> 0 | E11: =COUNTIFS('100선'!$A:$A,$A11,'100선'!$D:$D,E$1) -> 1 | F11: =COUNTIFS('100선'!$A:$A,$A11,'100선'!$D:$D,F$1) -> 0 | G11: =COUNTIFS('100선'!$A:$A,$A11,'100선'!$D:$D,G$1) -> 0 | H11: =SUM(B11:G11) -> 7
A12: 충북 | B12: =COUNTIFS('100선'!$A:$A,$A12,'100선'!$D:$D,B$1) -> 1 | C12: =COUNTIFS('100선'!$A:$A,$A12,'100선'!$D:$D,C$1) -> 0 | D12: =COUNTIFS('100선'!$A:$A,$A12,'100선'!$D:$D,D$1) -> 1 | E12: =COUNTIFS('100선'!$A:$A,$A12,'100선'!$D:$D,E$1) -> 0 | F12: =COUNTIFS('100선'!$A:$A,$A12,'100선'!$D:$D,F$1) -> 1 | G12: =COUNTIFS('100선'!$A:$A,$A12,'100선'!$D:$D,G$1) -> 0 | H12: =SUM(B12:G12) -> 3
A13: 충남 | B13: =COUNTIFS('100선'!$A:$A,$A13,'100선'!$D:$D,B$1) -> 4 | C13: =COUNTIFS('100선'!$A:$A,$A13,'100선'!$D:$D,C$1) -> 2 | D13: =COUNTIFS('100선'!$A:$A,$A13,'100선'!$D:$D,D$1) -> 0 | E13: =COUNTIFS('100선'!$A:$A,$A13,'100선'!$D:$D,E$1) -> 1 | F13: =COUNTIFS('100선'!$A:$A,$A13,'100선'!$D:$D,F$1) -> 1 | G13: =COUNTIFS('100선'!$A:$A,$A13,'100선'!$D:$D,G$1) -> 0 | H13: =SUM(B13:G13) -> 8
... A18: 제주 | B18: =COUNTIFS('100선'!$A:$A,$A18,'100선'!$D:$D,B$1) -> 1 | C18: =COUNTIFS('100선'!$A:$A,$A18,'100선'!$D:$D,C$1) -> 0 | D18: =COUNTIFS('100선'!$A:$A,$A18,'100선'!$D:$D,D$1) -> 0 | E18: =COUNTIFS('100선'!$A:$A,$A18,'100선'!$D:$D,E$1) -> 0 | F18: =COUNTIFS('100선'!$A:$A,$A18,'100선'!$D:$D,F$1) -> 0 | G18: =COUNTIFS('100선'!$A:$A,$A18,'100선'!$D:$D,G$1) -> 0 | H18: =SUM(B18:G18) -> 1
A19: 합계 | B19: =SUM(B2:B18) -> 37 | C19: =SUM(C2:C18) -> 34 | D19: =SUM(D2:D18) -> 10 | E19: =SUM(E2:E18) -> 7 | F19: =SUM(F2:F18) -> 7 | G19: =SUM(G2:G18) -> 5 | H19: =SUM(H2:H18) -> 100
A21: 검증: 전체 행 수 | B21: =COUNTA('100선'!C:C)-1 -> 100 | C21: ← 100이어야 함
A23: 경북 시군 | B23: 명소 수 | C23: 명소명(참고)
A24: 경주 | B24: =COUNTIFS('100선'!$A:$A,"경북",'100선'!$B:$B,$A24) -> 3 | C24: 대릉원, 동궁과 월지, 월정교
A25: 문경 | B25: =COUNTIFS('100선'!$A:$A,"경북",'100선'!$B:$B,$A25) -> 3 | C25: 문경새재 달빛사랑여행, 은성탄광 달빛여행, 전설의 귀신 in 문경
A26: 포항 | B26: =COUNTIFS('100선'!$A:$A,"경북",'100선'!$B:$B,$A26) -> 3 | C26: 구룡포 피어라계단 미디어아트, 스페이스워크, 포항 국제불빛축제
A27: 김천 | B27: =COUNTIFS('100선'!$A:$A,"경북",'100선'!$B:$B,$A27) -> 2 | C27: 사명대사공원, 연화지와 황산폭포
A28: 안동 | B28: =COUNTIFS('100선'!$A:$A,"경북",'100선'!$B:$B,$A28) -> 2 | C28: 선유줄불놀이, 월영교와 문보트
A29: 성주 | B29: =COUNTIFS('100선'!$A:$A,"경북",'100선'!$B:$B,$A29) -> 1 | C29: 성밖숲
A30: 칠곡 | B30: =COUNTIFS('100선'!$A:$A,"경북",'100선'!$B:$B,$A30) -> 1 | C30: 가산산성야행
A32: 운영기간 | B32: 명소 수
A33: 계절형(가을) | B33: =COUNTIFS('100선'!$E:$E,$A33) -> 10
A34: 계절형(겨울) | B34: =COUNTIFS('100선'!$E:$E,$A34) -> 7
A35: 계절형(봄) | B35: =COUNTIFS('100선'!$E:$E,$A35) -> 3
A36: 계절형(봄·가을) | B36: =COUNTIFS('100선'!$E:$E,$A36) -> 2
A37: 계절형(여름) | B37: =COUNTIFS('100선'!$E:$E,$A37) -> 6
A38: 계절형(여름·가을) | B38: =COUNTIFS('100선'!$E:$E,$A38) -> 3
A39: 연중 | B39: =COUNTIFS('100선'!$E:$E,$A39) -> 59
A40: 연중(동절기 제외) | B40: =COUNTIFS('100선'!$E:$E,$A40) -> 10

Sheet 출처·메모
A1: 구분 | B1: 내용
A2: 정식 명칭 | B2: 「대한민국 밤밤곡곡 100」(문화체육관광부·한국관광공사, 2023-11-08 발표). 작업 목록의 '야간관광 명소 100선'과 같은 것.
A3: 출처 1 (시도·시군·명소명) | B3: 대한민국 구석구석 '[야간관광지] 밤이 더 아름다운 대한민국! 대한민국 밤밤곡곡 100' https://korean.visitkorea.or.kr/detail/rem_detail.do?cotid=ec1515b2-8a5c-45c9-99dc-a8c23fea9f9b (등록 2023-10-31, 수정 2024-02-19). 페이지의 '전체' 탭 100곳을 그대로 옮김.
A4: 출처 2 (유형·운영기간·권역) | B4: Landscape Times 2023-11-08 김지운 기자, 문체부 발표 표 전재 https://www.latimes.kr/news/articleView.html?idxno=51248. 공식 페이지에는 유형·기간 열이 없어 이 표로 보완.
A5: 결합 방법 | B5: 같은 시도 안에서 명소명을 공백·기호 제거 후 일치 → 포함관계로 1:1 매칭(100건 전부 매칭, 수동 2건: DDP=동대문디자인플라자, 한강불빛공연과 드론라이트쇼=한강불빛공연(드론라이트쇼)). 발표 표기와 이름이 다른 곳은 비고에 '발표 표기와 다름'.
A6: 시군 빈칸 | B6: 서울·부산·대구·인천·광주·대전·울산·세종은 공식 목록에 구가 없어 비워 둠(추정하지 않음).
A7: 주의 | B7: Landscape Times 표만 보고 시군을 짐작하면 틀린다: 예) 나오라쇼 '나이트 오브 라이트'는 공식 목록상 강원 '원주'.
A8: 기존 파일 | B8: 조사/12_야간관광명소100선.csv(2026-09-14, 안동·비교 도시 11행)는 이 파일의 부분집합이다.
A9: 조사일 | B9: 2026-09-21
