Workbook

Sheet 프로그램_일정
A1: 프로그램명 | B1: 유형 | C1: 장소 | D1: 날짜 | E1: 시작시각 | F1: 종료시각 | G1: 요금 | H1: 예약 여부 | I1: 야간(18시 이후 시작) | J1: 21시 이후 종료 | K1: 공식분류 | L1: 권역 | M1: 요일 | N1: 출처 URL | O1: 게시일 | P1: 조사일 | Q1: 비고
A2: 이매 장가가는 날 | B2: 공연 | C2: 탈춤공원 | D2: 46289 | E2: 0.54166667 | F2: 0.58333333 | G2: 공식 안내에 표기 없음 | H2: 공식 안내에 표기 없음 | I2: =IF(E2>=TIME(18,0,0),"Y","") | J2: =IF(AND(ISNUMBER(F2),F2>TIME(21,0,0)),"Y","") | K2: 현장 이벤트 | L2: 탈춤공원 | M2: =CHOOSE(WEEKDAY(D2),"일","월","화","수","목","금","토") -> 목 | N2: https://www.maskdance.com/2024/sub7/sub1.asp?ymd=20260924 | O2: 페이지 게시일 미표기(리플릿 PDF 2026-09-21 생성) | P2: 46286
A3: 탈춤외전 | B3: 공연 | C3: 안동시전역 북문시장 | D3: 46289 | E3: 0.54166667 | F3: 0.625 | G3: 공식 안내에 표기 없음 | H3: 공식 안내에 표기 없음 | I3: =IF(E3>=TIME(18,0,0),"Y","") | J3: =IF(AND(ISNUMBER(F3),F3>TIME(21,0,0)),"Y","") | K3: 현장 이벤트 | L3: 시장·기타(안동시 전역) | M3: =CHOOSE(WEEKDAY(D3),"일","월","화","수","목","금","토") -> 목 | N3: https://www.maskdance.com/2024/sub7/sub1.asp?ymd=20260924 | O3: 페이지 게시일 미표기(리플릿 PDF 2026-09-21 생성) | P3: 46286
A4: 감사랑 파워점핑 줄넘기 | B4: 공연 | C4: 탈춤공원 탈춤공원무대 | D4: 46289 | E4: 0.5625 | F4: 0.58333333 | G4: 공식 안내에 표기 없음 | H4: 공식 안내에 표기 없음 | I4: =IF(E4>=TIME(18,0,0),"Y","") | J4: =IF(AND(ISNUMBER(F4),F4>TIME(21,0,0)),"Y","") | K4: 공연-자유참가작 | L4: 탈춤공원 | M4: =CHOOSE(WEEKDAY(D4),"일","월","화","수","목","금","토") -> 목 | N4: https://www.maskdance.com/2024/sub7/sub1.asp?ymd=20260924 | O4: 페이지 게시일 미표기(리플릿 PDF 2026-09-21 생성) | P4: 46286
A5: 어치브 | B5: 공연 | C5: 탈춤공원 탈춤공원무대 | D5: 46289 | E5: 0.58333333 | F5: 0.625 | G5: 공식 안내에 표기 없음 | H5: 공식 안내에 표기 없음 | I5: =IF(E5>=TIME(18,0,0),"Y","") | J5: =IF(AND(ISNUMBER(F5),F5>TIME(21,0,0)),"Y","") | K5: 공연-자유참가작 | L5: 탈춤공원 | M5: =CHOOSE(WEEKDAY(D5),"일","월","화","수","목","금","토") -> 목 | N5: https://www.maskdance.com/2024/sub7/sub1.asp?ymd=20260924 | O5: 페이지 게시일 미표기(리플릿 PDF 2026-09-21 생성) | P5: 46286
A6: 일본나라현 문화교류 | B6: 미분류 | C6: 중앙선1942 메인무대 | D6: 46289 | E6: 0.58333333 | F6: 0.70833333 | G6: 공식 안내에 표기 없음 | H6: 공식 안내에 표기 없음 | I6: =IF(E6>=TIME(18,0,0),"Y","") | J6: =IF(AND(ISNUMBER(F6),F6>TIME(21,0,0)),"Y","") | K6: 미분류(분류 목록에 없음) | L6: 중앙선1942(안동역) | M6: =CHOOSE(WEEKDAY(D6),"일","월","화","수","목","금","토") -> 목 | N6: https://www.maskdance.com/2024/sub7/sub1.asp?ymd=20260924 | O6: 페이지 게시일 미표기(리플릿 PDF 2026-09-21 생성) | P6: 46286
A7: 이매 장가가는 날 | B7: 공연 | C7: 탈춤공원 | D7: 46289 | E7: 0.625 | F7: 0.66666667 | G7: 공식 안내에 표기 없음 | H7: 공식 안내에 표기 없음 | I7: =IF(E7>=TIME(18,0,0),"Y","") | J7: =IF(AND(ISNUMBER(F7),F7>TIME(21,0,0)),"Y","") | K7: 현장 이벤트 | L7: 탈춤공원 | M7: =CHOOSE(WEEKDAY(D7),"일","월","화","수","목","금","토") -> 목 | N7: https://www.maskdance.com/2024/sub7/sub1.asp?ymd=20260924 | O7: 페이지 게시일 미표기(리플릿 PDF 2026-09-21 생성) | P7: 46286
A8: 하회별신굿탈놀이 청소년 아카데미 | B8: 공연 | C8: 탈춤공원 탈춤공원무대 | D8: 46289 | E8: 0.625 | F8: 0.66666667 | G8: 공식 안내에 표기 없음 | H8: 공식 안내에 표기 없음 | I8: =IF(E8>=TIME(18,0,0),"Y","") | J8: =IF(AND(ISNUMBER(F8),F8>TIME(21,0,0)),"Y","") | K8: 공연-자유참가작 | L8: 탈춤공원 | M8: =CHOOSE(WEEKDAY(D8),"일","월","화","수","목","금","토") -> 목 | N8: https://www.maskdance.com/2024/sub7/sub1.asp?ymd=20260924 | O8: 페이지 게시일 미표기(리플릿 PDF 2026-09-21 생성) | P8: 46286
A9: 용인대 힘찬태권도 | B9: 공연 | C9: 탈춤공원 탈춤공원무대 | D9: 46289 | E9: 0.66666667 | F9: 0.70833333 | G9: 공식 안내에 표기 없음 | H9: 공식 안내에 표기 없음 | I9: =IF(E9>=TIME(18,0,0),"Y","") | J9: =IF(AND(ISNUMBER(F9),F9>TIME(21,0,0)),"Y","") | K9: 공연-자유참가작 | L9: 탈춤공원 | M9: =CHOOSE(WEEKDAY(D9),"일","월","화","수","목","금","토") -> 목 | N9: https://www.maskdance.com/2024/sub7/sub1.asp?ymd=20260924 | O9: 페이지 게시일 미표기(리플릿 PDF 2026-09-21 생성) | P9: 46286
A10: 이매 장가가는 날 | B10: 공연 | C10: 탈춤공원 | D10: 46289 | E10: 0.70833333 | F10: 0.75 | G10: 공식 안내에 표기 없음 | H10: 공식 안내에 표기 없음 | I10: =IF(E10>=TIME(18,0,0),"Y","") | J10: =IF(AND(ISNUMBER(F10),F10>TIME(21,0,0)),"Y","") | K10: 현장 이벤트 | L10: 탈춤공원 | M10: =CHOOSE(WEEKDAY(D10),"일","월","화","수","목","금","토") -> 목 | N10: https://www.maskdance.com/2024/sub7/sub1.asp?ymd=20260924 | O10: 페이지 게시일 미표기(리플릿 PDF 2026-09-21 생성) | P10: 46286
A11: 풍물굿패 참넋 | B11: 공연 | C11: 중앙선1942 메인무대 | D11: 46289 | E11: 0.79166667 | F11: 0.83333333 | G11: 공식 안내에 표기 없음 | H11: 공식 안내에 표기 없음 | I11: =IF(E11>=TIME(18,0,0),"Y","") -> Y | J11: =IF(AND(ISNUMBER(F11),F11>TIME(21,0,0)),"Y","") | K11: 공연-자유참가작 | L11: 중앙선1942(안동역) | M11: =CHOOSE(WEEKDAY(D11),"일","월","화","수","목","금","토") -> 목 | N11: https://www.maskdance.com/2024/sub7/sub1.asp?ymd=20260924 | O11: 페이지 게시일 미표기(리플릿 PDF 2026-09-21 생성) | P11: 46286
A12: 영남가요제 | B12: 공연 | C12: 탈춤공원 탈춤공원무대 | D12: 46289 | E12: 0.79166667 | F12: 0.875 | G12: 공식 안내에 표기 없음 | H12: 공식 안내에 표기 없음 | I12: =IF(E12>=TIME(18,0,0),"Y","") -> Y | J12: =IF(AND(ISNUMBER(F12),F12>TIME(21,0,0)),"Y","") | K12: 연계 | L12: 탈춤공원 | M12: =CHOOSE(WEEKDAY(D12),"일","월","화","수","목","금","토") -> 목 | N12: https://www.maskdance.com/2024/sub7/sub1.asp?ymd=20260924 | O12: 페이지 게시일 미표기(리플릿 PDF 2026-09-21 생성) | P12: 46286
A13: 갓쓰고 탈쓰고 런웨이 | B13: 미분류 | C13: 중앙선1942 메인무대 | D13: 46289 | E13: 0.83333333 | F13: 0.875 | G13: 공식 안내에 표기 없음 | H13: 공식 안내에 표기 없음 | I13: =IF(E13>=TIME(18,0,0),"Y","") -> Y | J13: =IF(AND(ISNUMBER(F13),F13>TIME(21,0,0)),"Y","") | K13: 미분류(분류 목록에 없음) | L13: 중앙선1942(안동역) | M13: =CHOOSE(WEEKDAY(D13),"일","월","화","수","목","금","토") -> 목 | N13: https://www.maskdance.com/2024/sub7/sub1.asp?ymd=20260924 | O13: 페이지 게시일 미표기(리플릿 PDF 2026-09-21 생성) | P13: 46286
A14: 어린이대상 프로그램 | B14: 미분류 | C14: 원도심 왔니껴무대 | D14: 46290 | E14: 0.45833333 | F14: 0.5 | G14: 공식 안내에 표기 없음 | H14: 공식 안내에 표기 없음 | I14: =IF(E14>=TIME(18,0,0),"Y","") | J14: =IF(AND(ISNUMBER(F14),F14>TIME(21,0,0)),"Y","") | K14: 미분류(분류 목록에 없음) | L14: 원도심 | M14: =CHOOSE(WEEKDAY(D14),"일","월","화","수","목","금","토") -> 금 | N14: https://www.maskdance.com/2024/sub7/sub1.asp?ymd=20260925 | O14: 페이지 게시일 미표기(리플릿 PDF 2026-09-21 생성) | P14: 46286
A15: 강신마당 | B15: 공연 | C15: 하회마을 | D15: 46290 | E15: 0.45833333 | F15: 0.5 | G15: 공식 안내에 표기 없음 | H15: 공식 안내에 표기 없음 | I15: =IF(E15>=TIME(18,0,0),"Y","") | J15: =IF(AND(ISNUMBER(F15),F15>TIME(21,0,0)),"Y","") | K15: 관광지 프로그램(하회마을) | L15: 하회마을 | M15: =CHOOSE(WEEKDAY(D15),"일","월","화","수","목","금","토") -> 금 | N15: https://www.maskdance.com/2024/sub7/sub1.asp?ymd=20260925 | O15: 페이지 게시일 미표기(리플릿 PDF 2026-09-21 생성) | P15: 46286 | Q15: 하회마을 입장료 별도 여부는 확인 필요
A16: 탈랄라댄스배우기 | B16: 체험 | C16: 탈춤공원 버스킹무대 | D16: 46290 | E16: 0.47916667 | F16: 0.5 | G16: 공식 안내에 표기 없음 | H16: 공식 안내에 표기 없음 | I16: =IF(E16>=TIME(18,0,0),"Y","") | J16: =IF(AND(ISNUMBER(F16),F16>TIME(21,0,0)),"Y","") | K16: 체험 | L16: 탈춤공원 | M16: =CHOOSE(WEEKDAY(D16),"일","월","화","수","목","금","토") -> 금 | N16: https://www.maskdance.com/2024/sub7/sub1.asp?ymd=20260925 | O16: 페이지 게시일 미표기(리플릿 PDF 2026-09-21 생성) | P16: 46286
A17: 길놀이 | B17: 공연 | C17: 하회마을 | D17: 46290 | E17: 0.5 | F17: 0.54166667 | G17: 공식 안내에 표기 없음 | H17: 공식 안내에 표기 없음 | I17: =IF(E17>=TIME(18,0,0),"Y","") | J17: =IF(AND(ISNUMBER(F17),F17>TIME(21,0,0)),"Y","") | K17: 관광지 프로그램(하회마을) | L17: 하회마을 | M17: =CHOOSE(WEEKDAY(D17),"일","월","화","수","목","금","토") -> 금 | N17: https://www.maskdance.com/2024/sub7/sub1.asp?ymd=20260925 | O17: 페이지 게시일 미표기(리플릿 PDF 2026-09-21 생성) | P17: 46286 | Q17: 하회마을 입장료 별도 여부는 확인 필요
A18: 탈춤외전 | B18: 공연 | C18: 안동시전역 신시장 | D18: 46290 | E18: 0.54166667 | F18: 0.625 | G18: 공식 안내에 표기 없음 | H18: 공식 안내에 표기 없음 | I18: =IF(E18>=TIME(18,0,0),"Y","") | J18: =IF(AND(ISNUMBER(F18),F18>TIME(21,0,0)),"Y","") | K18: 현장 이벤트 | L18: 시장·기타(안동시 전역) | M18: =CHOOSE(WEEKDAY(D18),"일","월","화","수","목","금","토") -> 금 | N18: https://www.maskdance.com/2024/sub7/sub1.asp?ymd=20260925 | O18: 페이지 게시일 미표기(리플릿 PDF 2026-09-21 생성) | P18: 46286
A19: 탈춤따라배우기 | B19: 체험 | C19: 탈춤공원 버스킹무대 | D19: 46290 | E19: 0.58333333 | F19: 0.60416667 | G19: 공식 안내에 표기 없음 | H19: 공식 안내에 표기 없음 | I19: =IF(E19>=TIME(18,0,0),"Y","") | J19: =IF(AND(ISNUMBER(F19),F19>TIME(21,0,0)),"Y","") | K19: 체험 | L19: 탈춤공원 | M19: =CHOOSE(WEEKDAY(D19),"일","월","화","수","목","금","토") -> 금 | N19: https://www.maskdance.com/2024/sub7/sub1.asp?ymd=20260925 | O19: 페이지 게시일 미표기(리플릿 PDF 2026-09-21 생성) | P19: 46286
A20: 하회별신굿 탈놀이 | B20: 공연 | C20: 하회마을 전수회관 | D20: 46290 | E20: 0.58333333 | F20: 0.625 | G20: 공식 안내에 표기 없음 | H20: 공식 안내에 표기 없음 | I20: =IF(E20>=TIME(18,0,0),"Y","") | J20: =IF(AND(ISNUMBER(F20),F20>TIME(21,0,0)),"Y","") | K20: 관광지 프로그램(하회마을) | L20: 하회마을 | M20: =CHOOSE(WEEKDAY(D20),"일","월","화","수","목","금","토") -> 금 | N20: https://www.maskdance.com/2024/sub7/sub1.asp?ymd=20260925 | O20: 페이지 게시일 미표기(리플릿 PDF 2026-09-21 생성) | P20: 46286 | Q20: 하회마을 입장료 별도 여부는 확인 필요
A21: 일본나라현 문화교류 | B21: 미분류 | C21: 탈춤공원 탈춤공원무대 | D21: 46290 | E21: 0.58333333 | F21: 0.70833333 | G21: 공식 안내에 표기 없음 | H21: 공식 안내에 표기 없음 | I21: =IF(E21>=TIME(18,0,0),"Y","") | J21: =IF(AND(ISNUMBER(F21),F21>TIME(21,0,0)),"Y","") | K21: 미분류(분류 목록에 없음) | L21: 탈춤공원 | M21: =CHOOSE(WEEKDAY(D21),"일","월","화","수","목","금","토") -> 금 | N21: https://www.maskdance.com/2024/sub7/sub1.asp?ymd=20260925 | O21: 페이지 게시일 미표기(리플릿 PDF 2026-09-21 생성) | P21: 46286
A22: 시민참여프로그램 | B22: 미분류 | C22: 원도심 왔니껴무대 | D22: 46290 | E22: 0.58333333 | F22: 0.83333333 | G22: 공식 안내에 표기 없음 | H22: 공식 안내에 표기 없음 | I22: =IF(E22>=TIME(18,0,0),"Y","") | J22: =IF(AND(ISNUMBER(F22),F22>TIME(21,0,0)),"Y","") | K22: 미분류(분류 목록에 없음) | L22: 원도심 | M22: =CHOOSE(WEEKDAY(D22),"일","월","화","수","목","금","토") -> 금 | N22: https://www.maskdance.com/2024/sub7/sub1.asp?ymd=20260925 | O22: 페이지 게시일 미표기(리플릿 PDF 2026-09-21 생성) | P22: 46286
A23: 탈랄라댄스배우기 | B23: 체험 | C23: 탈춤공원 버스킹무대 | D23: 46290 | E23: 0.60416667 | F23: 0.625 | G23: 공식 안내에 표기 없음 | H23: 공식 안내에 표기 없음 | I23: =IF(E23>=TIME(18,0,0),"Y","") | J23: =IF(AND(ISNUMBER(F23),F23>TIME(21,0,0)),"Y","") | K23: 체험 | L23: 탈춤공원 | M23: =CHOOSE(WEEKDAY(D23),"일","월","화","수","목","금","토") -> 금 | N23: https://www.maskdance.com/2024/sub7/sub1.asp?ymd=20260925 | O23: 페이지 게시일 미표기(리플릿 PDF 2026-09-21 생성) | P23: 46286
A24: 탈랄라댄스배우기 | B24: 체험 | C24: 탈춤공원 버스킹무대 | D24: 46290 | E24: 0.66666667 | F24: 0.6875 | G24: 공식 안내에 표기 없음 | H24: 공식 안내에 표기 없음 | I24: =IF(E24>=TIME(18,0,0),"Y","") | J24: =IF(AND(ISNUMBER(F24),F24>TIME(21,0,0)),"Y","") | K24: 체험 | L24: 탈춤공원 | M24: =CHOOSE(WEEKDAY(D24),"일","월","화","수","목","금","토") -> 금 | N24: https://www.maskdance.com/2024/sub7/sub1.asp?ymd=20260925 | O24: 페이지 게시일 미표기(리플릿 PDF 2026-09-21 생성) | P24: 46286
A25: 하회별신굿 탈놀이 | B25: 공연 | C25: 탈춤공연장 | D25: 46290 | E25: 0.6875 | F25: 0.72916667 | G25: 유료: 탈춤공연장 관람권 현장 일반 8,000원·학생 6,000원(무료: 6세 이하·기초수급자·장애인·국가유공자) | H25: 사전예매(8/18~9/17) 종료 → 축제 기간 지정 매표소에서 구매·교환(1매 1회, 공연 후 전원 퇴장) | I25: =IF(E25>=TIME(18,0,0),"Y","") | J25: =IF(AND(ISNUMBER(F25),F25>TIME(21,0,0)),"Y","") | K25: 공연-한국탈춤 | L25: 탈춤공원 | M25: =CHOOSE(WEEKDAY(D25),"일","월","화","수","목","금","토") -> 금 | N25: https://www.maskdance.com/2024/sub7/sub1.asp?ymd=20260925 | O25: 페이지 게시일 미표기(리플릿 PDF 2026-09-21 생성) | P25: 46286 | Q25: 요금 적용 무대: 공식 입장권 안내엔 무대 미명시, 판매처 상품명 '탈춤공연장 공연관람권'(2025 NOL)으로 확인
A26: 허만성 | B26: 공연 | C26: 탈춤공원 탈춤공원무대 | D26: 46290 | E26: 0.70833333 | F26: 0.75 | G26: 공식 안내에 표기 없음 | H26: 공식 안내에 표기 없음 | I26: =IF(E26>=TIME(18,0,0),"Y","") | J26: =IF(AND(ISNUMBER(F26),F26>TIME(21,0,0)),"Y","") | K26: 공연-자유참가작 | L26: 탈춤공원 | M26: =CHOOSE(WEEKDAY(D26),"일","월","화","수","목","금","토") -> 금 | N26: https://www.maskdance.com/2024/sub7/sub1.asp?ymd=20260925 | O26: 페이지 게시일 미표기(리플릿 PDF 2026-09-21 생성) | P26: 46286
A27: 글로벌 마스크 퍼레이드 | B27: 공연 | C27: 중앙선1942 메인무대 | D27: 46290 | E27: 0.75 | F27: 0.79166667 | G27: 공식 안내에 표기 없음 | H27: 공식 안내에 표기 없음 | I27: =IF(E27>=TIME(18,0,0),"Y","") -> Y | J27: =IF(AND(ISNUMBER(F27),F27>TIME(21,0,0)),"Y","") | K27: 퍼레이드 | L27: 중앙선1942(안동역) | M27: =CHOOSE(WEEKDAY(D27),"일","월","화","수","목","금","토") -> 금 | N27: https://www.maskdance.com/2024/sub7/sub1.asp?ymd=20260925 | O27: 페이지 게시일 미표기(리플릿 PDF 2026-09-21 생성) | P27: 46286
A28: 안동가야금연주단 | B28: 공연 | C28: 탈춤공원 탈춤공원무대 | D28: 46290 | E28: 0.77083333 | F28: 0.79166667 | G28: 공식 안내에 표기 없음 | H28: 공식 안내에 표기 없음 | I28: =IF(E28>=TIME(18,0,0),"Y","") -> Y | J28: =IF(AND(ISNUMBER(F28),F28>TIME(21,0,0)),"Y","") | K28: 공연-자유참가작 | L28: 탈춤공원 | M28: =CHOOSE(WEEKDAY(D28),"일","월","화","수","목","금","토") -> 금 | N28: https://www.maskdance.com/2024/sub7/sub1.asp?ymd=20260925 | O28: 페이지 게시일 미표기(리플릿 PDF 2026-09-21 생성) | P28: 46286
A29: 권누리 | B29: 공연 | C29: 탈춤공원 탈춤공원무대 | D29: 46290 | E29: 0.79166667 | F29: 0.8125 | G29: 공식 안내에 표기 없음 | H29: 공식 안내에 표기 없음 | I29: =IF(E29>=TIME(18,0,0),"Y","") -> Y | J29: =IF(AND(ISNUMBER(F29),F29>TIME(21,0,0)),"Y","") | K29: 공연-자유참가작 | L29: 탈춤공원 | M29: =CHOOSE(WEEKDAY(D29),"일","월","화","수","목","금","토") -> 금 | N29: https://www.maskdance.com/2024/sub7/sub1.asp?ymd=20260925 | O29: 페이지 게시일 미표기(리플릿 PDF 2026-09-21 생성) | P29: 46286
A30: 개막식 | B30: 공연 | C30: 중앙선1942 메인무대 | D30: 46290 | E30: 0.79166667 | F30: 0.875 | G30: 공식 안내에 표기 없음 | H30: 공식 안내에 표기 없음 | I30: =IF(E30>=TIME(18,0,0),"Y","") -> Y | J30: =IF(AND(ISNUMBER(F30),F30>TIME(21,0,0)),"Y","") | K30: 개막식/폐막식 | L30: 중앙선1942(안동역) | M30: =CHOOSE(WEEKDAY(D30),"일","월","화","수","목","금","토") -> 금 | N30: https://www.maskdance.com/2024/sub7/sub1.asp?ymd=20260925 | O30: 페이지 게시일 미표기(리플릿 PDF 2026-09-21 생성) | P30: 46286
A31: 우리동네 친구들 | B31: 공연 | C31: 탈춤공원 탈춤공원무대 | D31: 46290 | E31: 0.83333333 | F31: 0.875 | G31: 공식 안내에 표기 없음 | H31: 공식 안내에 표기 없음 | I31: =IF(E31>=TIME(18,0,0),"Y","") -> Y | J31: =IF(AND(ISNUMBER(F31),F31>TIME(21,0,0)),"Y","") | K31: 공연-자유참가작 | L31: 탈춤공원 | M31: =CHOOSE(WEEKDAY(D31),"일","월","화","수","목","금","토") -> 금 | N31: https://www.maskdance.com/2024/sub7/sub1.asp?ymd=20260925 | O31: 페이지 게시일 미표기(리플릿 PDF 2026-09-21 생성) | P31: 46286
A32: 하회별신굿 탈놀이 | B32: 공연 | C32: 탈춤공연장 | D32: 46291 | E32: 0.41666667 | F32: 0.45833333 | G32: 유료: 탈춤공연장 관람권 현장 일반 8,000원·학생 6,000원(무료: 6세 이하·기초수급자·장애인·국가유공자) | H32: 사전예매(8/18~9/17) 종료 → 축제 기간 지정 매표소에서 구매·교환(1매 1회, 공연 후 전원 퇴장) | I32: =IF(E32>=TIME(18,0,0),"Y","") | J32: =IF(AND(ISNUMBER(F32),F32>TIME(21,0,0)),"Y","") | K32: 공연-한국탈춤 | L32: 탈춤공원 | M32: =CHOOSE(WEEKDAY(D32),"일","월","화","수","목","금","토") -> 토 | N32: https://www.maskdance.com/2024/sub7/sub1.asp?ymd=20260926 | O32: 페이지 게시일 미표기(리플릿 PDF 2026-09-21 생성) | P32: 46286 | Q32: 요금 적용 무대: 공식 입장권 안내엔 무대 미명시, 판매처 상품명 '탈춤공연장 공연관람권'(2025 NOL)으로 확인
A33: 탈춤따라배우기 | B33: 체험 | C33: 탈춤공원 버스킹무대 | D33: 46291 | E33: 0.45833333 | F33: 0.47916667 | G33: 공식 안내에 표기 없음 | H33: 공식 안내에 표기 없음 | I33: =IF(E33>=TIME(18,0,0),"Y","") | J33: =IF(AND(ISNUMBER(F33),F33>TIME(21,0,0)),"Y","") | K33: 체험 | L33: 탈춤공원 | M33: =CHOOSE(WEEKDAY(D33),"일","월","화","수","목","금","토") -> 토 | N33: https://www.maskdance.com/2024/sub7/sub1.asp?ymd=20260926 | O33: 페이지 게시일 미표기(리플릿 PDF 2026-09-21 생성) | P33: 46286
A34: 소명 예술연구소 | B34: 공연 | C34: 중앙선1942 메인무대 | D34: 46291 | E34: 0.45833333 | F34: 0.5 | G34: 공식 안내에 표기 없음 | H34: 공식 안내에 표기 없음 | I34: =IF(E34>=TIME(18,0,0),"Y","") | J34: =IF(AND(ISNUMBER(F34),F34>TIME(21,0,0)),"Y","") | K34: 공연-자유참가작 | L34: 중앙선1942(안동역) | M34: =CHOOSE(WEEKDAY(D34),"일","월","화","수","목","금","토") -> 토 | N34: https://www.maskdance.com/2024/sub7/sub1.asp?ymd=20260926 | O34: 페이지 게시일 미표기(리플릿 PDF 2026-09-21 생성) | P34: 46286
A35: 어린이대상 프로그램 | B35: 미분류 | C35: 원도심 왔니껴무대 | D35: 46291 | E35: 0.45833333 | F35: 0.5 | G35: 공식 안내에 표기 없음 | H35: 공식 안내에 표기 없음 | I35: =IF(E35>=TIME(18,0,0),"Y","") | J35: =IF(AND(ISNUMBER(F35),F35>TIME(21,0,0)),"Y","") | K35: 미분류(분류 목록에 없음) | L35: 원도심 | M35: =CHOOSE(WEEKDAY(D35),"일","월","화","수","목","금","토") -> 토 | N35: https://www.maskdance.com/2024/sub7/sub1.asp?ymd=20260926 | O35: 페이지 게시일 미표기(리플릿 PDF 2026-09-21 생성) | P35: 46286
A36: 탈랄라댄스배우기 | B36: 체험 | C36: 탈춤공원 버스킹무대 | D36: 46291 | E36: 0.47916667 | F36: 0.5 | G36: 공식 안내에 표기 없음 | H36: 공식 안내에 표기 없음 | I36: =IF(E36>=TIME(18,0,0),"Y","") | J36: =IF(AND(ISNUMBER(F36),F36>TIME(21,0,0)),"Y","") | K36: 체험 | L36: 탈춤공원 | M36: =CHOOSE(WEEKDAY(D36),"일","월","화","수","목","금","토") -> 토 | N36: https://www.maskdance.com/2024/sub7/sub1.asp?ymd=20260926 | O36: 페이지 게시일 미표기(리플릿 PDF 2026-09-21 생성) | P36: 46286
A37: 뉴질랜드 / 타타르스탄 / 불가리아 / 태국2 | B37: 공연 | C37: 탈춤공연장 | D37: 46291 | E37: 0.47916667 | F37: 0.52083333 | G37: 유료: 탈춤공연장 관람권 현장 일반 8,000원·학생 6,000원(무료: 6세 이하·기초수급자·장애인·국가유공자) | H37: 사전예매(8/18~9/17) 종료 → 축제 기간 지정 매표소에서 구매·교환(1매 1회, 공연 후 전원 퇴장) | I37: =IF(E37>=TIME(18,0,0),"Y","") | J37: =IF(AND(ISNUMBER(F37),F37>TIME(21,0,0)),"Y","") | K37: 공연-외국탈춤(해외공연단) | L37: 탈춤공원 | M37: =CHOOSE(WEEKDAY(D37),"일","월","화","수","목","금","토") -> 토 | N37: https://www.maskdance.com/2024/sub7/sub1.asp?ymd=20260926 | O37: 페이지 게시일 미표기(리플릿 PDF 2026-09-21 생성) | P37: 46286 | Q37: 요금 적용 무대: 공식 입장권 안내엔 무대 미명시, 판매처 상품명 '탈춤공연장 공연관람권'(2025 NOL)으로 확인
A38: 대만 / 라트비아 / 태국1 / 폴란드 / 몽골 / 튀르키예 | B38: 공연 | C38: 중앙선1942 메인무대 | D38: 46291 | E38: 0.5 | F38: 0.52083333 | G38: 공식 안내에 표기 없음 | H38: 공식 안내에 표기 없음 | I38: =IF(E38>=TIME(18,0,0),"Y","") | J38: =IF(AND(ISNUMBER(F38),F38>TIME(21,0,0)),"Y","") | K38: 공연-외국탈춤(해외공연단) | L38: 중앙선1942(안동역) | M38: =CHOOSE(WEEKDAY(D38),"일","월","화","수","목","금","토") -> 토 | N38: https://www.maskdance.com/2024/sub7/sub1.asp?ymd=20260926 | O38: 페이지 게시일 미표기(리플릿 PDF 2026-09-21 생성) | P38: 46286
A39: 안동향교 국악반 | B39: 공연 | C39: 탈춤공원 탈춤공원무대 | D39: 46291 | E39: 0.5 | F39: 0.54166667 | G39: 공식 안내에 표기 없음 | H39: 공식 안내에 표기 없음 | I39: =IF(E39>=TIME(18,0,0),"Y","") | J39: =IF(AND(ISNUMBER(F39),F39>TIME(21,0,0)),"Y","") | K39: 공연-자유참가작 | L39: 탈춤공원 | M39: =CHOOSE(WEEKDAY(D39),"일","월","화","수","목","금","토") -> 토 | N39: https://www.maskdance.com/2024/sub7/sub1.asp?ymd=20260926 | O39: 페이지 게시일 미표기(리플릿 PDF 2026-09-21 생성) | P39: 46286
A40: B.O.C | B40: 공연 | C40: 중앙선1942 메인무대 | D40: 46291 | E40: 0.52083333 | F40: 0.5625 | G40: 공식 안내에 표기 없음 | H40: 공식 안내에 표기 없음 | I40: =IF(E40>=TIME(18,0,0),"Y","") | J40: =IF(AND(ISNUMBER(F40),F40>TIME(21,0,0)),"Y","") | K40: 공연-자유참가작 | L40: 중앙선1942(안동역) | M40: =CHOOSE(WEEKDAY(D40),"일","월","화","수","목","금","토") -> 토 | N40: https://www.maskdance.com/2024/sub7/sub1.asp?ymd=20260926 | O40: 페이지 게시일 미표기(리플릿 PDF 2026-09-21 생성) | P40: 46286
...

Sheet 기간형·먹거리
A1: 프로그램명 | B1: 유형 | C1: 장소 | D1: 기간·시간 | E1: 공식분류 | F1: 출처 URL | G1: 게시일 | H1: 조사일 | I1: 비고
A2: 동아시아문화도시 탈전시 | B2: 기타 | C2: 탈춤공원 | D2: 2026.09.25 ~ 10.04 | E2: 전시 | F2: https://www.maskdance.com/2024/sub2/sub18.asp?yflag=2026&search=&page=1&seq=4504 | G2: 페이지 게시일 미표기 | H2: 46286
A3: 세계창작탈공모전 전시 | B3: 기타 | C3: 중앙선1942 | D3: 2026.09.25 ~ 10.04 | E3: 전시 | F3: https://www.maskdance.com/2024/sub2/sub18.asp?yflag=2026&search=&page=1&seq=4501 | G3: 페이지 게시일 미표기 | H3: 46286
A4: 전통주 박람회 | B4: 먹거리 | C4: 탈춤공원 / 벚꽃길 | D4: 2026.09.25 ~ 10.04 | E4: 전시 | F4: https://www.maskdance.com/2024/sub2/sub18.asp?yflag=2026&search=&page=1&seq=4503 | G4: 페이지 게시일 미표기 | H4: 46286
A5: 주빈국(말레이시아)의 날 부스 | B5: 기타 | C5: 탈춤공원 | D5: 2026.09.25 ~ 10.04 | E5: 전시 | F5: https://www.maskdance.com/2024/sub2/sub18.asp?yflag=2026&search=&page=1&seq=4502 | G5: 페이지 게시일 미표기 | H5: 46286
A6: ODA전시 | B6: 기타 | C6: 중앙선1942 | D6: 2026.09.25 ~ 10.04 | E6: 전시 | F6: https://www.maskdance.com/2024/sub2/sub18.asp?yflag=2026&search=&page=1&seq=4505 | G6: 페이지 게시일 미표기 | H6: 46286
A7: 2026 경상북도건축문화의날 | B7: 기타 | C7: 안동문화예술의전당 | D7: 2026.10.01.~10.04. | E7: 연계 | F7: https://www.maskdance.com/2024/sub2/sub17.asp?yflag=2026&search=&page=1&seq=4373 | G7: 페이지 게시일 미표기 | H7: 46286
A8: 2026 동아시아문화도시 안동 동아시아 탈전시 및 체험 | B8: 체험 | C8: 탈춤공원 | D8: 2026.09.24.~10.04. | E8: 연계 | F8: https://www.maskdance.com/2024/sub2/sub17.asp?yflag=2026&search=&page=1&seq=4380 | G8: 페이지 게시일 미표기 | H8: 46286
A9: 2026 안동마라톤대회 | B9: 기타 | C9: 안동시민운동장 | D9: 2026.10.04. | E9: 연계 | F9: https://www.maskdance.com/2024/sub2/sub17.asp?yflag=2026&search=&page=1&seq=4379 | G9: 페이지 게시일 미표기 | H9: 46286
A10: 2026 안동소주 공개행사 | B10: 먹거리 | C10: 탈춤공원 | D10: 2026.09.24.~10.04. | E10: 연계 | F10: https://www.maskdance.com/2024/sub2/sub17.asp?yflag=2026&search=&page=1&seq=4376 | G10: 페이지 게시일 미표기 | H10: 46286
A11: 웅부객주로드 | B11: 먹거리 | C11: 원도심 음식의 거리 | D11: 2026.9.24 ~10. 4 / 축제기간 중 | E11: 연계 | F11: https://www.maskdance.com/2024/sub2/sub17.asp?yflag=2026&search=&page=2&seq=4499 | G11: 페이지 게시일 미표기 | H11: 46286 | I11: 버스킹·길거리 객잔·이벤트, '흥해라 청춘': 지역 수제맥주·생맥주 판매, 쉼터(상세 페이지 문구)
A12: 제10회 안동시우리꽃연구회 우리꽃 전시회 | B12: 기타 | C12: 안동시립박물관 별관 | D12: 2026.09.24.~10.04. | E12: 연계 | F12: https://www.maskdance.com/2024/sub2/sub17.asp?yflag=2026&search=&page=2&seq=4372 | G12: 페이지 게시일 미표기 | H12: 46286
A13: 탈춤식당(축제 먹거리) | B13: 먹거리 | C13: 메인무대 서쪽 대형 그늘막 내부 | D13: 축제 기간 | E13: 리플릿 '춤추는 탈, 춤추는 맛 탈춤식당' | F13: https://www.maskdance.com/gears_pds/book/123/2026_leaflet_ko%20(2).pdf | G13: 2026-09-21(PDF 생성) | H13: 46286 | I13: 리플릿 2쪽 화면 확인
A14: 2026 산성마을의 추석 | B14: 기타 | C14: 한국문화테마파크 산성마을 | D14: 2026-09-24~09-27 | E14: 리플릿 | F14: https://www.maskdance.com/gears_pds/book/123/2026_leaflet_ko%20(2).pdf | G14: 2026-09-21(PDF 생성) | H14: 46286 | I14: 공연·전통놀이·떡메치기·소원 적기·포토존(리플릿 문구)
A15: 탈춤·탈랄라 댄스 따라 배우기(상시 안내) | B15: 체험 | C15: 탈춤공원 버스킹 무대 | D15: 2026-09-25~10-04 11:00~17:00 | E15: 리플릿·체험 | F15: https://www.maskdance.com/2024/sub2/sub3_3.asp | G15: 페이지 게시일 미표기 | H15: 46286 | I15: 회차별 시간은 '프로그램_일정' 시트

Sheet 야간 집계
A1: 날짜 | B1: 요일 | C1: 전체 일정 수 | D1: 18시 이후 시작 | E1: 21시 이후 종료 | F1: 18시 이후 비중
A2: 46289 | B2: =CHOOSE(WEEKDAY(A2),"일","월","화","수","목","금","토") -> 목 | C2: =COUNTIFS(프로그램_일정!$D$2:$D$414,A2) -> 12 | D2: =COUNTIFS(프로그램_일정!$D$2:$D$414,A2,프로그램_일정!$I$2:$I$414,"Y") -> 3 | E2: =COUNTIFS(프로그램_일정!$D$2:$D$414,A2,프로그램_일정!$J$2:$J$414,"Y") -> 0 | F2: =IF(C2=0,"",D2/C2) -> 0.25
A3: 46290 | B3: =CHOOSE(WEEKDAY(A3),"일","월","화","수","목","금","토") -> 금 | C3: =COUNTIFS(프로그램_일정!$D$2:$D$414,A3) -> 18 | D3: =COUNTIFS(프로그램_일정!$D$2:$D$414,A3,프로그램_일정!$I$2:$I$414,"Y") -> 5 | E3: =COUNTIFS(프로그램_일정!$D$2:$D$414,A3,프로그램_일정!$J$2:$J$414,"Y") -> 0 | F3: =IF(C3=0,"",D3/C3) -> 0.27777778
A4: 46291 | B4: =CHOOSE(WEEKDAY(A4),"일","월","화","수","목","금","토") -> 토 | C4: =COUNTIFS(프로그램_일정!$D$2:$D$414,A4) -> 55 | D4: =COUNTIFS(프로그램_일정!$D$2:$D$414,A4,프로그램_일정!$I$2:$I$414,"Y") -> 17 | E4: =COUNTIFS(프로그램_일정!$D$2:$D$414,A4,프로그램_일정!$J$2:$J$414,"Y") -> 4 | F4: =IF(C4=0,"",D4/C4) -> 0.30909091
A5: 46292 | B5: =CHOOSE(WEEKDAY(A5),"일","월","화","수","목","금","토") -> 일 | C5: =COUNTIFS(프로그램_일정!$D$2:$D$414,A5) -> 56 | D5: =COUNTIFS(프로그램_일정!$D$2:$D$414,A5,프로그램_일정!$I$2:$I$414,"Y") -> 15 | E5: =COUNTIFS(프로그램_일정!$D$2:$D$414,A5,프로그램_일정!$J$2:$J$414,"Y") -> 2 | F5: =IF(C5=0,"",D5/C5) -> 0.26785714
A6: 46293 | B6: =CHOOSE(WEEKDAY(A6),"일","월","화","수","목","금","토") -> 월 | C6: =COUNTIFS(프로그램_일정!$D$2:$D$414,A6) -> 30 | D6: =COUNTIFS(프로그램_일정!$D$2:$D$414,A6,프로그램_일정!$I$2:$I$414,"Y") -> 8 | E6: =COUNTIFS(프로그램_일정!$D$2:$D$414,A6,프로그램_일정!$J$2:$J$414,"Y") -> 0 | F6: =IF(C6=0,"",D6/C6) -> 0.26666667
A7: 46294 | B7: =CHOOSE(WEEKDAY(A7),"일","월","화","수","목","금","토") -> 화 | C7: =COUNTIFS(프로그램_일정!$D$2:$D$414,A7) -> 36 | D7: =COUNTIFS(프로그램_일정!$D$2:$D$414,A7,프로그램_일정!$I$2:$I$414,"Y") -> 10 | E7: =COUNTIFS(프로그램_일정!$D$2:$D$414,A7,프로그램_일정!$J$2:$J$414,"Y") -> 1 | F7: =IF(C7=0,"",D7/C7) -> 0.27777778
A8: 46295 | B8: =CHOOSE(WEEKDAY(A8),"일","월","화","수","목","금","토") -> 수 | C8: =COUNTIFS(프로그램_일정!$D$2:$D$414,A8) -> 35 | D8: =COUNTIFS(프로그램_일정!$D$2:$D$414,A8,프로그램_일정!$I$2:$I$414,"Y") -> 8 | E8: =COUNTIFS(프로그램_일정!$D$2:$D$414,A8,프로그램_일정!$J$2:$J$414,"Y") -> 0 | F8: =IF(C8=0,"",D8/C8) -> 0.22857143
A9: 46296 | B9: =CHOOSE(WEEKDAY(A9),"일","월","화","수","목","금","토") -> 목 | C9: =COUNTIFS(프로그램_일정!$D$2:$D$414,A9) -> 35 | D9: =COUNTIFS(프로그램_일정!$D$2:$D$414,A9,프로그램_일정!$I$2:$I$414,"Y") -> 7 | E9: =COUNTIFS(프로그램_일정!$D$2:$D$414,A9,프로그램_일정!$J$2:$J$414,"Y") -> 0 | F9: =IF(C9=0,"",D9/C9) -> 0.2
A10: 46297 | B10: =CHOOSE(WEEKDAY(A10),"일","월","화","수","목","금","토") -> 금 | C10: =COUNTIFS(프로그램_일정!$D$2:$D$414,A10) -> 30 | D10: =COUNTIFS(프로그램_일정!$D$2:$D$414,A10,프로그램_일정!$I$2:$I$414,"Y") -> 6 | E10: =COUNTIFS(프로그램_일정!$D$2:$D$414,A10,프로그램_일정!$J$2:$J$414,"Y") -> 1 | F10: =IF(C10=0,"",D10/C10) -> 0.2
A11: 46298 | B11: =CHOOSE(WEEKDAY(A11),"일","월","화","수","목","금","토") -> 토 | C11: =COUNTIFS(프로그램_일정!$D$2:$D$414,A11) -> 59 | D11: =COUNTIFS(프로그램_일정!$D$2:$D$414,A11,프로그램_일정!$I$2:$I$414,"Y") -> 14 | E11: =COUNTIFS(프로그램_일정!$D$2:$D$414,A11,프로그램_일정!$J$2:$J$414,"Y") -> 2 | F11: =IF(C11=0,"",D11/C11) -> 0.23728814
A12: 46299 | B12: =CHOOSE(WEEKDAY(A12),"일","월","화","수","목","금","토") -> 일 | C12: =COUNTIFS(프로그램_일정!$D$2:$D$414,A12) -> 47 | D12: =COUNTIFS(프로그램_일정!$D$2:$D$414,A12,프로그램_일정!$I$2:$I$414,"Y") -> 6 | E12: =COUNTIFS(프로그램_일정!$D$2:$D$414,A12,프로그램_일정!$J$2:$J$414,"Y") -> 1 | F12: =IF(C12=0,"",D12/C12) -> 0.12765957
A13: 합계 | C13: =SUM(C2:C12) -> 413 | D13: =SUM(D2:D12) -> 99 | E13: =SUM(E2:E12) -> 11 | F13: =IF(C13=0,"",D13/C13) -> 0.23970944
A15: 권역 | C15: 전체 일정 수 | D15: 18시 이후 시작 | E15: 21시 이후 종료 | F15: 18시 이후 비중
A16: 탈춤공원 | C16: =COUNTIFS(프로그램_일정!$L$2:$L$414,A16) -> 216 | D16: =COUNTIFS(프로그램_일정!$L$2:$L$414,A16,프로그램_일정!$I$2:$I$414,"Y") -> 50 | E16: =COUNTIFS(프로그램_일정!$L$2:$L$414,A16,프로그램_일정!$J$2:$J$414,"Y") -> 5 | F16: =IF(C16=0,"",D16/C16) -> 0.23148148
A17: 중앙선1942(안동역) | C17: =COUNTIFS(프로그램_일정!$L$2:$L$414,A17) -> 89 | D17: =COUNTIFS(프로그램_일정!$L$2:$L$414,A17,프로그램_일정!$I$2:$I$414,"Y") -> 32 | E17: =COUNTIFS(프로그램_일정!$L$2:$L$414,A17,프로그램_일정!$J$2:$J$414,"Y") -> 6 | F17: =IF(C17=0,"",D17/C17) -> 0.35955056
A18: 원도심 | C18: =COUNTIFS(프로그램_일정!$L$2:$L$414,A18) -> 63 | D18: =COUNTIFS(프로그램_일정!$L$2:$L$414,A18,프로그램_일정!$I$2:$I$414,"Y") -> 12 | E18: =COUNTIFS(프로그램_일정!$L$2:$L$414,A18,프로그램_일정!$J$2:$J$414,"Y") -> 0 | F18: =IF(C18=0,"",D18/C18) -> 0.19047619
A19: 시장·기타(안동시 전역) | C19: =COUNTIFS(프로그램_일정!$L$2:$L$414,A19) -> 26 | D19: =COUNTIFS(프로그램_일정!$L$2:$L$414,A19,프로그램_일정!$I$2:$I$414,"Y") -> 2 | E19: =COUNTIFS(프로그램_일정!$L$2:$L$414,A19,프로그램_일정!$J$2:$J$414,"Y") -> 0 | F19: =IF(C19=0,"",D19/C19) -> 0.076923077
A20: 하회마을 | C20: =COUNTIFS(프로그램_일정!$L$2:$L$414,A20) -> 19 | D20: =COUNTIFS(프로그램_일정!$L$2:$L$414,A20,프로그램_일정!$I$2:$I$414,"Y") -> 3 | E20: =COUNTIFS(프로그램_일정!$L$2:$L$414,A20,프로그램_일정!$J$2:$J$414,"Y") -> 0 | F20: =IF(C20=0,"",D20/C20) -> 0.15789474
A21: 기타 | C21: =COUNTIFS(프로그램_일정!$L$2:$L$414,A21) -> 0 | D21: =COUNTIFS(프로그램_일정!$L$2:$L$414,A21,프로그램_일정!$I$2:$I$414,"Y") -> 0 | E21: =COUNTIFS(프로그램_일정!$L$2:$L$414,A21,프로그램_일정!$J$2:$J$414,"Y") -> 0 | F21: =IF(C21=0,"",D21/C21)
A23: 유형 | C23: 전체 일정 수 | D23: 18시 이후 시작 | E23: 21시 이후 종료 | F23: 18시 이후 비중
A24: 공연 | C24: =COUNTIFS(프로그램_일정!$B$2:$B$414,A24) -> 320 | D24: =COUNTIFS(프로그램_일정!$B$2:$B$414,A24,프로그램_일정!$I$2:$I$414,"Y") -> 89 | E24: =COUNTIFS(프로그램_일정!$B$2:$B$414,A24,프로그램_일정!$J$2:$J$414,"Y") -> 11 | F24: =IF(C24=0,"",D24/C24) -> 0.278125
A25: 체험 | C25: =COUNTIFS(프로그램_일정!$B$2:$B$414,A25) -> 44 | D25: =COUNTIFS(프로그램_일정!$B$2:$B$414,A25,프로그램_일정!$I$2:$I$414,"Y") -> 0 | E25: =COUNTIFS(프로그램_일정!$B$2:$B$414,A25,프로그램_일정!$J$2:$J$414,"Y") -> 0 | F25: =IF(C25=0,"",D25/C25) -> 0
A26: 기타 | C26: =COUNTIFS(프로그램_일정!$B$2:$B$414,A26) -> 4 | D26: =COUNTIFS(프로그램_일정!$B$2:$B$414,A26,프로그램_일정!$I$2:$I$414,"Y") -> 0 | E26: =COUNTIFS(프로그램_일정!$B$2:$B$414,A26,프로그램_일정!$J$2:$J$414,"Y") -> 0 | F26: =IF(C26=0,"",D26/C26) -> 0
A27: 미분류 | C27: =COUNTIFS(프로그램_일정!$B$2:$B$414,A27) -> 45 | D27: =COUNTIFS(프로그램_일정!$B$2:$B$414,A27,프로그램_일정!$I$2:$I$414,"Y") -> 10 | E27: =COUNTIFS(프로그램_일정!$B$2:$B$414,A27,프로그램_일정!$J$2:$J$414,"Y") -> 0 | F27: =IF(C27=0,"",D27/C27) -> 0.22222222

Sheet 셔틀버스
A1: 구간 | B1: 운행일 구분 | C1: 출발 정류장 | D1: 도착(경유) | E1: 출발 시각 | F1: 출처 URL | G1: 게시일 | H1: 조사일 | I1: 비고
A2: 1구간 | B2: 평일(9.24·9.28·9.29·9.30·10.1) | C2: 탈춤축제장 | D2: 하회마을매표소 | E2: 10:00 | F2: https://www.maskdance.com/2024/sub7/sub5.asp | G2: 페이지 게시일 미표기 | H2: 46286 | I2: 원문 표 순서대로 전사. 휴게시간 12:00~12:59·18:00~18:59(원문 '운행' 표기는 오기로 보이나 그대로 둠)
A3: 1구간 | B3: 평일(9.24·9.28·9.29·9.30·10.1) | C3: 탈춤축제장 | D3: 하회마을매표소 | E3: 11:00 | F3: https://www.maskdance.com/2024/sub7/sub5.asp | G3: 페이지 게시일 미표기 | H3: 46286 | I3: 원문 표 순서대로 전사. 휴게시간 12:00~12:59·18:00~18:59(원문 '운행' 표기는 오기로 보이나 그대로 둠)
A4: 1구간 | B4: 평일(9.24·9.28·9.29·9.30·10.1) | C4: 탈춤축제장 | D4: 하회마을매표소 | E4: 13:00 | F4: https://www.maskdance.com/2024/sub7/sub5.asp | G4: 페이지 게시일 미표기 | H4: 46286 | I4: 원문 표 순서대로 전사. 휴게시간 12:00~12:59·18:00~18:59(원문 '운행' 표기는 오기로 보이나 그대로 둠)
A5: 1구간 | B5: 평일(9.24·9.28·9.29·9.30·10.1) | C5: 탈춤축제장 | D5: 하회마을매표소 | E5: 14:00 | F5: https://www.maskdance.com/2024/sub7/sub5.asp | G5: 페이지 게시일 미표기 | H5: 46286 | I5: 원문 표 순서대로 전사. 휴게시간 12:00~12:59·18:00~18:59(원문 '운행' 표기는 오기로 보이나 그대로 둠)
A6: 1구간 | B6: 평일(9.24·9.28·9.29·9.30·10.1) | C6: 탈춤축제장 | D6: 하회마을매표소 | E6: 15:00 | F6: https://www.maskdance.com/2024/sub7/sub5.asp | G6: 페이지 게시일 미표기 | H6: 46286 | I6: 원문 표 순서대로 전사. 휴게시간 12:00~12:59·18:00~18:59(원문 '운행' 표기는 오기로 보이나 그대로 둠)
A7: 1구간 | B7: 평일(9.24·9.28·9.29·9.30·10.1) | C7: 탈춤축제장 | D7: 하회마을매표소 | E7: 16:00 | F7: https://www.maskdance.com/2024/sub7/sub5.asp | G7: 페이지 게시일 미표기 | H7: 46286 | I7: 원문 표 순서대로 전사. 휴게시간 12:00~12:59·18:00~18:59(원문 '운행' 표기는 오기로 보이나 그대로 둠)
A8: 1구간 | B8: 평일(9.24·9.28·9.29·9.30·10.1) | C8: 탈춤축제장 | D8: 하회마을매표소 | E8: 17:00 | F8: https://www.maskdance.com/2024/sub7/sub5.asp | G8: 페이지 게시일 미표기 | H8: 46286 | I8: 원문 표 순서대로 전사. 휴게시간 12:00~12:59·18:00~18:59(원문 '운행' 표기는 오기로 보이나 그대로 둠)
A9: 1구간 | B9: 휴일(9.25·9.26·9.27·10.2) | C9: 탈춤축제장 | D9: 하회마을매표소 | E9: 10:00 | F9: https://www.maskdance.com/2024/sub7/sub5.asp | G9: 페이지 게시일 미표기 | H9: 46286 | I9: 원문 표 순서대로 전사. 휴게시간 12:00~12:59·18:00~18:59(원문 '운행' 표기는 오기로 보이나 그대로 둠)
A10: 1구간 | B10: 휴일(9.25·9.26·9.27·10.2) | C10: 탈춤축제장 | D10: 하회마을매표소 | E10: 11:00 | F10: https://www.maskdance.com/2024/sub7/sub5.asp | G10: 페이지 게시일 미표기 | H10: 46286 | I10: 원문 표 순서대로 전사. 휴게시간 12:00~12:59·18:00~18:59(원문 '운행' 표기는 오기로 보이나 그대로 둠)
A11: 1구간 | B11: 휴일(9.25·9.26·9.27·10.2) | C11: 탈춤축제장 | D11: 하회마을매표소 | E11: 13:00 | F11: https://www.maskdance.com/2024/sub7/sub5.asp | G11: 페이지 게시일 미표기 | H11: 46286 | I11: 원문 표 순서대로 전사. 휴게시간 12:00~12:59·18:00~18:59(원문 '운행' 표기는 오기로 보이나 그대로 둠)
A12: 1구간 | B12: 휴일(9.25·9.26·9.27·10.2) | C12: 탈춤축제장 | D12: 하회마을매표소 | E12: 14:00 | F12: https://www.maskdance.com/2024/sub7/sub5.asp | G12: 페이지 게시일 미표기 | H12: 46286 | I12: 원문 표 순서대로 전사. 휴게시간 12:00~12:59·18:00~18:59(원문 '운행' 표기는 오기로 보이나 그대로 둠)
A13: 1구간 | B13: 휴일(9.25·9.26·9.27·10.2) | C13: 탈춤축제장 | D13: 하회마을매표소 | E13: 15:00 | F13: https://www.maskdance.com/2024/sub7/sub5.asp | G13: 페이지 게시일 미표기 | H13: 46286 | I13: 원문 표 순서대로 전사. 휴게시간 12:00~12:59·18:00~18:59(원문 '운행' 표기는 오기로 보이나 그대로 둠)
... A80: 2구간 | B80: 선유줄불놀이일(9.26·10.3·10.4) | C80: 안동시외버스터미널(안동역) | D80: 탈춤축제장 | E80: 21:30 | F80: https://www.maskdance.com/2024/sub7/sub5.asp | G80: 페이지 게시일 미표기 | H80: 46286 | I80: 원문 표 순서대로 전사. 휴게시간 12:00~12:59·18:00~18:59(원문 '운행' 표기는 오기로 보이나 그대로 둠)

Sheet 요금·운영 규정
A1: 항목 | B1: 내용 | C1: 출처 URL | D1: 게시일 | E1: 조사일 | F1: 비고
A2: 입장권 | B2: 일반권 현장 8,000원 / 예매 6,000원(탈춤사랑쿠폰 2,000원 페이백) | C2: https://www.maskdance.com/2024/sub7/sub2.asp | D2: 미표기 | E2: 46286 | F2: 화면 그대로
A3: 입장권 | B3: 학생권 현장 6,000원 / 예매 4,000원 | C3: https://www.maskdance.com/2024/sub7/sub2.asp | D3: 미표기 | E3: 46286
A4: 입장권 | B4: 무료관람: 미취학아동(6세 이하)·기초생활수급자·장애인·국가유공자 | C4: https://www.maskdance.com/2024/sub7/sub2.asp | D4: 미표기 | E4: 46286
A5: 입장권 | B5: 예매권은 축제기간 지정 매표소에서 당회 입장권으로 교환 후 입장, 교환 시 탈춤사랑쿠폰(2,000원) 지급 / 공연 관람은 1매 1회(공연 후 전원 퇴장) | C5: https://www.maskdance.com/2024/sub7/sub2.asp | D5: 미표기 | E5: 46286
A6: 입장권 적용 무대 | B6: 판매처 상품명 '2025 안동국제탈춤페스티벌 탈춤공연장 공연관람권'(NOL 티켓). 2026 공식 안내엔 무대 미명시 | C6: https://tickets.interpark.com/goods/25014153 | D6: 2025 | E6: 46286 | F6: 2026 상품명은 미확인
A7: 사전예매 | B7: 2026-08-18~09-17, 네이버·카카오톡·쿠팡 / 시청 종합민원실·24개 읍면동·지정 판매처 | C7: https://biz.heraldcorp.com/article/10844864 | D7: 2026-08-19 | E7: 46286 | F7: 헤럴드경제
A8: 탈춤사랑쿠폰 사용처 | B8: 축제장 인근 원도심(음식의거리, 중앙문화의거리상점가, 남서상점가, 구시장, 중앙신시장 구역 및 주변)의 사용 가능 표지 부착 상가 | C8: https://www.maskdance.com/2024/sub4/sub4.asp | D8: 미표기 | E8: 46286 | F8: 원도심 식당 연결(1단계)과 직접 관련
A9: 문화의 거리 도로통제 | B9: 신한은행~삼보빌딩, 음식의길 남측 입구~파리바게트 안동중앙점 입구 / 2026-09-22~10-06 매일 17:00~24:00 | C9: https://www.maskdance.com/gears_pds/book/123/2026_leaflet_ko%20(2).pdf | D9: 2026-09-21(PDF 생성) | E9: 46286 | F9: 리플릿(최신). FAQ는 '9.16 10:00~10.7 23:00'로 다름 → 리플릿 우선, 현장 확인 필요
A10: 문화의 거리 도로통제(FAQ) | B10: 삼산우체국~삼보빌딩, 음식의길 남측 입구~파리바게트 안동중앙점 입구 / 9.16.(수) 10:00~10.7.(수) 23:00 | C10: https://www.maskdance.com/2024/sub4/sub4.asp | D10: 미표기 | E10: 46286 | F10: 리플릿과 기간·구간 다름
A11: 벚꽃도로 도로통제 | B11: 탈춤공원 뒤편 벚꽃도로(축제장길 200) / 2026-09-16 10:00~10-07 23:00 | C11: https://www.maskdance.com/gears_pds/book/123/2026_leaflet_ko%20(2).pdf | D11: 2026-09-21(PDF 생성) | E11: 46286 | F11: FAQ와 동일
A12: 탈놀이 대동난장 | B12: 2026-09-26·09-27·09-30·10-03, 19시~ 중앙선1942 메인무대 | C12: https://www.maskdance.com/2024/sub4/sub4.asp | D12: 미표기 | E12: 46286
A13: 하회선유줄불놀이 | B13: 2026-09-26(토)·10-03(토)·10-04(일) 19:00~21:00, 하회마을 만송정 일원. 요금·예약 표기 없음 | C13: https://www.maskdance.com/2024/sub2/sub1_9.asp | D13: 미표기 | E13: 46286 | F13: 반값여행 지정관광지(지역축제)에도 포함
A14: 개막식 | B14: 2026-09-25(금) 19:00~ 중앙선1942 메인무대(FAQ) / 리플릿은 '18:00~ 메인무대, 개막식 퍼레이드 포함' | C14: https://www.maskdance.com/2024/sub4/sub4.asp | D14: 미표기 | E14: 46286 | F14: 퍼레이드 포함 여부에 따라 시작 시각 표기가 다름
A15: 폐막식 | B15: 2026-10-04(일) 20:30~ 중앙선1942 메인무대(탈놀이 경연대회 결승과 함께) | C15: https://www.maskdance.com/2024/sub4/sub4.asp | D15: 미표기 | E15: 46286

Sheet 출처·메모
A1: 구분 | B1: 내용
A2: 축제 | B2: 2026 안동국제탈춤페스티벌, 2026-09-24(목)~10-04(일) 11일, 주제 '가면의 기억, 모두의 춤'. 주관 한국정신문화재단(054-840-3424).
A3: 일정 출처 | B3: 공식 누리집 행사일정표 날짜별 페이지(https://www.maskdance.com/2024/sub7/sub1.asp?ymd=YYYYMMDD) 11일치 전부. 시간·행사명·장소는 원문 그대로. 원문 표 413행.
A4: 유형 열 | B4: 작업 목록의 유형(공연/체험/야간/먹거리) 중 '야간'은 시간 조건이라 별도 열(야간(18시 이후 시작), 21시 이후 종료)로 분리. 유형 = 공연/체험/기타/미분류. 먹거리는 날짜별 일정표에 회차가 없어 '기간형·먹거리' 시트에 둠.
A5: 공식분류 규칙 | B5: 리플릿 2쪽 '축제 프로그램' 8분류(개막식·공연·퍼레이드·경연·전시·체험·현장 이벤트·관광지 프로그램) + 누리집 프로그램 메뉴 목록(한국탈춤·외국탈춤·마당극&창작극·자유참가작·민속놀이·하회마을행사·전시·연계, 187개 이름)에 이름을 맞춤. 체험 = 탈춤따라 배우기·탈랄라댄스 배우기(리플릿 체험 목록). 목록에 없는 이름은 미분류로 두고 추정하지 않음.
A6: 미분류 이름 | B6: COMA, DR CREW, SIGN CREW, 갓쓰고 탈쓰고 런웨이, 걷기대회 축하공연, 경북 국악협회, 경북 무용협회, 경북 연극협회, 경북 연예예술인협회, 경북 음악협회, 경북도청미래태권도줄넘기시범단, 박찬일 쉐프, 밴드 판소리 ‘막되먹은 응칠이’ (예술단 농음), 서중사밴드, 소유, 쉼표, 시민참여프로그램, 실루엣, 아랑고고장구 페스티벌, 안동영호초등탈춤동아리, 알파카어쿠스테이지, 어린이대상 프로그램, 예안 어쩌다밴드, 오색풍차, 웅부악단, 이성교 예천한천나들예술공연단, 일본나라현 문화교류, 조선의 서커스, 초청가수 공연, 팝스밴드
A7: 요금·예약 | B7: 탈춤공연장 공연만 유료(관람권). 공식 입장권 안내엔 적용 무대가 명시돼 있지 않아 판매처 상품명(2025 NOL '탈춤공연장 공연관람권')으로 확인. 다른 무대·체험은 공식 안내에 요금·예약 표기가 없어 '표기 없음'으로 둠(무료라고 단정하지 않음).
A8: 리플릿 대조 | B8: 20260925: 일치(리플릿 1회/누리집 1회); 20260926: 일치(리플릿 8회/누리집 8회); 20260927: 일치(리플릿 8회/누리집 8회); 20260928: 일치(리플릿 6회/누리집 6회); 20260929: 일치(리플릿 7회/누리집 7회) — 탈춤공연장 공연 시각을 리플릿 2쪽 표(9/25~9/29)와 대조.
A9: 리플릿 | B9: 2026_leaflet_ko (2).pdf, 2026-09-21 10:57 생성(오늘 오전 갱신본). 글자가 그림이라 화면으로 읽음. 원본·캡처는 data/external/작업목록_6-11_수집_20260921/07_탈춤축제/.
A10: 야간 참고 | B10: 선유줄불놀이(9/26·10/3·10/4 19~21시, 하회)일에는 셔틀 1구간 종점이 하회마을매표소 → 안동간고등어숯불가든 본점으로 바뀜. 셔틀 막차: 터미널(안동역) 21:30 출발(휴일·선유일), 평일은 18:00.
A11: 조사일 | B11: 2026-09-21
